2020-06-18 13:10:08 ('Connection aborted.', TimeoutError(60, 'Operation timed out'))
Traceback (most recent call last):
  File "/usr/local/lib/python3.7/site-packages/urllib3/connectionpool.py", line 600, in urlopen
    chunked=chunked)
  File "/usr/local/lib/python3.7/site-packages/urllib3/connectionpool.py", line 343, in _make_request
    self._validate_conn(conn)
  File "/usr/local/lib/python3.7/site-packages/urllib3/connectionpool.py", line 839, in _validate_conn
    conn.connect()
  File "/usr/local/lib/python3.7/site-packages/urllib3/connection.py", line 344, in connect
    ssl_context=context)
  File "/usr/local/lib/python3.7/site-packages/urllib3/util/ssl_.py", line 344, in ssl_wrap_socket
    return context.wrap_socket(sock, server_hostname=server_hostname)
  File "/usr/local/Cellar/python/3.7.2_1/Frameworks/Python.framework/Versions/3.7/lib/python3.7/ssl.py", line 412, in wrap_socket
    session=session
  File "/usr/local/Cellar/python/3.7.2_1/Frameworks/Python.framework/Versions/3.7/lib/python3.7/ssl.py", line 853, in _create
    self.do_handshake()
  File "/usr/local/Cellar/python/3.7.2_1/Frameworks/Python.framework/Versions/3.7/lib/python3.7/ssl.py", line 1117, in do_handshake
    self._sslobj.do_handshake()
TimeoutError: [Errno 60] Operation timed out

During handling of the above exception, another exception occurred:

Traceback (most recent call last):
  File "/usr/local/lib/python3.7/site-packages/requests/adapters.py", line 449, in send
    timeout=timeout
  File "/usr/local/lib/python3.7/site-packages/urllib3/connectionpool.py", line 638, in urlopen
    _stacktrace=sys.exc_info()[2])
  File "/usr/local/lib/python3.7/site-packages/urllib3/util/retry.py", line 367, in increment
    raise six.reraise(type(error), error, _stacktrace)
  File "/usr/local/lib/python3.7/site-packages/urllib3/packages/six.py", line 685, in reraise
    raise value.with_traceback(tb)
  File "/usr/local/lib/python3.7/site-packages/urllib3/connectionpool.py", line 600, in urlopen
    chunked=chunked)
  File "/usr/local/lib/python3.7/site-packages/urllib3/connectionpool.py", line 343, in _make_request
    self._validate_conn(conn)
  File "/usr/local/lib/python3.7/site-packages/urllib3/connectionpool.py", line 839, in _validate_conn
    conn.connect()
  File "/usr/local/lib/python3.7/site-packages/urllib3/connection.py", line 344, in connect
    ssl_context=context)
  File "/usr/local/lib/python3.7/site-packages/urllib3/util/ssl_.py", line 344, in ssl_wrap_socket
    return context.wrap_socket(sock, server_hostname=server_hostname)
  File "/usr/local/Cellar/python/3.7.2_1/Frameworks/Python.framework/Versions/3.7/lib/python3.7/ssl.py", line 412, in wrap_socket
    session=session
  File "/usr/local/Cellar/python/3.7.2_1/Frameworks/Python.framework/Versions/3.7/lib/python3.7/ssl.py", line 853, in _create
    self.do_handshake()
  File "/usr/local/Cellar/python/3.7.2_1/Frameworks/Python.framework/Versions/3.7/lib/python3.7/ssl.py", line 1117, in do_handshake
    self._sslobj.do_handshake()
urllib3.exceptions.ProtocolError: ('Connection aborted.', TimeoutError(60, 'Operation timed out'))

During handling of the above exception, another exception occurred:

Traceback (most recent call last):
  File "/Users/kimbach/Documents/wikilabskultur/wikilabskultur/smkbatch.py", line 184, in <module>
    smk_objects=smkapi.get_smk_objects(offset, rows)
  File "/Users/kimbach/Documents/wikilabskultur/wikilabskultur/smkapi.py", line 70, in get_smk_objects
    data=json.loads(requests.get(url).text)
  File "/usr/local/lib/python3.7/site-packages/requests/api.py", line 75, in get
    return request('get', url, params=params, **kwargs)
  File "/usr/local/lib/python3.7/site-packages/requests/api.py", line 60, in request
    return session.request(method=method, url=url, **kwargs)
  File "/usr/local/lib/python3.7/site-packages/requests/sessions.py", line 533, in request
    resp = self.send(prep, **send_kwargs)
  File "/usr/local/lib/python3.7/site-packages/requests/sessions.py", line 646, in send
    r = adapter.send(request, **kwargs)
  File "/usr/local/lib/python3.7/site-packages/requests/adapters.py", line 498, in send
    raise ConnectionError(err, request=request)
requests.exceptions.ConnectionError: ('Connection aborted.', TimeoutError(60, 'Operation timed out'))
2020-06-25 22:56:39 [Errno 2] No such file or directory: './downloads/Albrecht Altdorfer, Jomfru Maria med barnet og Sankt Anne ved vuggen, 1479-1537, KKS1615, Statens Museum for Kunst.jpg'
Traceback (most recent call last):
  File "/Users/kimbach/Documents/wikilabskultur/wikilabskultur/smkbatch.py", line 579, in <module>
    open(path, 'wb').write(r.content)
FileNotFoundError: [Errno 2] No such file or directory: './downloads/Albrecht Altdorfer, Jomfru Maria med barnet og Sankt Anne ved vuggen, 1479-1537, KKS1615, Statens Museum for Kunst.jpg'
2020-06-25 22:59:13 [Errno 2] No such file or directory: './downloads/Albrecht Altdorfer - Jomfru Maria med barnet og Sankt Anne ved vuggen - 1479-1537 - KKS1615 - Statens Museum for Kunst.jpg'
Traceback (most recent call last):
  File "/Users/kimbach/Documents/wikilabskultur/wikilabskultur/smkbatch.py", line 579, in <module>
    open(path, 'wb').write(r.content)
FileNotFoundError: [Errno 2] No such file or directory: './downloads/Albrecht Altdorfer - Jomfru Maria med barnet og Sankt Anne ved vuggen - 1479-1537 - KKS1615 - Statens Museum for Kunst.jpg'
2020-06-25 23:51:51 Closing network session.
2020-06-25 23:51:51 Network session closed.
2020-06-26 06:33:35 Closing network session.
2020-06-26 06:33:35 Network session closed.
2020-06-26 06:34:51 Closing network session.
2020-06-26 06:34:51 Network session closed.
2020-06-26 06:36:13 Closing network session.
2020-06-26 06:36:13 Network session closed.
2020-06-26 06:39:01 Closing network session.
2020-06-26 06:39:01 Network session closed.
2020-06-26 06:42:38 Closing network session.
2020-06-26 06:42:38 Network session closed.
2020-06-26 06:44:29 Closing network session.
2020-06-26 06:44:29 Network session closed.
2020-06-26 06:46:18 Closing network session.
2020-06-26 06:46:18 Network session closed.
2020-06-26 06:48:37 Closing network session.
2020-06-26 06:48:37 Network session closed.
