2021-12-10 12:53:40 Closing network session.
2021-12-10 12:53:40 Network session closed.
2021-12-10 14:41:58 can only concatenate str (not "_Printer") to str
Traceback (most recent call last):
  File "/Users/kimbach/Documents/wikilabskultur/batchupload/smkbatch.py", line 652, in TestSMKAPI
    wikitext = artwork.wikitext + '\n' + license + '\n' + str(smk_categories)
TypeError: can only concatenate str (not "_Printer") to str
2021-12-10 14:41:58 can only concatenate str (not "_Printer") to str
Traceback (most recent call last):
  File "/Users/kimbach/Documents/wikilabskultur/batchupload/smkbatch.py", line 652, in TestSMKAPI
    wikitext = artwork.wikitext + '\n' + license + '\n' + str(smk_categories)
TypeError: can only concatenate str (not "_Printer") to str
2021-12-10 14:41:59 can only concatenate str (not "_Printer") to str
Traceback (most recent call last):
  File "/Users/kimbach/Documents/wikilabskultur/batchupload/smkbatch.py", line 652, in TestSMKAPI
    wikitext = artwork.wikitext + '\n' + license + '\n' + str(smk_categories)
TypeError: can only concatenate str (not "_Printer") to str
2021-12-10 14:41:59 can only concatenate str (not "_Printer") to str
Traceback (most recent call last):
  File "/Users/kimbach/Documents/wikilabskultur/batchupload/smkbatch.py", line 652, in TestSMKAPI
    wikitext = artwork.wikitext + '\n' + license + '\n' + str(smk_categories)
TypeError: can only concatenate str (not "_Printer") to str
2021-12-10 14:41:59 can only concatenate str (not "_Printer") to str
Traceback (most recent call last):
  File "/Users/kimbach/Documents/wikilabskultur/batchupload/smkbatch.py", line 652, in TestSMKAPI
    wikitext = artwork.wikitext + '\n' + license + '\n' + str(smk_categories)
TypeError: can only concatenate str (not "_Printer") to str
2021-12-10 14:42:00 can only concatenate str (not "_Printer") to str
Traceback (most recent call last):
  File "/Users/kimbach/Documents/wikilabskultur/batchupload/smkbatch.py", line 652, in TestSMKAPI
    wikitext = artwork.wikitext + '\n' + license + '\n' + str(smk_categories)
TypeError: can only concatenate str (not "_Printer") to str
2021-12-10 14:42:00 can only concatenate str (not "_Printer") to str
Traceback (most recent call last):
  File "/Users/kimbach/Documents/wikilabskultur/batchupload/smkbatch.py", line 652, in TestSMKAPI
    wikitext = artwork.wikitext + '\n' + license + '\n' + str(smk_categories)
TypeError: can only concatenate str (not "_Printer") to str
2021-12-10 14:42:01 can only concatenate str (not "_Printer") to str
Traceback (most recent call last):
  File "/Users/kimbach/Documents/wikilabskultur/batchupload/smkbatch.py", line 652, in TestSMKAPI
    wikitext = artwork.wikitext + '\n' + license + '\n' + str(smk_categories)
TypeError: can only concatenate str (not "_Printer") to str
2021-12-10 14:42:01 can only concatenate str (not "_Printer") to str
Traceback (most recent call last):
  File "/Users/kimbach/Documents/wikilabskultur/batchupload/smkbatch.py", line 652, in TestSMKAPI
    wikitext = artwork.wikitext + '\n' + license + '\n' + str(smk_categories)
TypeError: can only concatenate str (not "_Printer") to str
2021-12-10 14:42:01 can only concatenate str (not "_Printer") to str
Traceback (most recent call last):
  File "/Users/kimbach/Documents/wikilabskultur/batchupload/smkbatch.py", line 652, in TestSMKAPI
    wikitext = artwork.wikitext + '\n' + license + '\n' + str(smk_categories)
TypeError: can only concatenate str (not "_Printer") to str
2021-12-10 14:42:02 Closing network session.
2021-12-10 14:42:02 Network session closed.
2021-12-10 16:12:55 Closing network session.
2021-12-10 16:12:55 Network session closed.
2021-12-10 17:33:02 Closing network session.
2021-12-10 17:33:02 Network session closed.
2021-12-10 17:34:52 Closing network session.
2021-12-10 17:34:52 Network session closed.
2021-12-10 17:44:39 Closing network session.
2021-12-10 17:44:39 Network session closed.
2021-12-10 18:22:20 HTTPSConnectionPool(host='api.smk.dk', port=443): Read timed out. (read timeout=None)
Traceback (most recent call last):
  File "/usr/local/lib/python3.7/site-packages/urllib3/connectionpool.py", line 384, in _make_request
    six.raise_from(e, None)
  File "<string>", line 2, in raise_from
  File "/usr/local/lib/python3.7/site-packages/urllib3/connectionpool.py", line 380, in _make_request
    httplib_response = conn.getresponse()
  File "/usr/local/Cellar/python/3.7.2_1/Frameworks/Python.framework/Versions/3.7/lib/python3.7/http/client.py", line 1321, in getresponse
    response.begin()
  File "/usr/local/Cellar/python/3.7.2_1/Frameworks/Python.framework/Versions/3.7/lib/python3.7/http/client.py", line 296, in begin
    version, status, reason = self._read_status()
  File "/usr/local/Cellar/python/3.7.2_1/Frameworks/Python.framework/Versions/3.7/lib/python3.7/http/client.py", line 257, in _read_status
    line = str(self.fp.readline(_MAXLINE + 1), "iso-8859-1")
  File "/usr/local/Cellar/python/3.7.2_1/Frameworks/Python.framework/Versions/3.7/lib/python3.7/socket.py", line 589, in readinto
    return self._sock.recv_into(b)
  File "/usr/local/Cellar/python/3.7.2_1/Frameworks/Python.framework/Versions/3.7/lib/python3.7/ssl.py", line 1052, in recv_into
    return self.read(nbytes, buffer)
  File "/usr/local/Cellar/python/3.7.2_1/Frameworks/Python.framework/Versions/3.7/lib/python3.7/ssl.py", line 911, in read
    return self._sslobj.read(len, buffer)
TimeoutError: [Errno 60] Operation timed out

During handling of the above exception, another exception occurred:

Traceback (most recent call last):
  File "/usr/local/lib/python3.7/site-packages/requests/adapters.py", line 449, in send
    timeout=timeout
  File "/usr/local/lib/python3.7/site-packages/urllib3/connectionpool.py", line 638, in urlopen
    _stacktrace=sys.exc_info()[2])
  File "/usr/local/lib/python3.7/site-packages/urllib3/util/retry.py", line 367, in increment
    raise six.reraise(type(error), error, _stacktrace)
  File "/usr/local/lib/python3.7/site-packages/urllib3/packages/six.py", line 686, in reraise
    raise value
  File "/usr/local/lib/python3.7/site-packages/urllib3/connectionpool.py", line 600, in urlopen
    chunked=chunked)
  File "/usr/local/lib/python3.7/site-packages/urllib3/connectionpool.py", line 386, in _make_request
    self._raise_timeout(err=e, url=url, timeout_value=read_timeout)
  File "/usr/local/lib/python3.7/site-packages/urllib3/connectionpool.py", line 317, in _raise_timeout
    raise ReadTimeoutError(self, url, "Read timed out. (read timeout=%s)" % timeout_value)
urllib3.exceptions.ReadTimeoutError: HTTPSConnectionPool(host='api.smk.dk', port=443): Read timed out. (read timeout=None)

During handling of the above exception, another exception occurred:

Traceback (most recent call last):
  File "/Users/kimbach/Documents/wikilabskultur/batchupload/smkbatch.py", line 207, in TestSMKAPI
    smk_objects=smkapi.get_smk_objects(smk_filter,offset, rows)
  File "/Users/kimbach/Documents/wikilabskultur/batchupload/smkapi.py", line 94, in get_smk_objects
    data=json.loads(requests.get(url).text)
  File "/usr/local/lib/python3.7/site-packages/requests/api.py", line 75, in get
    return request('get', url, params=params, **kwargs)
  File "/usr/local/lib/python3.7/site-packages/requests/api.py", line 60, in request
    return session.request(method=method, url=url, **kwargs)
  File "/usr/local/lib/python3.7/site-packages/requests/sessions.py", line 533, in request
    resp = self.send(prep, **send_kwargs)
  File "/usr/local/lib/python3.7/site-packages/requests/sessions.py", line 646, in send
    r = adapter.send(request, **kwargs)
  File "/usr/local/lib/python3.7/site-packages/requests/adapters.py", line 529, in send
    raise ReadTimeout(e, request=request)
requests.exceptions.ReadTimeout: HTTPSConnectionPool(host='api.smk.dk', port=443): Read timed out. (read timeout=None)
2021-12-10 18:40:27 ('Connection aborted.', TimeoutError(60, 'Operation timed out'))
Traceback (most recent call last):
  File "/usr/local/lib/python3.7/site-packages/urllib3/connectionpool.py", line 600, in urlopen
    chunked=chunked)
  File "/usr/local/lib/python3.7/site-packages/urllib3/connectionpool.py", line 343, in _make_request
    self._validate_conn(conn)
  File "/usr/local/lib/python3.7/site-packages/urllib3/connectionpool.py", line 839, in _validate_conn
    conn.connect()
  File "/usr/local/lib/python3.7/site-packages/urllib3/connection.py", line 344, in connect
    ssl_context=context)
  File "/usr/local/lib/python3.7/site-packages/urllib3/util/ssl_.py", line 344, in ssl_wrap_socket
    return context.wrap_socket(sock, server_hostname=server_hostname)
  File "/usr/local/Cellar/python/3.7.2_1/Frameworks/Python.framework/Versions/3.7/lib/python3.7/ssl.py", line 412, in wrap_socket
    session=session
  File "/usr/local/Cellar/python/3.7.2_1/Frameworks/Python.framework/Versions/3.7/lib/python3.7/ssl.py", line 853, in _create
    self.do_handshake()
  File "/usr/local/Cellar/python/3.7.2_1/Frameworks/Python.framework/Versions/3.7/lib/python3.7/ssl.py", line 1117, in do_handshake
    self._sslobj.do_handshake()
TimeoutError: [Errno 60] Operation timed out

During handling of the above exception, another exception occurred:

Traceback (most recent call last):
  File "/usr/local/lib/python3.7/site-packages/requests/adapters.py", line 449, in send
    timeout=timeout
  File "/usr/local/lib/python3.7/site-packages/urllib3/connectionpool.py", line 638, in urlopen
    _stacktrace=sys.exc_info()[2])
  File "/usr/local/lib/python3.7/site-packages/urllib3/util/retry.py", line 367, in increment
    raise six.reraise(type(error), error, _stacktrace)
  File "/usr/local/lib/python3.7/site-packages/urllib3/packages/six.py", line 685, in reraise
    raise value.with_traceback(tb)
  File "/usr/local/lib/python3.7/site-packages/urllib3/connectionpool.py", line 600, in urlopen
    chunked=chunked)
  File "/usr/local/lib/python3.7/site-packages/urllib3/connectionpool.py", line 343, in _make_request
    self._validate_conn(conn)
  File "/usr/local/lib/python3.7/site-packages/urllib3/connectionpool.py", line 839, in _validate_conn
    conn.connect()
  File "/usr/local/lib/python3.7/site-packages/urllib3/connection.py", line 344, in connect
    ssl_context=context)
  File "/usr/local/lib/python3.7/site-packages/urllib3/util/ssl_.py", line 344, in ssl_wrap_socket
    return context.wrap_socket(sock, server_hostname=server_hostname)
  File "/usr/local/Cellar/python/3.7.2_1/Frameworks/Python.framework/Versions/3.7/lib/python3.7/ssl.py", line 412, in wrap_socket
    session=session
  File "/usr/local/Cellar/python/3.7.2_1/Frameworks/Python.framework/Versions/3.7/lib/python3.7/ssl.py", line 853, in _create
    self.do_handshake()
  File "/usr/local/Cellar/python/3.7.2_1/Frameworks/Python.framework/Versions/3.7/lib/python3.7/ssl.py", line 1117, in do_handshake
    self._sslobj.do_handshake()
urllib3.exceptions.ProtocolError: ('Connection aborted.', TimeoutError(60, 'Operation timed out'))

During handling of the above exception, another exception occurred:

Traceback (most recent call last):
  File "/Users/kimbach/Documents/wikilabskultur/batchupload/smkbatch.py", line 207, in TestSMKAPI
    smk_objects=smkapi.get_smk_objects(smk_filter,offset, rows)
  File "/Users/kimbach/Documents/wikilabskultur/batchupload/smkapi.py", line 94, in get_smk_objects
    data=json.loads(requests.get(url).text)
  File "/usr/local/lib/python3.7/site-packages/requests/api.py", line 75, in get
    return request('get', url, params=params, **kwargs)
  File "/usr/local/lib/python3.7/site-packages/requests/api.py", line 60, in request
    return session.request(method=method, url=url, **kwargs)
  File "/usr/local/lib/python3.7/site-packages/requests/sessions.py", line 533, in request
    resp = self.send(prep, **send_kwargs)
  File "/usr/local/lib/python3.7/site-packages/requests/sessions.py", line 646, in send
    r = adapter.send(request, **kwargs)
  File "/usr/local/lib/python3.7/site-packages/requests/adapters.py", line 498, in send
    raise ConnectionError(err, request=request)
requests.exceptions.ConnectionError: ('Connection aborted.', TimeoutError(60, 'Operation timed out'))
2021-12-11 12:49:08 Closing network session.
2021-12-11 12:49:08 Network session closed.
2021-12-11 13:05:45 Closing network session.
2021-12-11 13:05:45 Network session closed.
2021-12-11 23:36:35 Closing network session.
2021-12-11 23:36:35 Network session closed.
2021-12-11 23:55:56 Closing network session.
2021-12-11 23:55:56 Network session closed.
2021-12-11 23:58:06 Closing network session.
2021-12-11 23:58:06 Network session closed.
2021-12-12 00:03:58 Closing network session.
2021-12-12 00:03:58 Network session closed.
2021-12-12 00:18:44 __init__() got an unexpected keyword argument 'object_type'
Traceback (most recent call last):
  File "/Users/kimbach/Documents/wikilabskultur/batchupload/smkbatch.py", line 608, in TestSMKAPI
    image_width = smk_image_width)
TypeError: __init__() got an unexpected keyword argument 'object_type'
2021-12-12 00:18:44 __init__() got an unexpected keyword argument 'object_type'
Traceback (most recent call last):
  File "/Users/kimbach/Documents/wikilabskultur/batchupload/smkbatch.py", line 608, in TestSMKAPI
    image_width = smk_image_width)
TypeError: __init__() got an unexpected keyword argument 'object_type'
2021-12-12 00:18:45 __init__() got an unexpected keyword argument 'object_type'
Traceback (most recent call last):
  File "/Users/kimbach/Documents/wikilabskultur/batchupload/smkbatch.py", line 608, in TestSMKAPI
    image_width = smk_image_width)
TypeError: __init__() got an unexpected keyword argument 'object_type'
2021-12-12 00:18:45 __init__() got an unexpected keyword argument 'object_type'
Traceback (most recent call last):
  File "/Users/kimbach/Documents/wikilabskultur/batchupload/smkbatch.py", line 608, in TestSMKAPI
    image_width = smk_image_width)
TypeError: __init__() got an unexpected keyword argument 'object_type'
2021-12-12 00:18:45 __init__() got an unexpected keyword argument 'object_type'
Traceback (most recent call last):
  File "/Users/kimbach/Documents/wikilabskultur/batchupload/smkbatch.py", line 608, in TestSMKAPI
    image_width = smk_image_width)
TypeError: __init__() got an unexpected keyword argument 'object_type'
2021-12-12 00:18:45 __init__() got an unexpected keyword argument 'object_type'
Traceback (most recent call last):
  File "/Users/kimbach/Documents/wikilabskultur/batchupload/smkbatch.py", line 608, in TestSMKAPI
    image_width = smk_image_width)
TypeError: __init__() got an unexpected keyword argument 'object_type'
2021-12-12 00:18:46 __init__() got an unexpected keyword argument 'object_type'
Traceback (most recent call last):
  File "/Users/kimbach/Documents/wikilabskultur/batchupload/smkbatch.py", line 608, in TestSMKAPI
    image_width = smk_image_width)
TypeError: __init__() got an unexpected keyword argument 'object_type'
2021-12-12 00:18:46 __init__() got an unexpected keyword argument 'object_type'
Traceback (most recent call last):
  File "/Users/kimbach/Documents/wikilabskultur/batchupload/smkbatch.py", line 608, in TestSMKAPI
    image_width = smk_image_width)
TypeError: __init__() got an unexpected keyword argument 'object_type'
2021-12-12 00:18:46 __init__() got an unexpected keyword argument 'object_type'
Traceback (most recent call last):
  File "/Users/kimbach/Documents/wikilabskultur/batchupload/smkbatch.py", line 608, in TestSMKAPI
    image_width = smk_image_width)
TypeError: __init__() got an unexpected keyword argument 'object_type'
2021-12-12 00:18:46 __init__() got an unexpected keyword argument 'object_type'
Traceback (most recent call last):
  File "/Users/kimbach/Documents/wikilabskultur/batchupload/smkbatch.py", line 608, in TestSMKAPI
    image_width = smk_image_width)
TypeError: __init__() got an unexpected keyword argument 'object_type'
2021-12-12 00:18:47 Closing network session.
2021-12-12 00:18:47 Network session closed.
2021-12-12 00:20:46 Closing network session.
2021-12-12 00:20:46 Network session closed.
2021-12-12 00:36:11 Closing network session.
2021-12-12 00:36:11 Network session closed.
2021-12-12 00:39:10 Closing network session.
2021-12-12 00:39:10 Network session closed.
2021-12-12 01:15:41 local variable 'smk_titles' referenced before assignment
Traceback (most recent call last):
  File "/Users/kimbach/Documents/wikilabskultur/batchupload/smkbatch.py", line 411, in TestSMKAPI
    smk_titles=smk_titles+'{{' + iso_code +'|' + smk_title + '}}'
UnboundLocalError: local variable 'smk_titles' referenced before assignment
2021-12-12 01:15:41 local variable 'smk_titles' referenced before assignment
Traceback (most recent call last):
  File "/Users/kimbach/Documents/wikilabskultur/batchupload/smkbatch.py", line 411, in TestSMKAPI
    smk_titles=smk_titles+'{{' + iso_code +'|' + smk_title + '}}'
UnboundLocalError: local variable 'smk_titles' referenced before assignment
2021-12-12 01:15:42 local variable 'smk_titles' referenced before assignment
Traceback (most recent call last):
  File "/Users/kimbach/Documents/wikilabskultur/batchupload/smkbatch.py", line 411, in TestSMKAPI
    smk_titles=smk_titles+'{{' + iso_code +'|' + smk_title + '}}'
UnboundLocalError: local variable 'smk_titles' referenced before assignment
2021-12-12 01:15:42 local variable 'smk_titles' referenced before assignment
Traceback (most recent call last):
  File "/Users/kimbach/Documents/wikilabskultur/batchupload/smkbatch.py", line 411, in TestSMKAPI
    smk_titles=smk_titles+'{{' + iso_code +'|' + smk_title + '}}'
UnboundLocalError: local variable 'smk_titles' referenced before assignment
2021-12-12 01:15:42 local variable 'smk_titles' referenced before assignment
Traceback (most recent call last):
  File "/Users/kimbach/Documents/wikilabskultur/batchupload/smkbatch.py", line 411, in TestSMKAPI
    smk_titles=smk_titles+'{{' + iso_code +'|' + smk_title + '}}'
UnboundLocalError: local variable 'smk_titles' referenced before assignment
2021-12-12 01:15:42 local variable 'smk_titles' referenced before assignment
Traceback (most recent call last):
  File "/Users/kimbach/Documents/wikilabskultur/batchupload/smkbatch.py", line 411, in TestSMKAPI
    smk_titles=smk_titles+'{{' + iso_code +'|' + smk_title + '}}'
UnboundLocalError: local variable 'smk_titles' referenced before assignment
2021-12-12 01:15:43 local variable 'smk_titles' referenced before assignment
Traceback (most recent call last):
  File "/Users/kimbach/Documents/wikilabskultur/batchupload/smkbatch.py", line 411, in TestSMKAPI
    smk_titles=smk_titles+'{{' + iso_code +'|' + smk_title + '}}'
UnboundLocalError: local variable 'smk_titles' referenced before assignment
2021-12-12 01:15:43 local variable 'smk_titles' referenced before assignment
Traceback (most recent call last):
  File "/Users/kimbach/Documents/wikilabskultur/batchupload/smkbatch.py", line 411, in TestSMKAPI
    smk_titles=smk_titles+'{{' + iso_code +'|' + smk_title + '}}'
UnboundLocalError: local variable 'smk_titles' referenced before assignment
2021-12-12 01:15:43 local variable 'smk_titles' referenced before assignment
Traceback (most recent call last):
  File "/Users/kimbach/Documents/wikilabskultur/batchupload/smkbatch.py", line 411, in TestSMKAPI
    smk_titles=smk_titles+'{{' + iso_code +'|' + smk_title + '}}'
UnboundLocalError: local variable 'smk_titles' referenced before assignment
2021-12-12 01:15:43 local variable 'smk_titles' referenced before assignment
Traceback (most recent call last):
  File "/Users/kimbach/Documents/wikilabskultur/batchupload/smkbatch.py", line 411, in TestSMKAPI
    smk_titles=smk_titles+'{{' + iso_code +'|' + smk_title + '}}'
UnboundLocalError: local variable 'smk_titles' referenced before assignment
2021-12-12 01:15:44 Closing network session.
2021-12-12 01:15:44 Network session closed.
2021-12-12 01:16:34 bad operand type for unary +: 'str'
Traceback (most recent call last):
  File "/Users/kimbach/Documents/wikilabskultur/batchupload/smkbatch.py", line 619, in TestSMKAPI
    '{{ProvenanceEvent|date='+smk_acquisition_date_precision+'|type=in collection|newowner={{institution:'++'}}}}'
TypeError: bad operand type for unary +: 'str'
2021-12-12 01:16:34 bad operand type for unary +: 'str'
Traceback (most recent call last):
  File "/Users/kimbach/Documents/wikilabskultur/batchupload/smkbatch.py", line 619, in TestSMKAPI
    '{{ProvenanceEvent|date='+smk_acquisition_date_precision+'|type=in collection|newowner={{institution:'++'}}}}'
TypeError: bad operand type for unary +: 'str'
2021-12-12 01:16:34 bad operand type for unary +: 'str'
Traceback (most recent call last):
  File "/Users/kimbach/Documents/wikilabskultur/batchupload/smkbatch.py", line 619, in TestSMKAPI
    '{{ProvenanceEvent|date='+smk_acquisition_date_precision+'|type=in collection|newowner={{institution:'++'}}}}'
TypeError: bad operand type for unary +: 'str'
2021-12-12 01:16:34 bad operand type for unary +: 'str'
Traceback (most recent call last):
  File "/Users/kimbach/Documents/wikilabskultur/batchupload/smkbatch.py", line 619, in TestSMKAPI
    '{{ProvenanceEvent|date='+smk_acquisition_date_precision+'|type=in collection|newowner={{institution:'++'}}}}'
TypeError: bad operand type for unary +: 'str'
2021-12-12 01:16:34 bad operand type for unary +: 'str'
Traceback (most recent call last):
  File "/Users/kimbach/Documents/wikilabskultur/batchupload/smkbatch.py", line 619, in TestSMKAPI
    '{{ProvenanceEvent|date='+smk_acquisition_date_precision+'|type=in collection|newowner={{institution:'++'}}}}'
TypeError: bad operand type for unary +: 'str'
2021-12-12 01:16:35 bad operand type for unary +: 'str'
Traceback (most recent call last):
  File "/Users/kimbach/Documents/wikilabskultur/batchupload/smkbatch.py", line 619, in TestSMKAPI
    '{{ProvenanceEvent|date='+smk_acquisition_date_precision+'|type=in collection|newowner={{institution:'++'}}}}'
TypeError: bad operand type for unary +: 'str'
2021-12-12 01:16:35 bad operand type for unary +: 'str'
Traceback (most recent call last):
  File "/Users/kimbach/Documents/wikilabskultur/batchupload/smkbatch.py", line 619, in TestSMKAPI
    '{{ProvenanceEvent|date='+smk_acquisition_date_precision+'|type=in collection|newowner={{institution:'++'}}}}'
TypeError: bad operand type for unary +: 'str'
2021-12-12 01:16:35 bad operand type for unary +: 'str'
Traceback (most recent call last):
  File "/Users/kimbach/Documents/wikilabskultur/batchupload/smkbatch.py", line 619, in TestSMKAPI
    '{{ProvenanceEvent|date='+smk_acquisition_date_precision+'|type=in collection|newowner={{institution:'++'}}}}'
TypeError: bad operand type for unary +: 'str'
2021-12-12 01:16:35 bad operand type for unary +: 'str'
Traceback (most recent call last):
  File "/Users/kimbach/Documents/wikilabskultur/batchupload/smkbatch.py", line 619, in TestSMKAPI
    '{{ProvenanceEvent|date='+smk_acquisition_date_precision+'|type=in collection|newowner={{institution:'++'}}}}'
TypeError: bad operand type for unary +: 'str'
2021-12-12 01:16:36 bad operand type for unary +: 'str'
Traceback (most recent call last):
  File "/Users/kimbach/Documents/wikilabskultur/batchupload/smkbatch.py", line 619, in TestSMKAPI
    '{{ProvenanceEvent|date='+smk_acquisition_date_precision+'|type=in collection|newowner={{institution:'++'}}}}'
TypeError: bad operand type for unary +: 'str'
2021-12-12 01:16:36 Closing network session.
2021-12-12 01:16:36 Network session closed.
2021-12-12 01:18:21 Closing network session.
2021-12-12 01:18:21 Network session closed.
2021-12-12 01:24:20 Closing network session.
2021-12-12 01:24:20 Network session closed.
