2021-10-12 20:11:04 Found 1 wikidata:wikidata processes running, including this one.
2021-10-12 20:11:29 API warning (main): Subscribe to the mediawiki-api-announce mailing list at <https://lists.wikimedia.org/postorius/lists/mediawiki-api-announce.lists.wikimedia.org/> for notice of API deprecations and breaking changes. Use [[Special:ApiFeatureUsage]] to see usage of deprecated features by your application.
2021-10-12 20:11:29 API warning (revisions): Because "rvslots" was not specified, a legacy format has been used for the output. This format is deprecated, and in the future the new format will always be used.
2021-10-12 20:11:29 API warning (main): Subscribe to the mediawiki-api-announce mailing list at <https://lists.wikimedia.org/postorius/lists/mediawiki-api-announce.lists.wikimedia.org/> for notice of API deprecations and breaking changes. Use [[Special:ApiFeatureUsage]] to see usage of deprecated features by your application.
2021-10-12 20:11:29 API warning (revisions): Because "rvslots" was not specified, a legacy format has been used for the output. This format is deprecated, and in the future the new format will always be used.
2021-10-12 20:11:30 API warning (main): Subscribe to the mediawiki-api-announce mailing list at <https://lists.wikimedia.org/postorius/lists/mediawiki-api-announce.lists.wikimedia.org/> for notice of API deprecations and breaking changes. Use [[Special:ApiFeatureUsage]] to see usage of deprecated features by your application.
2021-10-12 20:11:30 API warning (revisions): Because "rvslots" was not specified, a legacy format has been used for the output. This format is deprecated, and in the future the new format will always be used.
2021-10-12 20:13:32 API warning (main): Subscribe to the mediawiki-api-announce mailing list at <https://lists.wikimedia.org/postorius/lists/mediawiki-api-announce.lists.wikimedia.org/> for notice of API deprecations and breaking changes. Use [[Special:ApiFeatureUsage]] to see usage of deprecated features by your application.
2021-10-12 20:13:32 API warning (revisions): Because "rvslots" was not specified, a legacy format has been used for the output. This format is deprecated, and in the future the new format will always be used.
2021-10-12 20:17:03 Found 2 wikidata:wikidata processes running, including this one.
2021-10-12 20:17:03 Found 1 commons:commons processes running, including this one.
2021-10-12 21:13:54 Found 1 wikidata:wikidata processes running, including this one.
2021-10-12 21:13:54 Found 1 commons:commons processes running, including this one.
2021-10-12 21:18:54 Found 1 wikidata:wikidata processes running, including this one.
2021-10-12 21:18:55 Found 1 commons:commons processes running, including this one.
2021-10-12 21:21:42 Pausing due to database lag: Waiting for 10.64.0.128: 5.154561 seconds lagged.
2021-10-12 21:21:42 Sleeping for 5.0 seconds, 2021-10-12 21:21:42
2021-10-12 21:21:47 Pausing due to database lag: Waiting for 10.64.48.173: 10.329941 seconds lagged.
2021-10-12 21:21:47 Sleeping for 5.0 seconds, 2021-10-12 21:21:47
2021-10-12 21:23:54 Found 1 wikidata:wikidata processes running, including this one.
2021-10-12 21:23:55 Found 1 commons:commons processes running, including this one.
2021-10-12 21:28:55 Found 1 wikidata:wikidata processes running, including this one.
2021-10-12 21:28:55 Found 1 commons:commons processes running, including this one.
2021-10-12 21:33:55 Found 1 wikidata:wikidata processes running, including this one.
2021-10-12 21:33:56 Found 1 commons:commons processes running, including this one.
2021-10-12 21:38:55 Found 1 wikidata:wikidata processes running, including this one.
2021-10-12 21:38:57 Found 1 commons:commons processes running, including this one.
2021-10-12 21:43:55 Found 1 wikidata:wikidata processes running, including this one.
2021-10-12 21:43:57 Found 1 commons:commons processes running, including this one.
2021-10-12 21:44:56 Pausing due to database lag: Waiting for 10.64.0.154: 5.10616 seconds lagged.
2021-10-12 21:44:56 Sleeping for 5.0 seconds, 2021-10-12 21:44:56
2021-10-12 21:48:56 Found 1 wikidata:wikidata processes running, including this one.
2021-10-12 21:48:57 Found 1 commons:commons processes running, including this one.
2021-10-12 21:53:56 Found 1 wikidata:wikidata processes running, including this one.
2021-10-12 21:53:57 Found 1 commons:commons processes running, including this one.
2021-10-12 21:57:59 Dropped throttle(s).
2021-10-12 21:57:59 Closing network session.
2021-10-12 21:57:59 Network session closed.
2021-10-15 15:32:43 Found 1 wikidata:wikidata processes running, including this one.
2021-10-15 15:32:51 Found 1 commons:commons processes running, including this one.
2021-12-07 18:07:49 Found 1 wikidata:wikidata processes running, including this one.
2021-12-07 18:07:57 Found 1 commons:commons processes running, including this one.
2021-12-07 18:12:49 Found 1 wikidata:wikidata processes running, including this one.
2021-12-07 18:12:57 Found 1 commons:commons processes running, including this one.
2021-12-07 18:17:49 Found 1 wikidata:wikidata processes running, including this one.
2021-12-07 18:17:57 Found 1 commons:commons processes running, including this one.
2021-12-07 18:22:50 Found 1 wikidata:wikidata processes running, including this one.
2021-12-07 18:22:57 Found 1 commons:commons processes running, including this one.
2021-12-07 18:27:50 Found 1 wikidata:wikidata processes running, including this one.
2021-12-07 18:27:57 Found 1 commons:commons processes running, including this one.
2021-12-07 18:32:50 Found 1 wikidata:wikidata processes running, including this one.
2021-12-07 18:32:57 Found 1 commons:commons processes running, including this one.
2021-12-07 18:37:51 Found 1 wikidata:wikidata processes running, including this one.
2021-12-07 18:37:58 Found 1 commons:commons processes running, including this one.
2021-12-07 18:42:51 Found 1 wikidata:wikidata processes running, including this one.
2021-12-07 18:42:58 Found 1 commons:commons processes running, including this one.
2021-12-07 18:47:52 Found 1 wikidata:wikidata processes running, including this one.
2021-12-07 18:47:59 Found 1 commons:commons processes running, including this one.
2021-12-07 18:52:52 Found 1 wikidata:wikidata processes running, including this one.
2021-12-07 18:52:59 Found 1 commons:commons processes running, including this one.
2021-12-07 18:53:00 Dropped throttle(s).
2021-12-07 18:53:00 Closing network session.
2021-12-07 18:53:00 Network session closed.
2021-12-07 21:08:49 Found 1 wikidata:wikidata processes running, including this one.
2021-12-07 21:08:50 Found 1 commons:commons processes running, including this one.
2021-12-07 21:09:51 Found 2 wikidata:wikidata processes running, including this one.
2021-12-07 21:09:52 Found 2 commons:commons processes running, including this one.
2021-12-07 21:14:51 Found 2 wikidata:wikidata processes running, including this one.
2021-12-07 21:14:52 Found 2 commons:commons processes running, including this one.
2021-12-07 21:50:28 Traceback (most recent call last):
  File "/usr/local/lib/python3.7/site-packages/urllib3/connectionpool.py", line 384, in _make_request
    six.raise_from(e, None)
  File "<string>", line 2, in raise_from
  File "/usr/local/lib/python3.7/site-packages/urllib3/connectionpool.py", line 380, in _make_request
    httplib_response = conn.getresponse()
  File "/usr/local/Cellar/python/3.7.2_1/Frameworks/Python.framework/Versions/3.7/lib/python3.7/http/client.py", line 1321, in getresponse
    response.begin()
  File "/usr/local/Cellar/python/3.7.2_1/Frameworks/Python.framework/Versions/3.7/lib/python3.7/http/client.py", line 296, in begin
    version, status, reason = self._read_status()
  File "/usr/local/Cellar/python/3.7.2_1/Frameworks/Python.framework/Versions/3.7/lib/python3.7/http/client.py", line 257, in _read_status
    line = str(self.fp.readline(_MAXLINE + 1), "iso-8859-1")
  File "/usr/local/Cellar/python/3.7.2_1/Frameworks/Python.framework/Versions/3.7/lib/python3.7/socket.py", line 589, in readinto
    return self._sock.recv_into(b)
  File "/usr/local/Cellar/python/3.7.2_1/Frameworks/Python.framework/Versions/3.7/lib/python3.7/ssl.py", line 1052, in recv_into
    return self.read(nbytes, buffer)
  File "/usr/local/Cellar/python/3.7.2_1/Frameworks/Python.framework/Versions/3.7/lib/python3.7/ssl.py", line 911, in read
    return self._sslobj.read(len, buffer)
socket.timeout: The read operation timed out

During handling of the above exception, another exception occurred:

Traceback (most recent call last):
  File "/usr/local/lib/python3.7/site-packages/requests/adapters.py", line 449, in send
    timeout=timeout
  File "/usr/local/lib/python3.7/site-packages/urllib3/connectionpool.py", line 638, in urlopen
    _stacktrace=sys.exc_info()[2])
  File "/usr/local/lib/python3.7/site-packages/urllib3/util/retry.py", line 367, in increment
    raise six.reraise(type(error), error, _stacktrace)
  File "/usr/local/lib/python3.7/site-packages/urllib3/packages/six.py", line 686, in reraise
    raise value
  File "/usr/local/lib/python3.7/site-packages/urllib3/connectionpool.py", line 600, in urlopen
    chunked=chunked)
  File "/usr/local/lib/python3.7/site-packages/urllib3/connectionpool.py", line 386, in _make_request
    self._raise_timeout(err=e, url=url, timeout_value=read_timeout)
  File "/usr/local/lib/python3.7/site-packages/urllib3/connectionpool.py", line 306, in _raise_timeout
    raise ReadTimeoutError(self, url, "Read timed out. (read timeout=%s)" % timeout_value)
urllib3.exceptions.ReadTimeoutError: HTTPSConnectionPool(host='commons.wikimedia.org', port=443): Read timed out. (read timeout=45)

During handling of the above exception, another exception occurred:

Traceback (most recent call last):
  File "/usr/local/lib/python3.7/site-packages/pywikibot/data/api.py", line 1966, in submit
    body=body, headers=headers)
  File "/usr/local/lib/python3.7/site-packages/pywikibot/tools/__init__.py", line 1446, in wrapper
    return obj(*__args, **__kw)
  File "/usr/local/lib/python3.7/site-packages/pywikibot/comms/http.py", line 317, in request
    r = fetch(baseuri, method, params, body, headers, **kwargs)
  File "/usr/local/lib/python3.7/site-packages/pywikibot/comms/http.py", line 519, in fetch
    error_handling_callback(request)
  File "/usr/local/lib/python3.7/site-packages/pywikibot/comms/http.py", line 405, in error_handling_callback
    raise request.data
  File "/usr/local/lib/python3.7/site-packages/pywikibot/comms/http.py", line 384, in _http_process
    **http_request.kwargs)
  File "/usr/local/lib/python3.7/site-packages/requests/sessions.py", line 533, in request
    resp = self.send(prep, **send_kwargs)
  File "/usr/local/lib/python3.7/site-packages/requests/sessions.py", line 646, in send
    r = adapter.send(request, **kwargs)
  File "/usr/local/lib/python3.7/site-packages/requests/adapters.py", line 529, in send
    raise ReadTimeout(e, request=request)
requests.exceptions.ReadTimeout: HTTPSConnectionPool(host='commons.wikimedia.org', port=443): Read timed out. (read timeout=45)

2021-12-07 21:50:28 /w/api.php, iiprop=timestamp%7Cuser%7Ccomment%7Curl%7Csize%7Csha1%7Cmime%7Cmetadata%7Carchivename&titles=File%3AC.G.+Pilo+-+Aeneas+hindres+af+Venus+i+sin+h%C3%A6vn+mod+Helena%2C+som+har+s%C3%B8gt+tilflugt+ved+Cybeles+alter+-+KMS7320+-+Statens+Museum+for+Kunst.jpg&prop=imageinfo&action=query&indexpageids=&continue=&iilimit=500&meta=userinfo&uiprop=blockinfo%7Chasmsg&maxlag=5&format=json
2021-12-07 21:50:28 Waiting 5 seconds before retrying.
2021-12-07 21:50:33 Found 1 commons:commons processes running, including this one.
2021-12-07 21:50:57 Found 1 wikidata:wikidata processes running, including this one.
2021-12-07 21:50:57 Traceback (most recent call last):
  File "/usr/local/lib/python3.7/site-packages/urllib3/connectionpool.py", line 600, in urlopen
    chunked=chunked)
  File "/usr/local/lib/python3.7/site-packages/urllib3/connectionpool.py", line 384, in _make_request
    six.raise_from(e, None)
  File "<string>", line 2, in raise_from
  File "/usr/local/lib/python3.7/site-packages/urllib3/connectionpool.py", line 380, in _make_request
    httplib_response = conn.getresponse()
  File "/usr/local/Cellar/python/3.7.2_1/Frameworks/Python.framework/Versions/3.7/lib/python3.7/http/client.py", line 1321, in getresponse
    response.begin()
  File "/usr/local/Cellar/python/3.7.2_1/Frameworks/Python.framework/Versions/3.7/lib/python3.7/http/client.py", line 296, in begin
    version, status, reason = self._read_status()
  File "/usr/local/Cellar/python/3.7.2_1/Frameworks/Python.framework/Versions/3.7/lib/python3.7/http/client.py", line 257, in _read_status
    line = str(self.fp.readline(_MAXLINE + 1), "iso-8859-1")
  File "/usr/local/Cellar/python/3.7.2_1/Frameworks/Python.framework/Versions/3.7/lib/python3.7/socket.py", line 589, in readinto
    return self._sock.recv_into(b)
  File "/usr/local/Cellar/python/3.7.2_1/Frameworks/Python.framework/Versions/3.7/lib/python3.7/ssl.py", line 1052, in recv_into
    return self.read(nbytes, buffer)
  File "/usr/local/Cellar/python/3.7.2_1/Frameworks/Python.framework/Versions/3.7/lib/python3.7/ssl.py", line 911, in read
    return self._sslobj.read(len, buffer)
ConnectionResetError: [Errno 54] Connection reset by peer

During handling of the above exception, another exception occurred:

Traceback (most recent call last):
  File "/usr/local/lib/python3.7/site-packages/requests/adapters.py", line 449, in send
    timeout=timeout
  File "/usr/local/lib/python3.7/site-packages/urllib3/connectionpool.py", line 638, in urlopen
    _stacktrace=sys.exc_info()[2])
  File "/usr/local/lib/python3.7/site-packages/urllib3/util/retry.py", line 367, in increment
    raise six.reraise(type(error), error, _stacktrace)
  File "/usr/local/lib/python3.7/site-packages/urllib3/packages/six.py", line 685, in reraise
    raise value.with_traceback(tb)
  File "/usr/local/lib/python3.7/site-packages/urllib3/connectionpool.py", line 600, in urlopen
    chunked=chunked)
  File "/usr/local/lib/python3.7/site-packages/urllib3/connectionpool.py", line 384, in _make_request
    six.raise_from(e, None)
  File "<string>", line 2, in raise_from
  File "/usr/local/lib/python3.7/site-packages/urllib3/connectionpool.py", line 380, in _make_request
    httplib_response = conn.getresponse()
  File "/usr/local/Cellar/python/3.7.2_1/Frameworks/Python.framework/Versions/3.7/lib/python3.7/http/client.py", line 1321, in getresponse
    response.begin()
  File "/usr/local/Cellar/python/3.7.2_1/Frameworks/Python.framework/Versions/3.7/lib/python3.7/http/client.py", line 296, in begin
    version, status, reason = self._read_status()
  File "/usr/local/Cellar/python/3.7.2_1/Frameworks/Python.framework/Versions/3.7/lib/python3.7/http/client.py", line 257, in _read_status
    line = str(self.fp.readline(_MAXLINE + 1), "iso-8859-1")
  File "/usr/local/Cellar/python/3.7.2_1/Frameworks/Python.framework/Versions/3.7/lib/python3.7/socket.py", line 589, in readinto
    return self._sock.recv_into(b)
  File "/usr/local/Cellar/python/3.7.2_1/Frameworks/Python.framework/Versions/3.7/lib/python3.7/ssl.py", line 1052, in recv_into
    return self.read(nbytes, buffer)
  File "/usr/local/Cellar/python/3.7.2_1/Frameworks/Python.framework/Versions/3.7/lib/python3.7/ssl.py", line 911, in read
    return self._sslobj.read(len, buffer)
urllib3.exceptions.ProtocolError: ('Connection aborted.', ConnectionResetError(54, 'Connection reset by peer'))

During handling of the above exception, another exception occurred:

Traceback (most recent call last):
  File "/usr/local/lib/python3.7/site-packages/pywikibot/data/api.py", line 1966, in submit
    body=body, headers=headers)
  File "/usr/local/lib/python3.7/site-packages/pywikibot/tools/__init__.py", line 1446, in wrapper
    return obj(*__args, **__kw)
  File "/usr/local/lib/python3.7/site-packages/pywikibot/comms/http.py", line 317, in request
    r = fetch(baseuri, method, params, body, headers, **kwargs)
  File "/usr/local/lib/python3.7/site-packages/pywikibot/comms/http.py", line 519, in fetch
    error_handling_callback(request)
  File "/usr/local/lib/python3.7/site-packages/pywikibot/comms/http.py", line 405, in error_handling_callback
    raise request.data
  File "/usr/local/lib/python3.7/site-packages/pywikibot/comms/http.py", line 384, in _http_process
    **http_request.kwargs)
  File "/usr/local/lib/python3.7/site-packages/requests/sessions.py", line 533, in request
    resp = self.send(prep, **send_kwargs)
  File "/usr/local/lib/python3.7/site-packages/requests/sessions.py", line 646, in send
    r = adapter.send(request, **kwargs)
  File "/usr/local/lib/python3.7/site-packages/requests/adapters.py", line 498, in send
    raise ConnectionError(err, request=request)
requests.exceptions.ConnectionError: ('Connection aborted.', ConnectionResetError(54, 'Connection reset by peer'))

2021-12-07 21:50:57 /w/api.php?ids=Q20465119&action=wbgetentities&maxlag=5&format=json, ids=Q20465119&action=wbgetentities&maxlag=5&format=json
2021-12-07 21:50:57 Waiting 5 seconds before retrying.
2021-12-07 22:16:35 Traceback (most recent call last):
  File "/usr/local/lib/python3.7/site-packages/urllib3/connectionpool.py", line 384, in _make_request
    six.raise_from(e, None)
  File "<string>", line 2, in raise_from
  File "/usr/local/lib/python3.7/site-packages/urllib3/connectionpool.py", line 380, in _make_request
    httplib_response = conn.getresponse()
  File "/usr/local/Cellar/python/3.7.2_1/Frameworks/Python.framework/Versions/3.7/lib/python3.7/http/client.py", line 1321, in getresponse
    response.begin()
  File "/usr/local/Cellar/python/3.7.2_1/Frameworks/Python.framework/Versions/3.7/lib/python3.7/http/client.py", line 296, in begin
    version, status, reason = self._read_status()
  File "/usr/local/Cellar/python/3.7.2_1/Frameworks/Python.framework/Versions/3.7/lib/python3.7/http/client.py", line 257, in _read_status
    line = str(self.fp.readline(_MAXLINE + 1), "iso-8859-1")
  File "/usr/local/Cellar/python/3.7.2_1/Frameworks/Python.framework/Versions/3.7/lib/python3.7/socket.py", line 589, in readinto
    return self._sock.recv_into(b)
  File "/usr/local/Cellar/python/3.7.2_1/Frameworks/Python.framework/Versions/3.7/lib/python3.7/ssl.py", line 1052, in recv_into
    return self.read(nbytes, buffer)
  File "/usr/local/Cellar/python/3.7.2_1/Frameworks/Python.framework/Versions/3.7/lib/python3.7/ssl.py", line 911, in read
    return self._sslobj.read(len, buffer)
socket.timeout: The read operation timed out

During handling of the above exception, another exception occurred:

Traceback (most recent call last):
  File "/usr/local/lib/python3.7/site-packages/requests/adapters.py", line 449, in send
    timeout=timeout
  File "/usr/local/lib/python3.7/site-packages/urllib3/connectionpool.py", line 638, in urlopen
    _stacktrace=sys.exc_info()[2])
  File "/usr/local/lib/python3.7/site-packages/urllib3/util/retry.py", line 367, in increment
    raise six.reraise(type(error), error, _stacktrace)
  File "/usr/local/lib/python3.7/site-packages/urllib3/packages/six.py", line 686, in reraise
    raise value
  File "/usr/local/lib/python3.7/site-packages/urllib3/connectionpool.py", line 600, in urlopen
    chunked=chunked)
  File "/usr/local/lib/python3.7/site-packages/urllib3/connectionpool.py", line 386, in _make_request
    self._raise_timeout(err=e, url=url, timeout_value=read_timeout)
  File "/usr/local/lib/python3.7/site-packages/urllib3/connectionpool.py", line 306, in _raise_timeout
    raise ReadTimeoutError(self, url, "Read timed out. (read timeout=%s)" % timeout_value)
urllib3.exceptions.ReadTimeoutError: HTTPSConnectionPool(host='www.wikidata.org', port=443): Read timed out. (read timeout=45)

During handling of the above exception, another exception occurred:

Traceback (most recent call last):
  File "/usr/local/lib/python3.7/site-packages/pywikibot/data/api.py", line 1966, in submit
    body=body, headers=headers)
  File "/usr/local/lib/python3.7/site-packages/pywikibot/tools/__init__.py", line 1446, in wrapper
    return obj(*__args, **__kw)
  File "/usr/local/lib/python3.7/site-packages/pywikibot/comms/http.py", line 317, in request
    r = fetch(baseuri, method, params, body, headers, **kwargs)
  File "/usr/local/lib/python3.7/site-packages/pywikibot/comms/http.py", line 519, in fetch
    error_handling_callback(request)
  File "/usr/local/lib/python3.7/site-packages/pywikibot/comms/http.py", line 405, in error_handling_callback
    raise request.data
  File "/usr/local/lib/python3.7/site-packages/pywikibot/comms/http.py", line 384, in _http_process
    **http_request.kwargs)
  File "/usr/local/lib/python3.7/site-packages/requests/sessions.py", line 533, in request
    resp = self.send(prep, **send_kwargs)
  File "/usr/local/lib/python3.7/site-packages/requests/sessions.py", line 646, in send
    r = adapter.send(request, **kwargs)
  File "/usr/local/lib/python3.7/site-packages/requests/adapters.py", line 529, in send
    raise ReadTimeout(e, request=request)
requests.exceptions.ReadTimeout: HTTPSConnectionPool(host='www.wikidata.org', port=443): Read timed out. (read timeout=45)

2021-12-07 22:16:35 /w/api.php?ids=Q20380221&action=wbgetentities&maxlag=5&format=json, ids=Q20380221&action=wbgetentities&maxlag=5&format=json
2021-12-07 22:16:35 Waiting 5 seconds before retrying.
2021-12-07 22:16:40 Found 1 wikidata:wikidata processes running, including this one.
2021-12-07 22:16:41 Found 1 commons:commons processes running, including this one.
2021-12-07 22:16:41 Traceback (most recent call last):
  File "/usr/local/lib/python3.7/site-packages/urllib3/connectionpool.py", line 600, in urlopen
    chunked=chunked)
  File "/usr/local/lib/python3.7/site-packages/urllib3/connectionpool.py", line 384, in _make_request
    six.raise_from(e, None)
  File "<string>", line 2, in raise_from
  File "/usr/local/lib/python3.7/site-packages/urllib3/connectionpool.py", line 380, in _make_request
    httplib_response = conn.getresponse()
  File "/usr/local/Cellar/python/3.7.2_1/Frameworks/Python.framework/Versions/3.7/lib/python3.7/http/client.py", line 1321, in getresponse
    response.begin()
  File "/usr/local/Cellar/python/3.7.2_1/Frameworks/Python.framework/Versions/3.7/lib/python3.7/http/client.py", line 296, in begin
    version, status, reason = self._read_status()
  File "/usr/local/Cellar/python/3.7.2_1/Frameworks/Python.framework/Versions/3.7/lib/python3.7/http/client.py", line 257, in _read_status
    line = str(self.fp.readline(_MAXLINE + 1), "iso-8859-1")
  File "/usr/local/Cellar/python/3.7.2_1/Frameworks/Python.framework/Versions/3.7/lib/python3.7/socket.py", line 589, in readinto
    return self._sock.recv_into(b)
  File "/usr/local/Cellar/python/3.7.2_1/Frameworks/Python.framework/Versions/3.7/lib/python3.7/ssl.py", line 1052, in recv_into
    return self.read(nbytes, buffer)
  File "/usr/local/Cellar/python/3.7.2_1/Frameworks/Python.framework/Versions/3.7/lib/python3.7/ssl.py", line 911, in read
    return self._sslobj.read(len, buffer)
ConnectionResetError: [Errno 54] Connection reset by peer

During handling of the above exception, another exception occurred:

Traceback (most recent call last):
  File "/usr/local/lib/python3.7/site-packages/requests/adapters.py", line 449, in send
    timeout=timeout
  File "/usr/local/lib/python3.7/site-packages/urllib3/connectionpool.py", line 638, in urlopen
    _stacktrace=sys.exc_info()[2])
  File "/usr/local/lib/python3.7/site-packages/urllib3/util/retry.py", line 367, in increment
    raise six.reraise(type(error), error, _stacktrace)
  File "/usr/local/lib/python3.7/site-packages/urllib3/packages/six.py", line 685, in reraise
    raise value.with_traceback(tb)
  File "/usr/local/lib/python3.7/site-packages/urllib3/connectionpool.py", line 600, in urlopen
    chunked=chunked)
  File "/usr/local/lib/python3.7/site-packages/urllib3/connectionpool.py", line 384, in _make_request
    six.raise_from(e, None)
  File "<string>", line 2, in raise_from
  File "/usr/local/lib/python3.7/site-packages/urllib3/connectionpool.py", line 380, in _make_request
    httplib_response = conn.getresponse()
  File "/usr/local/Cellar/python/3.7.2_1/Frameworks/Python.framework/Versions/3.7/lib/python3.7/http/client.py", line 1321, in getresponse
    response.begin()
  File "/usr/local/Cellar/python/3.7.2_1/Frameworks/Python.framework/Versions/3.7/lib/python3.7/http/client.py", line 296, in begin
    version, status, reason = self._read_status()
  File "/usr/local/Cellar/python/3.7.2_1/Frameworks/Python.framework/Versions/3.7/lib/python3.7/http/client.py", line 257, in _read_status
    line = str(self.fp.readline(_MAXLINE + 1), "iso-8859-1")
  File "/usr/local/Cellar/python/3.7.2_1/Frameworks/Python.framework/Versions/3.7/lib/python3.7/socket.py", line 589, in readinto
    return self._sock.recv_into(b)
  File "/usr/local/Cellar/python/3.7.2_1/Frameworks/Python.framework/Versions/3.7/lib/python3.7/ssl.py", line 1052, in recv_into
    return self.read(nbytes, buffer)
  File "/usr/local/Cellar/python/3.7.2_1/Frameworks/Python.framework/Versions/3.7/lib/python3.7/ssl.py", line 911, in read
    return self._sslobj.read(len, buffer)
urllib3.exceptions.ProtocolError: ('Connection aborted.', ConnectionResetError(54, 'Connection reset by peer'))

During handling of the above exception, another exception occurred:

Traceback (most recent call last):
  File "/usr/local/lib/python3.7/site-packages/pywikibot/data/api.py", line 1966, in submit
    body=body, headers=headers)
  File "/usr/local/lib/python3.7/site-packages/pywikibot/tools/__init__.py", line 1446, in wrapper
    return obj(*__args, **__kw)
  File "/usr/local/lib/python3.7/site-packages/pywikibot/comms/http.py", line 317, in request
    r = fetch(baseuri, method, params, body, headers, **kwargs)
  File "/usr/local/lib/python3.7/site-packages/pywikibot/comms/http.py", line 519, in fetch
    error_handling_callback(request)
  File "/usr/local/lib/python3.7/site-packages/pywikibot/comms/http.py", line 405, in error_handling_callback
    raise request.data
  File "/usr/local/lib/python3.7/site-packages/pywikibot/comms/http.py", line 384, in _http_process
    **http_request.kwargs)
  File "/usr/local/lib/python3.7/site-packages/requests/sessions.py", line 533, in request
    resp = self.send(prep, **send_kwargs)
  File "/usr/local/lib/python3.7/site-packages/requests/sessions.py", line 646, in send
    r = adapter.send(request, **kwargs)
  File "/usr/local/lib/python3.7/site-packages/requests/adapters.py", line 498, in send
    raise ConnectionError(err, request=request)
requests.exceptions.ConnectionError: ('Connection aborted.', ConnectionResetError(54, 'Connection reset by peer'))

2021-12-07 22:16:41 /w/api.php, iiprop=timestamp%7Cuser%7Ccomment%7Curl%7Csize%7Csha1%7Cmime%7Cmetadata%7Carchivename&titles=File%3ALudvig+Karsten+-+View+of+Nyhavn+-+Fra+Nyhavn+-+Statens+Museum+for+Kunst+-+2020903+KMS6647.jpg&prop=imageinfo&action=query&indexpageids=&continue=&iilimit=500&meta=userinfo&uiprop=blockinfo%7Chasmsg&maxlag=5&format=json
2021-12-07 22:16:41 Waiting 5 seconds before retrying.
2021-12-07 22:21:40 Found 1 wikidata:wikidata processes running, including this one.
2021-12-07 22:21:41 Found 1 commons:commons processes running, including this one.
2021-12-07 22:26:40 Found 1 wikidata:wikidata processes running, including this one.
2021-12-07 22:26:41 Found 1 commons:commons processes running, including this one.
2021-12-07 22:31:40 Found 1 wikidata:wikidata processes running, including this one.
2021-12-07 22:31:41 Found 1 commons:commons processes running, including this one.
2021-12-07 22:42:44 Traceback (most recent call last):
  File "/usr/local/lib/python3.7/site-packages/urllib3/connectionpool.py", line 384, in _make_request
    six.raise_from(e, None)
  File "<string>", line 2, in raise_from
  File "/usr/local/lib/python3.7/site-packages/urllib3/connectionpool.py", line 380, in _make_request
    httplib_response = conn.getresponse()
  File "/usr/local/Cellar/python/3.7.2_1/Frameworks/Python.framework/Versions/3.7/lib/python3.7/http/client.py", line 1321, in getresponse
    response.begin()
  File "/usr/local/Cellar/python/3.7.2_1/Frameworks/Python.framework/Versions/3.7/lib/python3.7/http/client.py", line 296, in begin
    version, status, reason = self._read_status()
  File "/usr/local/Cellar/python/3.7.2_1/Frameworks/Python.framework/Versions/3.7/lib/python3.7/http/client.py", line 257, in _read_status
    line = str(self.fp.readline(_MAXLINE + 1), "iso-8859-1")
  File "/usr/local/Cellar/python/3.7.2_1/Frameworks/Python.framework/Versions/3.7/lib/python3.7/socket.py", line 589, in readinto
    return self._sock.recv_into(b)
  File "/usr/local/Cellar/python/3.7.2_1/Frameworks/Python.framework/Versions/3.7/lib/python3.7/ssl.py", line 1052, in recv_into
    return self.read(nbytes, buffer)
  File "/usr/local/Cellar/python/3.7.2_1/Frameworks/Python.framework/Versions/3.7/lib/python3.7/ssl.py", line 911, in read
    return self._sslobj.read(len, buffer)
socket.timeout: The read operation timed out

During handling of the above exception, another exception occurred:

Traceback (most recent call last):
  File "/usr/local/lib/python3.7/site-packages/requests/adapters.py", line 449, in send
    timeout=timeout
  File "/usr/local/lib/python3.7/site-packages/urllib3/connectionpool.py", line 638, in urlopen
    _stacktrace=sys.exc_info()[2])
  File "/usr/local/lib/python3.7/site-packages/urllib3/util/retry.py", line 367, in increment
    raise six.reraise(type(error), error, _stacktrace)
  File "/usr/local/lib/python3.7/site-packages/urllib3/packages/six.py", line 686, in reraise
    raise value
  File "/usr/local/lib/python3.7/site-packages/urllib3/connectionpool.py", line 600, in urlopen
    chunked=chunked)
  File "/usr/local/lib/python3.7/site-packages/urllib3/connectionpool.py", line 386, in _make_request
    self._raise_timeout(err=e, url=url, timeout_value=read_timeout)
  File "/usr/local/lib/python3.7/site-packages/urllib3/connectionpool.py", line 306, in _raise_timeout
    raise ReadTimeoutError(self, url, "Read timed out. (read timeout=%s)" % timeout_value)
urllib3.exceptions.ReadTimeoutError: HTTPSConnectionPool(host='www.wikidata.org', port=443): Read timed out. (read timeout=45)

During handling of the above exception, another exception occurred:

Traceback (most recent call last):
  File "/usr/local/lib/python3.7/site-packages/pywikibot/data/api.py", line 1966, in submit
    body=body, headers=headers)
  File "/usr/local/lib/python3.7/site-packages/pywikibot/tools/__init__.py", line 1446, in wrapper
    return obj(*__args, **__kw)
  File "/usr/local/lib/python3.7/site-packages/pywikibot/comms/http.py", line 317, in request
    r = fetch(baseuri, method, params, body, headers, **kwargs)
  File "/usr/local/lib/python3.7/site-packages/pywikibot/comms/http.py", line 519, in fetch
    error_handling_callback(request)
  File "/usr/local/lib/python3.7/site-packages/pywikibot/comms/http.py", line 405, in error_handling_callback
    raise request.data
  File "/usr/local/lib/python3.7/site-packages/pywikibot/comms/http.py", line 384, in _http_process
    **http_request.kwargs)
  File "/usr/local/lib/python3.7/site-packages/requests/sessions.py", line 533, in request
    resp = self.send(prep, **send_kwargs)
  File "/usr/local/lib/python3.7/site-packages/requests/sessions.py", line 646, in send
    r = adapter.send(request, **kwargs)
  File "/usr/local/lib/python3.7/site-packages/requests/adapters.py", line 529, in send
    raise ReadTimeout(e, request=request)
requests.exceptions.ReadTimeout: HTTPSConnectionPool(host='www.wikidata.org', port=443): Read timed out. (read timeout=45)

2021-12-07 22:42:44 /w/api.php?ids=Q20440492&action=wbgetentities&maxlag=5&format=json, ids=Q20440492&action=wbgetentities&maxlag=5&format=json
2021-12-07 22:42:44 Waiting 5 seconds before retrying.
2021-12-07 22:42:49 Found 1 wikidata:wikidata processes running, including this one.
2021-12-07 22:48:55 Found 1 wikidata:wikidata processes running, including this one.
2021-12-07 22:48:56 Found 1 commons:commons processes running, including this one.
2021-12-07 22:48:56 Traceback (most recent call last):
  File "/usr/local/lib/python3.7/site-packages/urllib3/connectionpool.py", line 600, in urlopen
    chunked=chunked)
  File "/usr/local/lib/python3.7/site-packages/urllib3/connectionpool.py", line 384, in _make_request
    six.raise_from(e, None)
  File "<string>", line 2, in raise_from
  File "/usr/local/lib/python3.7/site-packages/urllib3/connectionpool.py", line 380, in _make_request
    httplib_response = conn.getresponse()
  File "/usr/local/Cellar/python/3.7.2_1/Frameworks/Python.framework/Versions/3.7/lib/python3.7/http/client.py", line 1321, in getresponse
    response.begin()
  File "/usr/local/Cellar/python/3.7.2_1/Frameworks/Python.framework/Versions/3.7/lib/python3.7/http/client.py", line 296, in begin
    version, status, reason = self._read_status()
  File "/usr/local/Cellar/python/3.7.2_1/Frameworks/Python.framework/Versions/3.7/lib/python3.7/http/client.py", line 257, in _read_status
    line = str(self.fp.readline(_MAXLINE + 1), "iso-8859-1")
  File "/usr/local/Cellar/python/3.7.2_1/Frameworks/Python.framework/Versions/3.7/lib/python3.7/socket.py", line 589, in readinto
    return self._sock.recv_into(b)
  File "/usr/local/Cellar/python/3.7.2_1/Frameworks/Python.framework/Versions/3.7/lib/python3.7/ssl.py", line 1052, in recv_into
    return self.read(nbytes, buffer)
  File "/usr/local/Cellar/python/3.7.2_1/Frameworks/Python.framework/Versions/3.7/lib/python3.7/ssl.py", line 911, in read
    return self._sslobj.read(len, buffer)
ConnectionResetError: [Errno 54] Connection reset by peer

During handling of the above exception, another exception occurred:

Traceback (most recent call last):
  File "/usr/local/lib/python3.7/site-packages/requests/adapters.py", line 449, in send
    timeout=timeout
  File "/usr/local/lib/python3.7/site-packages/urllib3/connectionpool.py", line 638, in urlopen
    _stacktrace=sys.exc_info()[2])
  File "/usr/local/lib/python3.7/site-packages/urllib3/util/retry.py", line 367, in increment
    raise six.reraise(type(error), error, _stacktrace)
  File "/usr/local/lib/python3.7/site-packages/urllib3/packages/six.py", line 685, in reraise
    raise value.with_traceback(tb)
  File "/usr/local/lib/python3.7/site-packages/urllib3/connectionpool.py", line 600, in urlopen
    chunked=chunked)
  File "/usr/local/lib/python3.7/site-packages/urllib3/connectionpool.py", line 384, in _make_request
    six.raise_from(e, None)
  File "<string>", line 2, in raise_from
  File "/usr/local/lib/python3.7/site-packages/urllib3/connectionpool.py", line 380, in _make_request
    httplib_response = conn.getresponse()
  File "/usr/local/Cellar/python/3.7.2_1/Frameworks/Python.framework/Versions/3.7/lib/python3.7/http/client.py", line 1321, in getresponse
    response.begin()
  File "/usr/local/Cellar/python/3.7.2_1/Frameworks/Python.framework/Versions/3.7/lib/python3.7/http/client.py", line 296, in begin
    version, status, reason = self._read_status()
  File "/usr/local/Cellar/python/3.7.2_1/Frameworks/Python.framework/Versions/3.7/lib/python3.7/http/client.py", line 257, in _read_status
    line = str(self.fp.readline(_MAXLINE + 1), "iso-8859-1")
  File "/usr/local/Cellar/python/3.7.2_1/Frameworks/Python.framework/Versions/3.7/lib/python3.7/socket.py", line 589, in readinto
    return self._sock.recv_into(b)
  File "/usr/local/Cellar/python/3.7.2_1/Frameworks/Python.framework/Versions/3.7/lib/python3.7/ssl.py", line 1052, in recv_into
    return self.read(nbytes, buffer)
  File "/usr/local/Cellar/python/3.7.2_1/Frameworks/Python.framework/Versions/3.7/lib/python3.7/ssl.py", line 911, in read
    return self._sslobj.read(len, buffer)
urllib3.exceptions.ProtocolError: ('Connection aborted.', ConnectionResetError(54, 'Connection reset by peer'))

During handling of the above exception, another exception occurred:

Traceback (most recent call last):
  File "/usr/local/lib/python3.7/site-packages/pywikibot/data/api.py", line 1966, in submit
    body=body, headers=headers)
  File "/usr/local/lib/python3.7/site-packages/pywikibot/tools/__init__.py", line 1446, in wrapper
    return obj(*__args, **__kw)
  File "/usr/local/lib/python3.7/site-packages/pywikibot/comms/http.py", line 317, in request
    r = fetch(baseuri, method, params, body, headers, **kwargs)
  File "/usr/local/lib/python3.7/site-packages/pywikibot/comms/http.py", line 519, in fetch
    error_handling_callback(request)
  File "/usr/local/lib/python3.7/site-packages/pywikibot/comms/http.py", line 405, in error_handling_callback
    raise request.data
  File "/usr/local/lib/python3.7/site-packages/pywikibot/comms/http.py", line 384, in _http_process
    **http_request.kwargs)
  File "/usr/local/lib/python3.7/site-packages/requests/sessions.py", line 533, in request
    resp = self.send(prep, **send_kwargs)
  File "/usr/local/lib/python3.7/site-packages/requests/sessions.py", line 646, in send
    r = adapter.send(request, **kwargs)
  File "/usr/local/lib/python3.7/site-packages/requests/adapters.py", line 498, in send
    raise ConnectionError(err, request=request)
requests.exceptions.ConnectionError: ('Connection aborted.', ConnectionResetError(54, 'Connection reset by peer'))

2021-12-07 22:48:56 /w/api.php, iiprop=timestamp%7Cuser%7Ccomment%7Curl%7Csize%7Csha1%7Cmime%7Cmetadata%7Carchivename&titles=File%3AFrans+Hals%2C+Portrait+of+Ren%C3%A9+Descartes.jpg&prop=imageinfo&action=query&indexpageids=&continue=&iilimit=500&meta=userinfo&uiprop=blockinfo%7Chasmsg&maxlag=5&format=json
2021-12-07 22:48:56 Waiting 5 seconds before retrying.
2021-12-08 00:51:04 Traceback (most recent call last):
  File "/usr/local/lib/python3.7/site-packages/urllib3/connectionpool.py", line 384, in _make_request
    six.raise_from(e, None)
  File "<string>", line 2, in raise_from
  File "/usr/local/lib/python3.7/site-packages/urllib3/connectionpool.py", line 380, in _make_request
    httplib_response = conn.getresponse()
  File "/usr/local/Cellar/python/3.7.2_1/Frameworks/Python.framework/Versions/3.7/lib/python3.7/http/client.py", line 1321, in getresponse
    response.begin()
  File "/usr/local/Cellar/python/3.7.2_1/Frameworks/Python.framework/Versions/3.7/lib/python3.7/http/client.py", line 296, in begin
    version, status, reason = self._read_status()
  File "/usr/local/Cellar/python/3.7.2_1/Frameworks/Python.framework/Versions/3.7/lib/python3.7/http/client.py", line 257, in _read_status
    line = str(self.fp.readline(_MAXLINE + 1), "iso-8859-1")
  File "/usr/local/Cellar/python/3.7.2_1/Frameworks/Python.framework/Versions/3.7/lib/python3.7/socket.py", line 589, in readinto
    return self._sock.recv_into(b)
  File "/usr/local/Cellar/python/3.7.2_1/Frameworks/Python.framework/Versions/3.7/lib/python3.7/ssl.py", line 1052, in recv_into
    return self.read(nbytes, buffer)
  File "/usr/local/Cellar/python/3.7.2_1/Frameworks/Python.framework/Versions/3.7/lib/python3.7/ssl.py", line 911, in read
    return self._sslobj.read(len, buffer)
TimeoutError: [Errno 60] Operation timed out

During handling of the above exception, another exception occurred:

Traceback (most recent call last):
  File "/usr/local/lib/python3.7/site-packages/requests/adapters.py", line 449, in send
    timeout=timeout
  File "/usr/local/lib/python3.7/site-packages/urllib3/connectionpool.py", line 638, in urlopen
    _stacktrace=sys.exc_info()[2])
  File "/usr/local/lib/python3.7/site-packages/urllib3/util/retry.py", line 367, in increment
    raise six.reraise(type(error), error, _stacktrace)
  File "/usr/local/lib/python3.7/site-packages/urllib3/packages/six.py", line 686, in reraise
    raise value
  File "/usr/local/lib/python3.7/site-packages/urllib3/connectionpool.py", line 600, in urlopen
    chunked=chunked)
  File "/usr/local/lib/python3.7/site-packages/urllib3/connectionpool.py", line 386, in _make_request
    self._raise_timeout(err=e, url=url, timeout_value=read_timeout)
  File "/usr/local/lib/python3.7/site-packages/urllib3/connectionpool.py", line 317, in _raise_timeout
    raise ReadTimeoutError(self, url, "Read timed out. (read timeout=%s)" % timeout_value)
urllib3.exceptions.ReadTimeoutError: HTTPSConnectionPool(host='www.wikidata.org', port=443): Read timed out. (read timeout=45)

During handling of the above exception, another exception occurred:

Traceback (most recent call last):
  File "/usr/local/lib/python3.7/site-packages/pywikibot/data/api.py", line 1966, in submit
    body=body, headers=headers)
  File "/usr/local/lib/python3.7/site-packages/pywikibot/tools/__init__.py", line 1446, in wrapper
    return obj(*__args, **__kw)
  File "/usr/local/lib/python3.7/site-packages/pywikibot/comms/http.py", line 317, in request
    r = fetch(baseuri, method, params, body, headers, **kwargs)
  File "/usr/local/lib/python3.7/site-packages/pywikibot/comms/http.py", line 519, in fetch
    error_handling_callback(request)
  File "/usr/local/lib/python3.7/site-packages/pywikibot/comms/http.py", line 405, in error_handling_callback
    raise request.data
  File "/usr/local/lib/python3.7/site-packages/pywikibot/comms/http.py", line 384, in _http_process
    **http_request.kwargs)
  File "/usr/local/lib/python3.7/site-packages/requests/sessions.py", line 533, in request
    resp = self.send(prep, **send_kwargs)
  File "/usr/local/lib/python3.7/site-packages/requests/sessions.py", line 646, in send
    r = adapter.send(request, **kwargs)
  File "/usr/local/lib/python3.7/site-packages/requests/adapters.py", line 529, in send
    raise ReadTimeout(e, request=request)
requests.exceptions.ReadTimeout: HTTPSConnectionPool(host='www.wikidata.org', port=443): Read timed out. (read timeout=45)

2021-12-08 00:51:04 /w/api.php?ids=Q20539316&action=wbgetentities&maxlag=5&format=json, ids=Q20539316&action=wbgetentities&maxlag=5&format=json
2021-12-08 00:51:04 Waiting 5 seconds before retrying.
2021-12-08 00:51:09 Found 1 wikidata:wikidata processes running, including this one.
2021-12-08 00:51:09 Found 1 commons:commons processes running, including this one.
2021-12-08 00:51:10 Traceback (most recent call last):
  File "/usr/local/lib/python3.7/site-packages/urllib3/connectionpool.py", line 600, in urlopen
    chunked=chunked)
  File "/usr/local/lib/python3.7/site-packages/urllib3/connectionpool.py", line 384, in _make_request
    six.raise_from(e, None)
  File "<string>", line 2, in raise_from
  File "/usr/local/lib/python3.7/site-packages/urllib3/connectionpool.py", line 380, in _make_request
    httplib_response = conn.getresponse()
  File "/usr/local/Cellar/python/3.7.2_1/Frameworks/Python.framework/Versions/3.7/lib/python3.7/http/client.py", line 1321, in getresponse
    response.begin()
  File "/usr/local/Cellar/python/3.7.2_1/Frameworks/Python.framework/Versions/3.7/lib/python3.7/http/client.py", line 296, in begin
    version, status, reason = self._read_status()
  File "/usr/local/Cellar/python/3.7.2_1/Frameworks/Python.framework/Versions/3.7/lib/python3.7/http/client.py", line 257, in _read_status
    line = str(self.fp.readline(_MAXLINE + 1), "iso-8859-1")
  File "/usr/local/Cellar/python/3.7.2_1/Frameworks/Python.framework/Versions/3.7/lib/python3.7/socket.py", line 589, in readinto
    return self._sock.recv_into(b)
  File "/usr/local/Cellar/python/3.7.2_1/Frameworks/Python.framework/Versions/3.7/lib/python3.7/ssl.py", line 1052, in recv_into
    return self.read(nbytes, buffer)
  File "/usr/local/Cellar/python/3.7.2_1/Frameworks/Python.framework/Versions/3.7/lib/python3.7/ssl.py", line 911, in read
    return self._sslobj.read(len, buffer)
ConnectionResetError: [Errno 54] Connection reset by peer

During handling of the above exception, another exception occurred:

Traceback (most recent call last):
  File "/usr/local/lib/python3.7/site-packages/requests/adapters.py", line 449, in send
    timeout=timeout
  File "/usr/local/lib/python3.7/site-packages/urllib3/connectionpool.py", line 638, in urlopen
    _stacktrace=sys.exc_info()[2])
  File "/usr/local/lib/python3.7/site-packages/urllib3/util/retry.py", line 367, in increment
    raise six.reraise(type(error), error, _stacktrace)
  File "/usr/local/lib/python3.7/site-packages/urllib3/packages/six.py", line 685, in reraise
    raise value.with_traceback(tb)
  File "/usr/local/lib/python3.7/site-packages/urllib3/connectionpool.py", line 600, in urlopen
    chunked=chunked)
  File "/usr/local/lib/python3.7/site-packages/urllib3/connectionpool.py", line 384, in _make_request
    six.raise_from(e, None)
  File "<string>", line 2, in raise_from
  File "/usr/local/lib/python3.7/site-packages/urllib3/connectionpool.py", line 380, in _make_request
    httplib_response = conn.getresponse()
  File "/usr/local/Cellar/python/3.7.2_1/Frameworks/Python.framework/Versions/3.7/lib/python3.7/http/client.py", line 1321, in getresponse
    response.begin()
  File "/usr/local/Cellar/python/3.7.2_1/Frameworks/Python.framework/Versions/3.7/lib/python3.7/http/client.py", line 296, in begin
    version, status, reason = self._read_status()
  File "/usr/local/Cellar/python/3.7.2_1/Frameworks/Python.framework/Versions/3.7/lib/python3.7/http/client.py", line 257, in _read_status
    line = str(self.fp.readline(_MAXLINE + 1), "iso-8859-1")
  File "/usr/local/Cellar/python/3.7.2_1/Frameworks/Python.framework/Versions/3.7/lib/python3.7/socket.py", line 589, in readinto
    return self._sock.recv_into(b)
  File "/usr/local/Cellar/python/3.7.2_1/Frameworks/Python.framework/Versions/3.7/lib/python3.7/ssl.py", line 1052, in recv_into
    return self.read(nbytes, buffer)
  File "/usr/local/Cellar/python/3.7.2_1/Frameworks/Python.framework/Versions/3.7/lib/python3.7/ssl.py", line 911, in read
    return self._sslobj.read(len, buffer)
urllib3.exceptions.ProtocolError: ('Connection aborted.', ConnectionResetError(54, 'Connection reset by peer'))

During handling of the above exception, another exception occurred:

Traceback (most recent call last):
  File "/usr/local/lib/python3.7/site-packages/pywikibot/data/api.py", line 1966, in submit
    body=body, headers=headers)
  File "/usr/local/lib/python3.7/site-packages/pywikibot/tools/__init__.py", line 1446, in wrapper
    return obj(*__args, **__kw)
  File "/usr/local/lib/python3.7/site-packages/pywikibot/comms/http.py", line 317, in request
    r = fetch(baseuri, method, params, body, headers, **kwargs)
  File "/usr/local/lib/python3.7/site-packages/pywikibot/comms/http.py", line 519, in fetch
    error_handling_callback(request)
  File "/usr/local/lib/python3.7/site-packages/pywikibot/comms/http.py", line 405, in error_handling_callback
    raise request.data
  File "/usr/local/lib/python3.7/site-packages/pywikibot/comms/http.py", line 384, in _http_process
    **http_request.kwargs)
  File "/usr/local/lib/python3.7/site-packages/requests/sessions.py", line 533, in request
    resp = self.send(prep, **send_kwargs)
  File "/usr/local/lib/python3.7/site-packages/requests/sessions.py", line 646, in send
    r = adapter.send(request, **kwargs)
  File "/usr/local/lib/python3.7/site-packages/requests/adapters.py", line 498, in send
    raise ConnectionError(err, request=request)
requests.exceptions.ConnectionError: ('Connection aborted.', ConnectionResetError(54, 'Connection reset by peer'))

2021-12-08 00:51:10 /w/api.php, iiprop=timestamp%7Cuser%7Ccomment%7Curl%7Csize%7Csha1%7Cmime%7Cmetadata%7Carchivename&titles=File%3AFranz+R%C3%B6sel+von+Rosenhof+-+The+Earth+after+the+Fall+of+Man+-+KMS1899+-+Statens+Museum+for+Kunst.jpg&prop=imageinfo&action=query&indexpageids=&continue=&iilimit=500&meta=userinfo&uiprop=blockinfo%7Chasmsg&maxlag=5&format=json
2021-12-08 00:51:10 Waiting 5 seconds before retrying.
2021-12-08 02:52:38 Traceback (most recent call last):
  File "/usr/local/lib/python3.7/site-packages/urllib3/connectionpool.py", line 384, in _make_request
    six.raise_from(e, None)
  File "<string>", line 2, in raise_from
  File "/usr/local/lib/python3.7/site-packages/urllib3/connectionpool.py", line 380, in _make_request
    httplib_response = conn.getresponse()
  File "/usr/local/Cellar/python/3.7.2_1/Frameworks/Python.framework/Versions/3.7/lib/python3.7/http/client.py", line 1321, in getresponse
    response.begin()
  File "/usr/local/Cellar/python/3.7.2_1/Frameworks/Python.framework/Versions/3.7/lib/python3.7/http/client.py", line 296, in begin
    version, status, reason = self._read_status()
  File "/usr/local/Cellar/python/3.7.2_1/Frameworks/Python.framework/Versions/3.7/lib/python3.7/http/client.py", line 257, in _read_status
    line = str(self.fp.readline(_MAXLINE + 1), "iso-8859-1")
  File "/usr/local/Cellar/python/3.7.2_1/Frameworks/Python.framework/Versions/3.7/lib/python3.7/socket.py", line 589, in readinto
    return self._sock.recv_into(b)
  File "/usr/local/Cellar/python/3.7.2_1/Frameworks/Python.framework/Versions/3.7/lib/python3.7/ssl.py", line 1052, in recv_into
    return self.read(nbytes, buffer)
  File "/usr/local/Cellar/python/3.7.2_1/Frameworks/Python.framework/Versions/3.7/lib/python3.7/ssl.py", line 911, in read
    return self._sslobj.read(len, buffer)
socket.timeout: The read operation timed out

During handling of the above exception, another exception occurred:

Traceback (most recent call last):
  File "/usr/local/lib/python3.7/site-packages/requests/adapters.py", line 449, in send
    timeout=timeout
  File "/usr/local/lib/python3.7/site-packages/urllib3/connectionpool.py", line 638, in urlopen
    _stacktrace=sys.exc_info()[2])
  File "/usr/local/lib/python3.7/site-packages/urllib3/util/retry.py", line 367, in increment
    raise six.reraise(type(error), error, _stacktrace)
  File "/usr/local/lib/python3.7/site-packages/urllib3/packages/six.py", line 686, in reraise
    raise value
  File "/usr/local/lib/python3.7/site-packages/urllib3/connectionpool.py", line 600, in urlopen
    chunked=chunked)
  File "/usr/local/lib/python3.7/site-packages/urllib3/connectionpool.py", line 386, in _make_request
    self._raise_timeout(err=e, url=url, timeout_value=read_timeout)
  File "/usr/local/lib/python3.7/site-packages/urllib3/connectionpool.py", line 306, in _raise_timeout
    raise ReadTimeoutError(self, url, "Read timed out. (read timeout=%s)" % timeout_value)
urllib3.exceptions.ReadTimeoutError: HTTPSConnectionPool(host='www.wikidata.org', port=443): Read timed out. (read timeout=45)

During handling of the above exception, another exception occurred:

Traceback (most recent call last):
  File "/usr/local/lib/python3.7/site-packages/pywikibot/data/api.py", line 1966, in submit
    body=body, headers=headers)
  File "/usr/local/lib/python3.7/site-packages/pywikibot/tools/__init__.py", line 1446, in wrapper
    return obj(*__args, **__kw)
  File "/usr/local/lib/python3.7/site-packages/pywikibot/comms/http.py", line 317, in request
    r = fetch(baseuri, method, params, body, headers, **kwargs)
  File "/usr/local/lib/python3.7/site-packages/pywikibot/comms/http.py", line 519, in fetch
    error_handling_callback(request)
  File "/usr/local/lib/python3.7/site-packages/pywikibot/comms/http.py", line 405, in error_handling_callback
    raise request.data
  File "/usr/local/lib/python3.7/site-packages/pywikibot/comms/http.py", line 384, in _http_process
    **http_request.kwargs)
  File "/usr/local/lib/python3.7/site-packages/requests/sessions.py", line 533, in request
    resp = self.send(prep, **send_kwargs)
  File "/usr/local/lib/python3.7/site-packages/requests/sessions.py", line 646, in send
    r = adapter.send(request, **kwargs)
  File "/usr/local/lib/python3.7/site-packages/requests/adapters.py", line 529, in send
    raise ReadTimeout(e, request=request)
requests.exceptions.ReadTimeout: HTTPSConnectionPool(host='www.wikidata.org', port=443): Read timed out. (read timeout=45)

2021-12-08 02:52:38 /w/api.php?ids=Q20355130&action=wbgetentities&maxlag=5&format=json, ids=Q20355130&action=wbgetentities&maxlag=5&format=json
2021-12-08 02:52:38 Waiting 5 seconds before retrying.
2021-12-08 02:52:43 Found 1 wikidata:wikidata processes running, including this one.
2021-12-08 04:52:46 Found 1 commons:commons processes running, including this one.
2021-12-08 04:52:46 Traceback (most recent call last):
  File "/usr/local/lib/python3.7/site-packages/urllib3/connectionpool.py", line 600, in urlopen
    chunked=chunked)
  File "/usr/local/lib/python3.7/site-packages/urllib3/connectionpool.py", line 384, in _make_request
    six.raise_from(e, None)
  File "<string>", line 2, in raise_from
  File "/usr/local/lib/python3.7/site-packages/urllib3/connectionpool.py", line 380, in _make_request
    httplib_response = conn.getresponse()
  File "/usr/local/Cellar/python/3.7.2_1/Frameworks/Python.framework/Versions/3.7/lib/python3.7/http/client.py", line 1321, in getresponse
    response.begin()
  File "/usr/local/Cellar/python/3.7.2_1/Frameworks/Python.framework/Versions/3.7/lib/python3.7/http/client.py", line 296, in begin
    version, status, reason = self._read_status()
  File "/usr/local/Cellar/python/3.7.2_1/Frameworks/Python.framework/Versions/3.7/lib/python3.7/http/client.py", line 257, in _read_status
    line = str(self.fp.readline(_MAXLINE + 1), "iso-8859-1")
  File "/usr/local/Cellar/python/3.7.2_1/Frameworks/Python.framework/Versions/3.7/lib/python3.7/socket.py", line 589, in readinto
    return self._sock.recv_into(b)
  File "/usr/local/Cellar/python/3.7.2_1/Frameworks/Python.framework/Versions/3.7/lib/python3.7/ssl.py", line 1052, in recv_into
    return self.read(nbytes, buffer)
  File "/usr/local/Cellar/python/3.7.2_1/Frameworks/Python.framework/Versions/3.7/lib/python3.7/ssl.py", line 911, in read
    return self._sslobj.read(len, buffer)
ConnectionResetError: [Errno 54] Connection reset by peer

During handling of the above exception, another exception occurred:

Traceback (most recent call last):
  File "/usr/local/lib/python3.7/site-packages/requests/adapters.py", line 449, in send
    timeout=timeout
  File "/usr/local/lib/python3.7/site-packages/urllib3/connectionpool.py", line 638, in urlopen
    _stacktrace=sys.exc_info()[2])
  File "/usr/local/lib/python3.7/site-packages/urllib3/util/retry.py", line 367, in increment
    raise six.reraise(type(error), error, _stacktrace)
  File "/usr/local/lib/python3.7/site-packages/urllib3/packages/six.py", line 685, in reraise
    raise value.with_traceback(tb)
  File "/usr/local/lib/python3.7/site-packages/urllib3/connectionpool.py", line 600, in urlopen
    chunked=chunked)
  File "/usr/local/lib/python3.7/site-packages/urllib3/connectionpool.py", line 384, in _make_request
    six.raise_from(e, None)
  File "<string>", line 2, in raise_from
  File "/usr/local/lib/python3.7/site-packages/urllib3/connectionpool.py", line 380, in _make_request
    httplib_response = conn.getresponse()
  File "/usr/local/Cellar/python/3.7.2_1/Frameworks/Python.framework/Versions/3.7/lib/python3.7/http/client.py", line 1321, in getresponse
    response.begin()
  File "/usr/local/Cellar/python/3.7.2_1/Frameworks/Python.framework/Versions/3.7/lib/python3.7/http/client.py", line 296, in begin
    version, status, reason = self._read_status()
  File "/usr/local/Cellar/python/3.7.2_1/Frameworks/Python.framework/Versions/3.7/lib/python3.7/http/client.py", line 257, in _read_status
    line = str(self.fp.readline(_MAXLINE + 1), "iso-8859-1")
  File "/usr/local/Cellar/python/3.7.2_1/Frameworks/Python.framework/Versions/3.7/lib/python3.7/socket.py", line 589, in readinto
    return self._sock.recv_into(b)
  File "/usr/local/Cellar/python/3.7.2_1/Frameworks/Python.framework/Versions/3.7/lib/python3.7/ssl.py", line 1052, in recv_into
    return self.read(nbytes, buffer)
  File "/usr/local/Cellar/python/3.7.2_1/Frameworks/Python.framework/Versions/3.7/lib/python3.7/ssl.py", line 911, in read
    return self._sslobj.read(len, buffer)
urllib3.exceptions.ProtocolError: ('Connection aborted.', ConnectionResetError(54, 'Connection reset by peer'))

During handling of the above exception, another exception occurred:

Traceback (most recent call last):
  File "/usr/local/lib/python3.7/site-packages/pywikibot/data/api.py", line 1966, in submit
    body=body, headers=headers)
  File "/usr/local/lib/python3.7/site-packages/pywikibot/tools/__init__.py", line 1446, in wrapper
    return obj(*__args, **__kw)
  File "/usr/local/lib/python3.7/site-packages/pywikibot/comms/http.py", line 317, in request
    r = fetch(baseuri, method, params, body, headers, **kwargs)
  File "/usr/local/lib/python3.7/site-packages/pywikibot/comms/http.py", line 519, in fetch
    error_handling_callback(request)
  File "/usr/local/lib/python3.7/site-packages/pywikibot/comms/http.py", line 405, in error_handling_callback
    raise request.data
  File "/usr/local/lib/python3.7/site-packages/pywikibot/comms/http.py", line 384, in _http_process
    **http_request.kwargs)
  File "/usr/local/lib/python3.7/site-packages/requests/sessions.py", line 533, in request
    resp = self.send(prep, **send_kwargs)
  File "/usr/local/lib/python3.7/site-packages/requests/sessions.py", line 646, in send
    r = adapter.send(request, **kwargs)
  File "/usr/local/lib/python3.7/site-packages/requests/adapters.py", line 498, in send
    raise ConnectionError(err, request=request)
requests.exceptions.ConnectionError: ('Connection aborted.', ConnectionResetError(54, 'Connection reset by peer'))

2021-12-08 04:52:46 /w/api.php, iiprop=timestamp%7Cuser%7Ccomment%7Curl%7Csize%7Csha1%7Cmime%7Cmetadata%7Carchivename&titles=File%3AJacobus+Storck+-+Harbour+Scene+with+Antique+Ruins+-+KMS3054+-+Statens+Museum+for+Kunst.jpg&prop=imageinfo&action=query&indexpageids=&continue=&iilimit=500&meta=userinfo&uiprop=blockinfo%7Chasmsg&maxlag=5&format=json
2021-12-08 04:52:46 Waiting 5 seconds before retrying.
2021-12-08 04:52:52 Found 1 wikidata:wikidata processes running, including this one.
2021-12-08 05:49:06 Traceback (most recent call last):
  File "/usr/local/lib/python3.7/site-packages/urllib3/connectionpool.py", line 384, in _make_request
    six.raise_from(e, None)
  File "<string>", line 2, in raise_from
  File "/usr/local/lib/python3.7/site-packages/urllib3/connectionpool.py", line 380, in _make_request
    httplib_response = conn.getresponse()
  File "/usr/local/Cellar/python/3.7.2_1/Frameworks/Python.framework/Versions/3.7/lib/python3.7/http/client.py", line 1321, in getresponse
    response.begin()
  File "/usr/local/Cellar/python/3.7.2_1/Frameworks/Python.framework/Versions/3.7/lib/python3.7/http/client.py", line 296, in begin
    version, status, reason = self._read_status()
  File "/usr/local/Cellar/python/3.7.2_1/Frameworks/Python.framework/Versions/3.7/lib/python3.7/http/client.py", line 257, in _read_status
    line = str(self.fp.readline(_MAXLINE + 1), "iso-8859-1")
  File "/usr/local/Cellar/python/3.7.2_1/Frameworks/Python.framework/Versions/3.7/lib/python3.7/socket.py", line 589, in readinto
    return self._sock.recv_into(b)
  File "/usr/local/Cellar/python/3.7.2_1/Frameworks/Python.framework/Versions/3.7/lib/python3.7/ssl.py", line 1052, in recv_into
    return self.read(nbytes, buffer)
  File "/usr/local/Cellar/python/3.7.2_1/Frameworks/Python.framework/Versions/3.7/lib/python3.7/ssl.py", line 911, in read
    return self._sslobj.read(len, buffer)
socket.timeout: The read operation timed out

During handling of the above exception, another exception occurred:

Traceback (most recent call last):
  File "/usr/local/lib/python3.7/site-packages/requests/adapters.py", line 449, in send
    timeout=timeout
  File "/usr/local/lib/python3.7/site-packages/urllib3/connectionpool.py", line 638, in urlopen
    _stacktrace=sys.exc_info()[2])
  File "/usr/local/lib/python3.7/site-packages/urllib3/util/retry.py", line 367, in increment
    raise six.reraise(type(error), error, _stacktrace)
  File "/usr/local/lib/python3.7/site-packages/urllib3/packages/six.py", line 686, in reraise
    raise value
  File "/usr/local/lib/python3.7/site-packages/urllib3/connectionpool.py", line 600, in urlopen
    chunked=chunked)
  File "/usr/local/lib/python3.7/site-packages/urllib3/connectionpool.py", line 386, in _make_request
    self._raise_timeout(err=e, url=url, timeout_value=read_timeout)
  File "/usr/local/lib/python3.7/site-packages/urllib3/connectionpool.py", line 306, in _raise_timeout
    raise ReadTimeoutError(self, url, "Read timed out. (read timeout=%s)" % timeout_value)
urllib3.exceptions.ReadTimeoutError: HTTPSConnectionPool(host='commons.wikimedia.org', port=443): Read timed out. (read timeout=45)

During handling of the above exception, another exception occurred:

Traceback (most recent call last):
  File "/usr/local/lib/python3.7/site-packages/pywikibot/data/api.py", line 1966, in submit
    body=body, headers=headers)
  File "/usr/local/lib/python3.7/site-packages/pywikibot/tools/__init__.py", line 1446, in wrapper
    return obj(*__args, **__kw)
  File "/usr/local/lib/python3.7/site-packages/pywikibot/comms/http.py", line 317, in request
    r = fetch(baseuri, method, params, body, headers, **kwargs)
  File "/usr/local/lib/python3.7/site-packages/pywikibot/comms/http.py", line 519, in fetch
    error_handling_callback(request)
  File "/usr/local/lib/python3.7/site-packages/pywikibot/comms/http.py", line 405, in error_handling_callback
    raise request.data
  File "/usr/local/lib/python3.7/site-packages/pywikibot/comms/http.py", line 384, in _http_process
    **http_request.kwargs)
  File "/usr/local/lib/python3.7/site-packages/requests/sessions.py", line 533, in request
    resp = self.send(prep, **send_kwargs)
  File "/usr/local/lib/python3.7/site-packages/requests/sessions.py", line 646, in send
    r = adapter.send(request, **kwargs)
  File "/usr/local/lib/python3.7/site-packages/requests/adapters.py", line 529, in send
    raise ReadTimeout(e, request=request)
requests.exceptions.ReadTimeout: HTTPSConnectionPool(host='commons.wikimedia.org', port=443): Read timed out. (read timeout=45)

2021-12-08 05:49:06 /w/api.php, iiprop=timestamp%7Cuser%7Ccomment%7Curl%7Csize%7Csha1%7Cmime%7Cmetadata%7Carchivename&titles=File%3AAdam+Colonia+-+Noah+Leaving+the+Ark+-+KMSsp534+-+Statens+Museum+for+Kunst.jpg&prop=imageinfo&action=query&indexpageids=&continue=&iilimit=500&meta=userinfo&uiprop=blockinfo%7Chasmsg&maxlag=5&format=json
2021-12-08 05:49:06 Waiting 5 seconds before retrying.
2021-12-08 05:49:11 Found 1 commons:commons processes running, including this one.
2021-12-08 06:06:00 Found 1 wikidata:wikidata processes running, including this one.
2021-12-08 06:06:00 Traceback (most recent call last):
  File "/usr/local/lib/python3.7/site-packages/urllib3/connectionpool.py", line 600, in urlopen
    chunked=chunked)
  File "/usr/local/lib/python3.7/site-packages/urllib3/connectionpool.py", line 384, in _make_request
    six.raise_from(e, None)
  File "<string>", line 2, in raise_from
  File "/usr/local/lib/python3.7/site-packages/urllib3/connectionpool.py", line 380, in _make_request
    httplib_response = conn.getresponse()
  File "/usr/local/Cellar/python/3.7.2_1/Frameworks/Python.framework/Versions/3.7/lib/python3.7/http/client.py", line 1321, in getresponse
    response.begin()
  File "/usr/local/Cellar/python/3.7.2_1/Frameworks/Python.framework/Versions/3.7/lib/python3.7/http/client.py", line 296, in begin
    version, status, reason = self._read_status()
  File "/usr/local/Cellar/python/3.7.2_1/Frameworks/Python.framework/Versions/3.7/lib/python3.7/http/client.py", line 257, in _read_status
    line = str(self.fp.readline(_MAXLINE + 1), "iso-8859-1")
  File "/usr/local/Cellar/python/3.7.2_1/Frameworks/Python.framework/Versions/3.7/lib/python3.7/socket.py", line 589, in readinto
    return self._sock.recv_into(b)
  File "/usr/local/Cellar/python/3.7.2_1/Frameworks/Python.framework/Versions/3.7/lib/python3.7/ssl.py", line 1052, in recv_into
    return self.read(nbytes, buffer)
  File "/usr/local/Cellar/python/3.7.2_1/Frameworks/Python.framework/Versions/3.7/lib/python3.7/ssl.py", line 911, in read
    return self._sslobj.read(len, buffer)
ConnectionResetError: [Errno 54] Connection reset by peer

During handling of the above exception, another exception occurred:

Traceback (most recent call last):
  File "/usr/local/lib/python3.7/site-packages/requests/adapters.py", line 449, in send
    timeout=timeout
  File "/usr/local/lib/python3.7/site-packages/urllib3/connectionpool.py", line 638, in urlopen
    _stacktrace=sys.exc_info()[2])
  File "/usr/local/lib/python3.7/site-packages/urllib3/util/retry.py", line 367, in increment
    raise six.reraise(type(error), error, _stacktrace)
  File "/usr/local/lib/python3.7/site-packages/urllib3/packages/six.py", line 685, in reraise
    raise value.with_traceback(tb)
  File "/usr/local/lib/python3.7/site-packages/urllib3/connectionpool.py", line 600, in urlopen
    chunked=chunked)
  File "/usr/local/lib/python3.7/site-packages/urllib3/connectionpool.py", line 384, in _make_request
    six.raise_from(e, None)
  File "<string>", line 2, in raise_from
  File "/usr/local/lib/python3.7/site-packages/urllib3/connectionpool.py", line 380, in _make_request
    httplib_response = conn.getresponse()
  File "/usr/local/Cellar/python/3.7.2_1/Frameworks/Python.framework/Versions/3.7/lib/python3.7/http/client.py", line 1321, in getresponse
    response.begin()
  File "/usr/local/Cellar/python/3.7.2_1/Frameworks/Python.framework/Versions/3.7/lib/python3.7/http/client.py", line 296, in begin
    version, status, reason = self._read_status()
  File "/usr/local/Cellar/python/3.7.2_1/Frameworks/Python.framework/Versions/3.7/lib/python3.7/http/client.py", line 257, in _read_status
    line = str(self.fp.readline(_MAXLINE + 1), "iso-8859-1")
  File "/usr/local/Cellar/python/3.7.2_1/Frameworks/Python.framework/Versions/3.7/lib/python3.7/socket.py", line 589, in readinto
    return self._sock.recv_into(b)
  File "/usr/local/Cellar/python/3.7.2_1/Frameworks/Python.framework/Versions/3.7/lib/python3.7/ssl.py", line 1052, in recv_into
    return self.read(nbytes, buffer)
  File "/usr/local/Cellar/python/3.7.2_1/Frameworks/Python.framework/Versions/3.7/lib/python3.7/ssl.py", line 911, in read
    return self._sslobj.read(len, buffer)
urllib3.exceptions.ProtocolError: ('Connection aborted.', ConnectionResetError(54, 'Connection reset by peer'))

During handling of the above exception, another exception occurred:

Traceback (most recent call last):
  File "/usr/local/lib/python3.7/site-packages/pywikibot/data/api.py", line 1966, in submit
    body=body, headers=headers)
  File "/usr/local/lib/python3.7/site-packages/pywikibot/tools/__init__.py", line 1446, in wrapper
    return obj(*__args, **__kw)
  File "/usr/local/lib/python3.7/site-packages/pywikibot/comms/http.py", line 317, in request
    r = fetch(baseuri, method, params, body, headers, **kwargs)
  File "/usr/local/lib/python3.7/site-packages/pywikibot/comms/http.py", line 519, in fetch
    error_handling_callback(request)
  File "/usr/local/lib/python3.7/site-packages/pywikibot/comms/http.py", line 405, in error_handling_callback
    raise request.data
  File "/usr/local/lib/python3.7/site-packages/pywikibot/comms/http.py", line 384, in _http_process
    **http_request.kwargs)
  File "/usr/local/lib/python3.7/site-packages/requests/sessions.py", line 533, in request
    resp = self.send(prep, **send_kwargs)
  File "/usr/local/lib/python3.7/site-packages/requests/sessions.py", line 646, in send
    r = adapter.send(request, **kwargs)
  File "/usr/local/lib/python3.7/site-packages/requests/adapters.py", line 498, in send
    raise ConnectionError(err, request=request)
requests.exceptions.ConnectionError: ('Connection aborted.', ConnectionResetError(54, 'Connection reset by peer'))

2021-12-08 06:06:00 /w/api.php?ids=Q20380881&action=wbgetentities&maxlag=5&format=json, ids=Q20380881&action=wbgetentities&maxlag=5&format=json
2021-12-08 06:06:00 Waiting 5 seconds before retrying.
2021-12-08 06:06:06 Found 1 commons:commons processes running, including this one.
2021-12-08 08:06:51 Found 1 wikidata:wikidata processes running, including this one.
2021-12-08 08:06:51 Traceback (most recent call last):
  File "/usr/local/lib/python3.7/site-packages/urllib3/connectionpool.py", line 600, in urlopen
    chunked=chunked)
  File "/usr/local/lib/python3.7/site-packages/urllib3/connectionpool.py", line 384, in _make_request
    six.raise_from(e, None)
  File "<string>", line 2, in raise_from
  File "/usr/local/lib/python3.7/site-packages/urllib3/connectionpool.py", line 380, in _make_request
    httplib_response = conn.getresponse()
  File "/usr/local/Cellar/python/3.7.2_1/Frameworks/Python.framework/Versions/3.7/lib/python3.7/http/client.py", line 1321, in getresponse
    response.begin()
  File "/usr/local/Cellar/python/3.7.2_1/Frameworks/Python.framework/Versions/3.7/lib/python3.7/http/client.py", line 296, in begin
    version, status, reason = self._read_status()
  File "/usr/local/Cellar/python/3.7.2_1/Frameworks/Python.framework/Versions/3.7/lib/python3.7/http/client.py", line 257, in _read_status
    line = str(self.fp.readline(_MAXLINE + 1), "iso-8859-1")
  File "/usr/local/Cellar/python/3.7.2_1/Frameworks/Python.framework/Versions/3.7/lib/python3.7/socket.py", line 589, in readinto
    return self._sock.recv_into(b)
  File "/usr/local/Cellar/python/3.7.2_1/Frameworks/Python.framework/Versions/3.7/lib/python3.7/ssl.py", line 1052, in recv_into
    return self.read(nbytes, buffer)
  File "/usr/local/Cellar/python/3.7.2_1/Frameworks/Python.framework/Versions/3.7/lib/python3.7/ssl.py", line 911, in read
    return self._sslobj.read(len, buffer)
ConnectionResetError: [Errno 54] Connection reset by peer

During handling of the above exception, another exception occurred:

Traceback (most recent call last):
  File "/usr/local/lib/python3.7/site-packages/requests/adapters.py", line 449, in send
    timeout=timeout
  File "/usr/local/lib/python3.7/site-packages/urllib3/connectionpool.py", line 638, in urlopen
    _stacktrace=sys.exc_info()[2])
  File "/usr/local/lib/python3.7/site-packages/urllib3/util/retry.py", line 367, in increment
    raise six.reraise(type(error), error, _stacktrace)
  File "/usr/local/lib/python3.7/site-packages/urllib3/packages/six.py", line 685, in reraise
    raise value.with_traceback(tb)
  File "/usr/local/lib/python3.7/site-packages/urllib3/connectionpool.py", line 600, in urlopen
    chunked=chunked)
  File "/usr/local/lib/python3.7/site-packages/urllib3/connectionpool.py", line 384, in _make_request
    six.raise_from(e, None)
  File "<string>", line 2, in raise_from
  File "/usr/local/lib/python3.7/site-packages/urllib3/connectionpool.py", line 380, in _make_request
    httplib_response = conn.getresponse()
  File "/usr/local/Cellar/python/3.7.2_1/Frameworks/Python.framework/Versions/3.7/lib/python3.7/http/client.py", line 1321, in getresponse
    response.begin()
  File "/usr/local/Cellar/python/3.7.2_1/Frameworks/Python.framework/Versions/3.7/lib/python3.7/http/client.py", line 296, in begin
    version, status, reason = self._read_status()
  File "/usr/local/Cellar/python/3.7.2_1/Frameworks/Python.framework/Versions/3.7/lib/python3.7/http/client.py", line 257, in _read_status
    line = str(self.fp.readline(_MAXLINE + 1), "iso-8859-1")
  File "/usr/local/Cellar/python/3.7.2_1/Frameworks/Python.framework/Versions/3.7/lib/python3.7/socket.py", line 589, in readinto
    return self._sock.recv_into(b)
  File "/usr/local/Cellar/python/3.7.2_1/Frameworks/Python.framework/Versions/3.7/lib/python3.7/ssl.py", line 1052, in recv_into
    return self.read(nbytes, buffer)
  File "/usr/local/Cellar/python/3.7.2_1/Frameworks/Python.framework/Versions/3.7/lib/python3.7/ssl.py", line 911, in read
    return self._sslobj.read(len, buffer)
urllib3.exceptions.ProtocolError: ('Connection aborted.', ConnectionResetError(54, 'Connection reset by peer'))

During handling of the above exception, another exception occurred:

Traceback (most recent call last):
  File "/usr/local/lib/python3.7/site-packages/pywikibot/data/api.py", line 1966, in submit
    body=body, headers=headers)
  File "/usr/local/lib/python3.7/site-packages/pywikibot/tools/__init__.py", line 1446, in wrapper
    return obj(*__args, **__kw)
  File "/usr/local/lib/python3.7/site-packages/pywikibot/comms/http.py", line 317, in request
    r = fetch(baseuri, method, params, body, headers, **kwargs)
  File "/usr/local/lib/python3.7/site-packages/pywikibot/comms/http.py", line 519, in fetch
    error_handling_callback(request)
  File "/usr/local/lib/python3.7/site-packages/pywikibot/comms/http.py", line 405, in error_handling_callback
    raise request.data
  File "/usr/local/lib/python3.7/site-packages/pywikibot/comms/http.py", line 384, in _http_process
    **http_request.kwargs)
  File "/usr/local/lib/python3.7/site-packages/requests/sessions.py", line 533, in request
    resp = self.send(prep, **send_kwargs)
  File "/usr/local/lib/python3.7/site-packages/requests/sessions.py", line 646, in send
    r = adapter.send(request, **kwargs)
  File "/usr/local/lib/python3.7/site-packages/requests/adapters.py", line 498, in send
    raise ConnectionError(err, request=request)
requests.exceptions.ConnectionError: ('Connection aborted.', ConnectionResetError(54, 'Connection reset by peer'))

2021-12-08 08:06:51 /w/api.php?ids=Q20469004&action=wbgetentities&maxlag=5&format=json, ids=Q20469004&action=wbgetentities&maxlag=5&format=json
2021-12-08 08:06:51 Waiting 5 seconds before retrying.
2021-12-08 08:06:56 Found 1 commons:commons processes running, including this one.
2021-12-08 08:06:56 Traceback (most recent call last):
  File "/usr/local/lib/python3.7/site-packages/urllib3/connectionpool.py", line 600, in urlopen
    chunked=chunked)
  File "/usr/local/lib/python3.7/site-packages/urllib3/connectionpool.py", line 384, in _make_request
    six.raise_from(e, None)
  File "<string>", line 2, in raise_from
  File "/usr/local/lib/python3.7/site-packages/urllib3/connectionpool.py", line 380, in _make_request
    httplib_response = conn.getresponse()
  File "/usr/local/Cellar/python/3.7.2_1/Frameworks/Python.framework/Versions/3.7/lib/python3.7/http/client.py", line 1321, in getresponse
    response.begin()
  File "/usr/local/Cellar/python/3.7.2_1/Frameworks/Python.framework/Versions/3.7/lib/python3.7/http/client.py", line 296, in begin
    version, status, reason = self._read_status()
  File "/usr/local/Cellar/python/3.7.2_1/Frameworks/Python.framework/Versions/3.7/lib/python3.7/http/client.py", line 257, in _read_status
    line = str(self.fp.readline(_MAXLINE + 1), "iso-8859-1")
  File "/usr/local/Cellar/python/3.7.2_1/Frameworks/Python.framework/Versions/3.7/lib/python3.7/socket.py", line 589, in readinto
    return self._sock.recv_into(b)
  File "/usr/local/Cellar/python/3.7.2_1/Frameworks/Python.framework/Versions/3.7/lib/python3.7/ssl.py", line 1052, in recv_into
    return self.read(nbytes, buffer)
  File "/usr/local/Cellar/python/3.7.2_1/Frameworks/Python.framework/Versions/3.7/lib/python3.7/ssl.py", line 911, in read
    return self._sslobj.read(len, buffer)
ConnectionResetError: [Errno 54] Connection reset by peer

During handling of the above exception, another exception occurred:

Traceback (most recent call last):
  File "/usr/local/lib/python3.7/site-packages/requests/adapters.py", line 449, in send
    timeout=timeout
  File "/usr/local/lib/python3.7/site-packages/urllib3/connectionpool.py", line 638, in urlopen
    _stacktrace=sys.exc_info()[2])
  File "/usr/local/lib/python3.7/site-packages/urllib3/util/retry.py", line 367, in increment
    raise six.reraise(type(error), error, _stacktrace)
  File "/usr/local/lib/python3.7/site-packages/urllib3/packages/six.py", line 685, in reraise
    raise value.with_traceback(tb)
  File "/usr/local/lib/python3.7/site-packages/urllib3/connectionpool.py", line 600, in urlopen
    chunked=chunked)
  File "/usr/local/lib/python3.7/site-packages/urllib3/connectionpool.py", line 384, in _make_request
    six.raise_from(e, None)
  File "<string>", line 2, in raise_from
  File "/usr/local/lib/python3.7/site-packages/urllib3/connectionpool.py", line 380, in _make_request
    httplib_response = conn.getresponse()
  File "/usr/local/Cellar/python/3.7.2_1/Frameworks/Python.framework/Versions/3.7/lib/python3.7/http/client.py", line 1321, in getresponse
    response.begin()
  File "/usr/local/Cellar/python/3.7.2_1/Frameworks/Python.framework/Versions/3.7/lib/python3.7/http/client.py", line 296, in begin
    version, status, reason = self._read_status()
  File "/usr/local/Cellar/python/3.7.2_1/Frameworks/Python.framework/Versions/3.7/lib/python3.7/http/client.py", line 257, in _read_status
    line = str(self.fp.readline(_MAXLINE + 1), "iso-8859-1")
  File "/usr/local/Cellar/python/3.7.2_1/Frameworks/Python.framework/Versions/3.7/lib/python3.7/socket.py", line 589, in readinto
    return self._sock.recv_into(b)
  File "/usr/local/Cellar/python/3.7.2_1/Frameworks/Python.framework/Versions/3.7/lib/python3.7/ssl.py", line 1052, in recv_into
    return self.read(nbytes, buffer)
  File "/usr/local/Cellar/python/3.7.2_1/Frameworks/Python.framework/Versions/3.7/lib/python3.7/ssl.py", line 911, in read
    return self._sslobj.read(len, buffer)
urllib3.exceptions.ProtocolError: ('Connection aborted.', ConnectionResetError(54, 'Connection reset by peer'))

During handling of the above exception, another exception occurred:

Traceback (most recent call last):
  File "/usr/local/lib/python3.7/site-packages/pywikibot/data/api.py", line 1966, in submit
    body=body, headers=headers)
  File "/usr/local/lib/python3.7/site-packages/pywikibot/tools/__init__.py", line 1446, in wrapper
    return obj(*__args, **__kw)
  File "/usr/local/lib/python3.7/site-packages/pywikibot/comms/http.py", line 317, in request
    r = fetch(baseuri, method, params, body, headers, **kwargs)
  File "/usr/local/lib/python3.7/site-packages/pywikibot/comms/http.py", line 519, in fetch
    error_handling_callback(request)
  File "/usr/local/lib/python3.7/site-packages/pywikibot/comms/http.py", line 405, in error_handling_callback
    raise request.data
  File "/usr/local/lib/python3.7/site-packages/pywikibot/comms/http.py", line 384, in _http_process
    **http_request.kwargs)
  File "/usr/local/lib/python3.7/site-packages/requests/sessions.py", line 533, in request
    resp = self.send(prep, **send_kwargs)
  File "/usr/local/lib/python3.7/site-packages/requests/sessions.py", line 646, in send
    r = adapter.send(request, **kwargs)
  File "/usr/local/lib/python3.7/site-packages/requests/adapters.py", line 498, in send
    raise ConnectionError(err, request=request)
requests.exceptions.ConnectionError: ('Connection aborted.', ConnectionResetError(54, 'Connection reset by peer'))

2021-12-08 08:06:56 /w/api.php, iiprop=timestamp%7Cuser%7Ccomment%7Curl%7Csize%7Csha1%7Cmime%7Cmetadata%7Carchivename&titles=File%3APeder+Als+-+%C3%86rkeenglen+Raphael+-+KMSst121+-+Statens+Museum+for+Kunst.jpg&prop=imageinfo&action=query&indexpageids=&continue=&iilimit=500&meta=userinfo&uiprop=blockinfo%7Chasmsg&maxlag=5&format=json
2021-12-08 08:06:56 Waiting 5 seconds before retrying.
2021-12-08 08:24:40 Traceback (most recent call last):
  File "/usr/local/lib/python3.7/site-packages/urllib3/connectionpool.py", line 384, in _make_request
    six.raise_from(e, None)
  File "<string>", line 2, in raise_from
  File "/usr/local/lib/python3.7/site-packages/urllib3/connectionpool.py", line 380, in _make_request
    httplib_response = conn.getresponse()
  File "/usr/local/Cellar/python/3.7.2_1/Frameworks/Python.framework/Versions/3.7/lib/python3.7/http/client.py", line 1321, in getresponse
    response.begin()
  File "/usr/local/Cellar/python/3.7.2_1/Frameworks/Python.framework/Versions/3.7/lib/python3.7/http/client.py", line 296, in begin
    version, status, reason = self._read_status()
  File "/usr/local/Cellar/python/3.7.2_1/Frameworks/Python.framework/Versions/3.7/lib/python3.7/http/client.py", line 257, in _read_status
    line = str(self.fp.readline(_MAXLINE + 1), "iso-8859-1")
  File "/usr/local/Cellar/python/3.7.2_1/Frameworks/Python.framework/Versions/3.7/lib/python3.7/socket.py", line 589, in readinto
    return self._sock.recv_into(b)
  File "/usr/local/Cellar/python/3.7.2_1/Frameworks/Python.framework/Versions/3.7/lib/python3.7/ssl.py", line 1052, in recv_into
    return self.read(nbytes, buffer)
  File "/usr/local/Cellar/python/3.7.2_1/Frameworks/Python.framework/Versions/3.7/lib/python3.7/ssl.py", line 911, in read
    return self._sslobj.read(len, buffer)
socket.timeout: The read operation timed out

During handling of the above exception, another exception occurred:

Traceback (most recent call last):
  File "/usr/local/lib/python3.7/site-packages/requests/adapters.py", line 449, in send
    timeout=timeout
  File "/usr/local/lib/python3.7/site-packages/urllib3/connectionpool.py", line 638, in urlopen
    _stacktrace=sys.exc_info()[2])
  File "/usr/local/lib/python3.7/site-packages/urllib3/util/retry.py", line 367, in increment
    raise six.reraise(type(error), error, _stacktrace)
  File "/usr/local/lib/python3.7/site-packages/urllib3/packages/six.py", line 686, in reraise
    raise value
  File "/usr/local/lib/python3.7/site-packages/urllib3/connectionpool.py", line 600, in urlopen
    chunked=chunked)
  File "/usr/local/lib/python3.7/site-packages/urllib3/connectionpool.py", line 386, in _make_request
    self._raise_timeout(err=e, url=url, timeout_value=read_timeout)
  File "/usr/local/lib/python3.7/site-packages/urllib3/connectionpool.py", line 306, in _raise_timeout
    raise ReadTimeoutError(self, url, "Read timed out. (read timeout=%s)" % timeout_value)
urllib3.exceptions.ReadTimeoutError: HTTPSConnectionPool(host='www.wikidata.org', port=443): Read timed out. (read timeout=45)

During handling of the above exception, another exception occurred:

Traceback (most recent call last):
  File "/usr/local/lib/python3.7/site-packages/pywikibot/data/api.py", line 1966, in submit
    body=body, headers=headers)
  File "/usr/local/lib/python3.7/site-packages/pywikibot/tools/__init__.py", line 1446, in wrapper
    return obj(*__args, **__kw)
  File "/usr/local/lib/python3.7/site-packages/pywikibot/comms/http.py", line 317, in request
    r = fetch(baseuri, method, params, body, headers, **kwargs)
  File "/usr/local/lib/python3.7/site-packages/pywikibot/comms/http.py", line 519, in fetch
    error_handling_callback(request)
  File "/usr/local/lib/python3.7/site-packages/pywikibot/comms/http.py", line 405, in error_handling_callback
    raise request.data
  File "/usr/local/lib/python3.7/site-packages/pywikibot/comms/http.py", line 384, in _http_process
    **http_request.kwargs)
  File "/usr/local/lib/python3.7/site-packages/requests/sessions.py", line 533, in request
    resp = self.send(prep, **send_kwargs)
  File "/usr/local/lib/python3.7/site-packages/requests/sessions.py", line 646, in send
    r = adapter.send(request, **kwargs)
  File "/usr/local/lib/python3.7/site-packages/requests/adapters.py", line 529, in send
    raise ReadTimeout(e, request=request)
requests.exceptions.ReadTimeout: HTTPSConnectionPool(host='www.wikidata.org', port=443): Read timed out. (read timeout=45)

2021-12-08 08:24:40 /w/api.php?ids=Q20493246&action=wbgetentities&maxlag=5&format=json, ids=Q20493246&action=wbgetentities&maxlag=5&format=json
2021-12-08 08:24:40 Waiting 5 seconds before retrying.
2021-12-08 08:24:45 Found 1 wikidata:wikidata processes running, including this one.
2021-12-08 08:24:46 Found 1 commons:commons processes running, including this one.
2021-12-08 08:24:46 Traceback (most recent call last):
  File "/usr/local/lib/python3.7/site-packages/urllib3/connectionpool.py", line 600, in urlopen
    chunked=chunked)
  File "/usr/local/lib/python3.7/site-packages/urllib3/connectionpool.py", line 384, in _make_request
    six.raise_from(e, None)
  File "<string>", line 2, in raise_from
  File "/usr/local/lib/python3.7/site-packages/urllib3/connectionpool.py", line 380, in _make_request
    httplib_response = conn.getresponse()
  File "/usr/local/Cellar/python/3.7.2_1/Frameworks/Python.framework/Versions/3.7/lib/python3.7/http/client.py", line 1321, in getresponse
    response.begin()
  File "/usr/local/Cellar/python/3.7.2_1/Frameworks/Python.framework/Versions/3.7/lib/python3.7/http/client.py", line 296, in begin
    version, status, reason = self._read_status()
  File "/usr/local/Cellar/python/3.7.2_1/Frameworks/Python.framework/Versions/3.7/lib/python3.7/http/client.py", line 257, in _read_status
    line = str(self.fp.readline(_MAXLINE + 1), "iso-8859-1")
  File "/usr/local/Cellar/python/3.7.2_1/Frameworks/Python.framework/Versions/3.7/lib/python3.7/socket.py", line 589, in readinto
    return self._sock.recv_into(b)
  File "/usr/local/Cellar/python/3.7.2_1/Frameworks/Python.framework/Versions/3.7/lib/python3.7/ssl.py", line 1052, in recv_into
    return self.read(nbytes, buffer)
  File "/usr/local/Cellar/python/3.7.2_1/Frameworks/Python.framework/Versions/3.7/lib/python3.7/ssl.py", line 911, in read
    return self._sslobj.read(len, buffer)
ConnectionResetError: [Errno 54] Connection reset by peer

During handling of the above exception, another exception occurred:

Traceback (most recent call last):
  File "/usr/local/lib/python3.7/site-packages/requests/adapters.py", line 449, in send
    timeout=timeout
  File "/usr/local/lib/python3.7/site-packages/urllib3/connectionpool.py", line 638, in urlopen
    _stacktrace=sys.exc_info()[2])
  File "/usr/local/lib/python3.7/site-packages/urllib3/util/retry.py", line 367, in increment
    raise six.reraise(type(error), error, _stacktrace)
  File "/usr/local/lib/python3.7/site-packages/urllib3/packages/six.py", line 685, in reraise
    raise value.with_traceback(tb)
  File "/usr/local/lib/python3.7/site-packages/urllib3/connectionpool.py", line 600, in urlopen
    chunked=chunked)
  File "/usr/local/lib/python3.7/site-packages/urllib3/connectionpool.py", line 384, in _make_request
    six.raise_from(e, None)
  File "<string>", line 2, in raise_from
  File "/usr/local/lib/python3.7/site-packages/urllib3/connectionpool.py", line 380, in _make_request
    httplib_response = conn.getresponse()
  File "/usr/local/Cellar/python/3.7.2_1/Frameworks/Python.framework/Versions/3.7/lib/python3.7/http/client.py", line 1321, in getresponse
    response.begin()
  File "/usr/local/Cellar/python/3.7.2_1/Frameworks/Python.framework/Versions/3.7/lib/python3.7/http/client.py", line 296, in begin
    version, status, reason = self._read_status()
  File "/usr/local/Cellar/python/3.7.2_1/Frameworks/Python.framework/Versions/3.7/lib/python3.7/http/client.py", line 257, in _read_status
    line = str(self.fp.readline(_MAXLINE + 1), "iso-8859-1")
  File "/usr/local/Cellar/python/3.7.2_1/Frameworks/Python.framework/Versions/3.7/lib/python3.7/socket.py", line 589, in readinto
    return self._sock.recv_into(b)
  File "/usr/local/Cellar/python/3.7.2_1/Frameworks/Python.framework/Versions/3.7/lib/python3.7/ssl.py", line 1052, in recv_into
    return self.read(nbytes, buffer)
  File "/usr/local/Cellar/python/3.7.2_1/Frameworks/Python.framework/Versions/3.7/lib/python3.7/ssl.py", line 911, in read
    return self._sslobj.read(len, buffer)
urllib3.exceptions.ProtocolError: ('Connection aborted.', ConnectionResetError(54, 'Connection reset by peer'))

During handling of the above exception, another exception occurred:

Traceback (most recent call last):
  File "/usr/local/lib/python3.7/site-packages/pywikibot/data/api.py", line 1966, in submit
    body=body, headers=headers)
  File "/usr/local/lib/python3.7/site-packages/pywikibot/tools/__init__.py", line 1446, in wrapper
    return obj(*__args, **__kw)
  File "/usr/local/lib/python3.7/site-packages/pywikibot/comms/http.py", line 317, in request
    r = fetch(baseuri, method, params, body, headers, **kwargs)
  File "/usr/local/lib/python3.7/site-packages/pywikibot/comms/http.py", line 519, in fetch
    error_handling_callback(request)
  File "/usr/local/lib/python3.7/site-packages/pywikibot/comms/http.py", line 405, in error_handling_callback
    raise request.data
  File "/usr/local/lib/python3.7/site-packages/pywikibot/comms/http.py", line 384, in _http_process
    **http_request.kwargs)
  File "/usr/local/lib/python3.7/site-packages/requests/sessions.py", line 533, in request
    resp = self.send(prep, **send_kwargs)
  File "/usr/local/lib/python3.7/site-packages/requests/sessions.py", line 646, in send
    r = adapter.send(request, **kwargs)
  File "/usr/local/lib/python3.7/site-packages/requests/adapters.py", line 498, in send
    raise ConnectionError(err, request=request)
requests.exceptions.ConnectionError: ('Connection aborted.', ConnectionResetError(54, 'Connection reset by peer'))

2021-12-08 08:24:46 /w/api.php, iiprop=timestamp%7Cuser%7Ccomment%7Curl%7Csize%7Csha1%7Cmime%7Cmetadata%7Carchivename&titles=File%3AAbraham+Wuchters+-+Portrait+of+the+Artist+-+KMSsp803+-+Statens+Museum+for+Kunst.jpg&prop=imageinfo&action=query&indexpageids=&continue=&iilimit=500&meta=userinfo&uiprop=blockinfo%7Chasmsg&maxlag=5&format=json
2021-12-08 08:24:46 Waiting 5 seconds before retrying.
2021-12-08 08:39:27 Found 1 wikidata:wikidata processes running, including this one.
2021-12-08 08:39:28 Traceback (most recent call last):
  File "/usr/local/lib/python3.7/site-packages/urllib3/connectionpool.py", line 600, in urlopen
    chunked=chunked)
  File "/usr/local/lib/python3.7/site-packages/urllib3/connectionpool.py", line 384, in _make_request
    six.raise_from(e, None)
  File "<string>", line 2, in raise_from
  File "/usr/local/lib/python3.7/site-packages/urllib3/connectionpool.py", line 380, in _make_request
    httplib_response = conn.getresponse()
  File "/usr/local/Cellar/python/3.7.2_1/Frameworks/Python.framework/Versions/3.7/lib/python3.7/http/client.py", line 1321, in getresponse
    response.begin()
  File "/usr/local/Cellar/python/3.7.2_1/Frameworks/Python.framework/Versions/3.7/lib/python3.7/http/client.py", line 296, in begin
    version, status, reason = self._read_status()
  File "/usr/local/Cellar/python/3.7.2_1/Frameworks/Python.framework/Versions/3.7/lib/python3.7/http/client.py", line 257, in _read_status
    line = str(self.fp.readline(_MAXLINE + 1), "iso-8859-1")
  File "/usr/local/Cellar/python/3.7.2_1/Frameworks/Python.framework/Versions/3.7/lib/python3.7/socket.py", line 589, in readinto
    return self._sock.recv_into(b)
  File "/usr/local/Cellar/python/3.7.2_1/Frameworks/Python.framework/Versions/3.7/lib/python3.7/ssl.py", line 1052, in recv_into
    return self.read(nbytes, buffer)
  File "/usr/local/Cellar/python/3.7.2_1/Frameworks/Python.framework/Versions/3.7/lib/python3.7/ssl.py", line 911, in read
    return self._sslobj.read(len, buffer)
ConnectionResetError: [Errno 54] Connection reset by peer

During handling of the above exception, another exception occurred:

Traceback (most recent call last):
  File "/usr/local/lib/python3.7/site-packages/requests/adapters.py", line 449, in send
    timeout=timeout
  File "/usr/local/lib/python3.7/site-packages/urllib3/connectionpool.py", line 638, in urlopen
    _stacktrace=sys.exc_info()[2])
  File "/usr/local/lib/python3.7/site-packages/urllib3/util/retry.py", line 367, in increment
    raise six.reraise(type(error), error, _stacktrace)
  File "/usr/local/lib/python3.7/site-packages/urllib3/packages/six.py", line 685, in reraise
    raise value.with_traceback(tb)
  File "/usr/local/lib/python3.7/site-packages/urllib3/connectionpool.py", line 600, in urlopen
    chunked=chunked)
  File "/usr/local/lib/python3.7/site-packages/urllib3/connectionpool.py", line 384, in _make_request
    six.raise_from(e, None)
  File "<string>", line 2, in raise_from
  File "/usr/local/lib/python3.7/site-packages/urllib3/connectionpool.py", line 380, in _make_request
    httplib_response = conn.getresponse()
  File "/usr/local/Cellar/python/3.7.2_1/Frameworks/Python.framework/Versions/3.7/lib/python3.7/http/client.py", line 1321, in getresponse
    response.begin()
  File "/usr/local/Cellar/python/3.7.2_1/Frameworks/Python.framework/Versions/3.7/lib/python3.7/http/client.py", line 296, in begin
    version, status, reason = self._read_status()
  File "/usr/local/Cellar/python/3.7.2_1/Frameworks/Python.framework/Versions/3.7/lib/python3.7/http/client.py", line 257, in _read_status
    line = str(self.fp.readline(_MAXLINE + 1), "iso-8859-1")
  File "/usr/local/Cellar/python/3.7.2_1/Frameworks/Python.framework/Versions/3.7/lib/python3.7/socket.py", line 589, in readinto
    return self._sock.recv_into(b)
  File "/usr/local/Cellar/python/3.7.2_1/Frameworks/Python.framework/Versions/3.7/lib/python3.7/ssl.py", line 1052, in recv_into
    return self.read(nbytes, buffer)
  File "/usr/local/Cellar/python/3.7.2_1/Frameworks/Python.framework/Versions/3.7/lib/python3.7/ssl.py", line 911, in read
    return self._sslobj.read(len, buffer)
urllib3.exceptions.ProtocolError: ('Connection aborted.', ConnectionResetError(54, 'Connection reset by peer'))

During handling of the above exception, another exception occurred:

Traceback (most recent call last):
  File "/usr/local/lib/python3.7/site-packages/pywikibot/data/api.py", line 1966, in submit
    body=body, headers=headers)
  File "/usr/local/lib/python3.7/site-packages/pywikibot/tools/__init__.py", line 1446, in wrapper
    return obj(*__args, **__kw)
  File "/usr/local/lib/python3.7/site-packages/pywikibot/comms/http.py", line 317, in request
    r = fetch(baseuri, method, params, body, headers, **kwargs)
  File "/usr/local/lib/python3.7/site-packages/pywikibot/comms/http.py", line 519, in fetch
    error_handling_callback(request)
  File "/usr/local/lib/python3.7/site-packages/pywikibot/comms/http.py", line 405, in error_handling_callback
    raise request.data
  File "/usr/local/lib/python3.7/site-packages/pywikibot/comms/http.py", line 384, in _http_process
    **http_request.kwargs)
  File "/usr/local/lib/python3.7/site-packages/requests/sessions.py", line 533, in request
    resp = self.send(prep, **send_kwargs)
  File "/usr/local/lib/python3.7/site-packages/requests/sessions.py", line 646, in send
    r = adapter.send(request, **kwargs)
  File "/usr/local/lib/python3.7/site-packages/requests/adapters.py", line 498, in send
    raise ConnectionError(err, request=request)
requests.exceptions.ConnectionError: ('Connection aborted.', ConnectionResetError(54, 'Connection reset by peer'))

2021-12-08 08:39:28 /w/api.php?ids=Q20425847&action=wbgetentities&maxlag=5&format=json, ids=Q20425847&action=wbgetentities&maxlag=5&format=json
2021-12-08 08:39:28 Waiting 5 seconds before retrying.
2021-12-08 08:39:33 Found 1 commons:commons processes running, including this one.
2021-12-08 08:39:33 Traceback (most recent call last):
  File "/usr/local/lib/python3.7/site-packages/urllib3/connectionpool.py", line 600, in urlopen
    chunked=chunked)
  File "/usr/local/lib/python3.7/site-packages/urllib3/connectionpool.py", line 384, in _make_request
    six.raise_from(e, None)
  File "<string>", line 2, in raise_from
  File "/usr/local/lib/python3.7/site-packages/urllib3/connectionpool.py", line 380, in _make_request
    httplib_response = conn.getresponse()
  File "/usr/local/Cellar/python/3.7.2_1/Frameworks/Python.framework/Versions/3.7/lib/python3.7/http/client.py", line 1321, in getresponse
    response.begin()
  File "/usr/local/Cellar/python/3.7.2_1/Frameworks/Python.framework/Versions/3.7/lib/python3.7/http/client.py", line 296, in begin
    version, status, reason = self._read_status()
  File "/usr/local/Cellar/python/3.7.2_1/Frameworks/Python.framework/Versions/3.7/lib/python3.7/http/client.py", line 257, in _read_status
    line = str(self.fp.readline(_MAXLINE + 1), "iso-8859-1")
  File "/usr/local/Cellar/python/3.7.2_1/Frameworks/Python.framework/Versions/3.7/lib/python3.7/socket.py", line 589, in readinto
    return self._sock.recv_into(b)
  File "/usr/local/Cellar/python/3.7.2_1/Frameworks/Python.framework/Versions/3.7/lib/python3.7/ssl.py", line 1052, in recv_into
    return self.read(nbytes, buffer)
  File "/usr/local/Cellar/python/3.7.2_1/Frameworks/Python.framework/Versions/3.7/lib/python3.7/ssl.py", line 911, in read
    return self._sslobj.read(len, buffer)
ConnectionResetError: [Errno 54] Connection reset by peer

During handling of the above exception, another exception occurred:

Traceback (most recent call last):
  File "/usr/local/lib/python3.7/site-packages/requests/adapters.py", line 449, in send
    timeout=timeout
  File "/usr/local/lib/python3.7/site-packages/urllib3/connectionpool.py", line 638, in urlopen
    _stacktrace=sys.exc_info()[2])
  File "/usr/local/lib/python3.7/site-packages/urllib3/util/retry.py", line 367, in increment
    raise six.reraise(type(error), error, _stacktrace)
  File "/usr/local/lib/python3.7/site-packages/urllib3/packages/six.py", line 685, in reraise
    raise value.with_traceback(tb)
  File "/usr/local/lib/python3.7/site-packages/urllib3/connectionpool.py", line 600, in urlopen
    chunked=chunked)
  File "/usr/local/lib/python3.7/site-packages/urllib3/connectionpool.py", line 384, in _make_request
    six.raise_from(e, None)
  File "<string>", line 2, in raise_from
  File "/usr/local/lib/python3.7/site-packages/urllib3/connectionpool.py", line 380, in _make_request
    httplib_response = conn.getresponse()
  File "/usr/local/Cellar/python/3.7.2_1/Frameworks/Python.framework/Versions/3.7/lib/python3.7/http/client.py", line 1321, in getresponse
    response.begin()
  File "/usr/local/Cellar/python/3.7.2_1/Frameworks/Python.framework/Versions/3.7/lib/python3.7/http/client.py", line 296, in begin
    version, status, reason = self._read_status()
  File "/usr/local/Cellar/python/3.7.2_1/Frameworks/Python.framework/Versions/3.7/lib/python3.7/http/client.py", line 257, in _read_status
    line = str(self.fp.readline(_MAXLINE + 1), "iso-8859-1")
  File "/usr/local/Cellar/python/3.7.2_1/Frameworks/Python.framework/Versions/3.7/lib/python3.7/socket.py", line 589, in readinto
    return self._sock.recv_into(b)
  File "/usr/local/Cellar/python/3.7.2_1/Frameworks/Python.framework/Versions/3.7/lib/python3.7/ssl.py", line 1052, in recv_into
    return self.read(nbytes, buffer)
  File "/usr/local/Cellar/python/3.7.2_1/Frameworks/Python.framework/Versions/3.7/lib/python3.7/ssl.py", line 911, in read
    return self._sslobj.read(len, buffer)
urllib3.exceptions.ProtocolError: ('Connection aborted.', ConnectionResetError(54, 'Connection reset by peer'))

During handling of the above exception, another exception occurred:

Traceback (most recent call last):
  File "/usr/local/lib/python3.7/site-packages/pywikibot/data/api.py", line 1966, in submit
    body=body, headers=headers)
  File "/usr/local/lib/python3.7/site-packages/pywikibot/tools/__init__.py", line 1446, in wrapper
    return obj(*__args, **__kw)
  File "/usr/local/lib/python3.7/site-packages/pywikibot/comms/http.py", line 317, in request
    r = fetch(baseuri, method, params, body, headers, **kwargs)
  File "/usr/local/lib/python3.7/site-packages/pywikibot/comms/http.py", line 519, in fetch
    error_handling_callback(request)
  File "/usr/local/lib/python3.7/site-packages/pywikibot/comms/http.py", line 405, in error_handling_callback
    raise request.data
  File "/usr/local/lib/python3.7/site-packages/pywikibot/comms/http.py", line 384, in _http_process
    **http_request.kwargs)
  File "/usr/local/lib/python3.7/site-packages/requests/sessions.py", line 533, in request
    resp = self.send(prep, **send_kwargs)
  File "/usr/local/lib/python3.7/site-packages/requests/sessions.py", line 646, in send
    r = adapter.send(request, **kwargs)
  File "/usr/local/lib/python3.7/site-packages/requests/adapters.py", line 498, in send
    raise ConnectionError(err, request=request)
requests.exceptions.ConnectionError: ('Connection aborted.', ConnectionResetError(54, 'Connection reset by peer'))

2021-12-08 08:39:33 /w/api.php, iiprop=timestamp%7Cuser%7Ccomment%7Curl%7Csize%7Csha1%7Cmime%7Cmetadata%7Carchivename&titles=File%3ADitlev+Blunck+-+The+Vision+of+the+Prophet+Ezekiel+-+KMS200+-+Statens+Museum+for+Kunst.jpg&prop=imageinfo&action=query&indexpageids=&continue=&iilimit=500&meta=userinfo&uiprop=blockinfo%7Chasmsg&maxlag=5&format=json
2021-12-08 08:39:33 Waiting 5 seconds before retrying.
2021-12-08 08:54:57 Found 1 wikidata:wikidata processes running, including this one.
2021-12-08 08:54:57 Traceback (most recent call last):
  File "/usr/local/lib/python3.7/site-packages/urllib3/connectionpool.py", line 600, in urlopen
    chunked=chunked)
  File "/usr/local/lib/python3.7/site-packages/urllib3/connectionpool.py", line 384, in _make_request
    six.raise_from(e, None)
  File "<string>", line 2, in raise_from
  File "/usr/local/lib/python3.7/site-packages/urllib3/connectionpool.py", line 380, in _make_request
    httplib_response = conn.getresponse()
  File "/usr/local/Cellar/python/3.7.2_1/Frameworks/Python.framework/Versions/3.7/lib/python3.7/http/client.py", line 1321, in getresponse
    response.begin()
  File "/usr/local/Cellar/python/3.7.2_1/Frameworks/Python.framework/Versions/3.7/lib/python3.7/http/client.py", line 296, in begin
    version, status, reason = self._read_status()
  File "/usr/local/Cellar/python/3.7.2_1/Frameworks/Python.framework/Versions/3.7/lib/python3.7/http/client.py", line 257, in _read_status
    line = str(self.fp.readline(_MAXLINE + 1), "iso-8859-1")
  File "/usr/local/Cellar/python/3.7.2_1/Frameworks/Python.framework/Versions/3.7/lib/python3.7/socket.py", line 589, in readinto
    return self._sock.recv_into(b)
  File "/usr/local/Cellar/python/3.7.2_1/Frameworks/Python.framework/Versions/3.7/lib/python3.7/ssl.py", line 1052, in recv_into
    return self.read(nbytes, buffer)
  File "/usr/local/Cellar/python/3.7.2_1/Frameworks/Python.framework/Versions/3.7/lib/python3.7/ssl.py", line 911, in read
    return self._sslobj.read(len, buffer)
ConnectionResetError: [Errno 54] Connection reset by peer

During handling of the above exception, another exception occurred:

Traceback (most recent call last):
  File "/usr/local/lib/python3.7/site-packages/requests/adapters.py", line 449, in send
    timeout=timeout
  File "/usr/local/lib/python3.7/site-packages/urllib3/connectionpool.py", line 638, in urlopen
    _stacktrace=sys.exc_info()[2])
  File "/usr/local/lib/python3.7/site-packages/urllib3/util/retry.py", line 367, in increment
    raise six.reraise(type(error), error, _stacktrace)
  File "/usr/local/lib/python3.7/site-packages/urllib3/packages/six.py", line 685, in reraise
    raise value.with_traceback(tb)
  File "/usr/local/lib/python3.7/site-packages/urllib3/connectionpool.py", line 600, in urlopen
    chunked=chunked)
  File "/usr/local/lib/python3.7/site-packages/urllib3/connectionpool.py", line 384, in _make_request
    six.raise_from(e, None)
  File "<string>", line 2, in raise_from
  File "/usr/local/lib/python3.7/site-packages/urllib3/connectionpool.py", line 380, in _make_request
    httplib_response = conn.getresponse()
  File "/usr/local/Cellar/python/3.7.2_1/Frameworks/Python.framework/Versions/3.7/lib/python3.7/http/client.py", line 1321, in getresponse
    response.begin()
  File "/usr/local/Cellar/python/3.7.2_1/Frameworks/Python.framework/Versions/3.7/lib/python3.7/http/client.py", line 296, in begin
    version, status, reason = self._read_status()
  File "/usr/local/Cellar/python/3.7.2_1/Frameworks/Python.framework/Versions/3.7/lib/python3.7/http/client.py", line 257, in _read_status
    line = str(self.fp.readline(_MAXLINE + 1), "iso-8859-1")
  File "/usr/local/Cellar/python/3.7.2_1/Frameworks/Python.framework/Versions/3.7/lib/python3.7/socket.py", line 589, in readinto
    return self._sock.recv_into(b)
  File "/usr/local/Cellar/python/3.7.2_1/Frameworks/Python.framework/Versions/3.7/lib/python3.7/ssl.py", line 1052, in recv_into
    return self.read(nbytes, buffer)
  File "/usr/local/Cellar/python/3.7.2_1/Frameworks/Python.framework/Versions/3.7/lib/python3.7/ssl.py", line 911, in read
    return self._sslobj.read(len, buffer)
urllib3.exceptions.ProtocolError: ('Connection aborted.', ConnectionResetError(54, 'Connection reset by peer'))

During handling of the above exception, another exception occurred:

Traceback (most recent call last):
  File "/usr/local/lib/python3.7/site-packages/pywikibot/data/api.py", line 1966, in submit
    body=body, headers=headers)
  File "/usr/local/lib/python3.7/site-packages/pywikibot/tools/__init__.py", line 1446, in wrapper
    return obj(*__args, **__kw)
  File "/usr/local/lib/python3.7/site-packages/pywikibot/comms/http.py", line 317, in request
    r = fetch(baseuri, method, params, body, headers, **kwargs)
  File "/usr/local/lib/python3.7/site-packages/pywikibot/comms/http.py", line 519, in fetch
    error_handling_callback(request)
  File "/usr/local/lib/python3.7/site-packages/pywikibot/comms/http.py", line 405, in error_handling_callback
    raise request.data
  File "/usr/local/lib/python3.7/site-packages/pywikibot/comms/http.py", line 384, in _http_process
    **http_request.kwargs)
  File "/usr/local/lib/python3.7/site-packages/requests/sessions.py", line 533, in request
    resp = self.send(prep, **send_kwargs)
  File "/usr/local/lib/python3.7/site-packages/requests/sessions.py", line 646, in send
    r = adapter.send(request, **kwargs)
  File "/usr/local/lib/python3.7/site-packages/requests/adapters.py", line 498, in send
    raise ConnectionError(err, request=request)
requests.exceptions.ConnectionError: ('Connection aborted.', ConnectionResetError(54, 'Connection reset by peer'))

2021-12-08 08:54:57 /w/api.php?ids=Q20425923&action=wbgetentities&maxlag=5&format=json, ids=Q20425923&action=wbgetentities&maxlag=5&format=json
2021-12-08 08:54:57 Waiting 5 seconds before retrying.
2021-12-08 08:55:02 Found 1 commons:commons processes running, including this one.
2021-12-08 08:55:02 Traceback (most recent call last):
  File "/usr/local/lib/python3.7/site-packages/urllib3/connectionpool.py", line 600, in urlopen
    chunked=chunked)
  File "/usr/local/lib/python3.7/site-packages/urllib3/connectionpool.py", line 384, in _make_request
    six.raise_from(e, None)
  File "<string>", line 2, in raise_from
  File "/usr/local/lib/python3.7/site-packages/urllib3/connectionpool.py", line 380, in _make_request
    httplib_response = conn.getresponse()
  File "/usr/local/Cellar/python/3.7.2_1/Frameworks/Python.framework/Versions/3.7/lib/python3.7/http/client.py", line 1321, in getresponse
    response.begin()
  File "/usr/local/Cellar/python/3.7.2_1/Frameworks/Python.framework/Versions/3.7/lib/python3.7/http/client.py", line 296, in begin
    version, status, reason = self._read_status()
  File "/usr/local/Cellar/python/3.7.2_1/Frameworks/Python.framework/Versions/3.7/lib/python3.7/http/client.py", line 257, in _read_status
    line = str(self.fp.readline(_MAXLINE + 1), "iso-8859-1")
  File "/usr/local/Cellar/python/3.7.2_1/Frameworks/Python.framework/Versions/3.7/lib/python3.7/socket.py", line 589, in readinto
    return self._sock.recv_into(b)
  File "/usr/local/Cellar/python/3.7.2_1/Frameworks/Python.framework/Versions/3.7/lib/python3.7/ssl.py", line 1052, in recv_into
    return self.read(nbytes, buffer)
  File "/usr/local/Cellar/python/3.7.2_1/Frameworks/Python.framework/Versions/3.7/lib/python3.7/ssl.py", line 911, in read
    return self._sslobj.read(len, buffer)
ConnectionResetError: [Errno 54] Connection reset by peer

During handling of the above exception, another exception occurred:

Traceback (most recent call last):
  File "/usr/local/lib/python3.7/site-packages/requests/adapters.py", line 449, in send
    timeout=timeout
  File "/usr/local/lib/python3.7/site-packages/urllib3/connectionpool.py", line 638, in urlopen
    _stacktrace=sys.exc_info()[2])
  File "/usr/local/lib/python3.7/site-packages/urllib3/util/retry.py", line 367, in increment
    raise six.reraise(type(error), error, _stacktrace)
  File "/usr/local/lib/python3.7/site-packages/urllib3/packages/six.py", line 685, in reraise
    raise value.with_traceback(tb)
  File "/usr/local/lib/python3.7/site-packages/urllib3/connectionpool.py", line 600, in urlopen
    chunked=chunked)
  File "/usr/local/lib/python3.7/site-packages/urllib3/connectionpool.py", line 384, in _make_request
    six.raise_from(e, None)
  File "<string>", line 2, in raise_from
  File "/usr/local/lib/python3.7/site-packages/urllib3/connectionpool.py", line 380, in _make_request
    httplib_response = conn.getresponse()
  File "/usr/local/Cellar/python/3.7.2_1/Frameworks/Python.framework/Versions/3.7/lib/python3.7/http/client.py", line 1321, in getresponse
    response.begin()
  File "/usr/local/Cellar/python/3.7.2_1/Frameworks/Python.framework/Versions/3.7/lib/python3.7/http/client.py", line 296, in begin
    version, status, reason = self._read_status()
  File "/usr/local/Cellar/python/3.7.2_1/Frameworks/Python.framework/Versions/3.7/lib/python3.7/http/client.py", line 257, in _read_status
    line = str(self.fp.readline(_MAXLINE + 1), "iso-8859-1")
  File "/usr/local/Cellar/python/3.7.2_1/Frameworks/Python.framework/Versions/3.7/lib/python3.7/socket.py", line 589, in readinto
    return self._sock.recv_into(b)
  File "/usr/local/Cellar/python/3.7.2_1/Frameworks/Python.framework/Versions/3.7/lib/python3.7/ssl.py", line 1052, in recv_into
    return self.read(nbytes, buffer)
  File "/usr/local/Cellar/python/3.7.2_1/Frameworks/Python.framework/Versions/3.7/lib/python3.7/ssl.py", line 911, in read
    return self._sslobj.read(len, buffer)
urllib3.exceptions.ProtocolError: ('Connection aborted.', ConnectionResetError(54, 'Connection reset by peer'))

During handling of the above exception, another exception occurred:

Traceback (most recent call last):
  File "/usr/local/lib/python3.7/site-packages/pywikibot/data/api.py", line 1966, in submit
    body=body, headers=headers)
  File "/usr/local/lib/python3.7/site-packages/pywikibot/tools/__init__.py", line 1446, in wrapper
    return obj(*__args, **__kw)
  File "/usr/local/lib/python3.7/site-packages/pywikibot/comms/http.py", line 317, in request
    r = fetch(baseuri, method, params, body, headers, **kwargs)
  File "/usr/local/lib/python3.7/site-packages/pywikibot/comms/http.py", line 519, in fetch
    error_handling_callback(request)
  File "/usr/local/lib/python3.7/site-packages/pywikibot/comms/http.py", line 405, in error_handling_callback
    raise request.data
  File "/usr/local/lib/python3.7/site-packages/pywikibot/comms/http.py", line 384, in _http_process
    **http_request.kwargs)
  File "/usr/local/lib/python3.7/site-packages/requests/sessions.py", line 533, in request
    resp = self.send(prep, **send_kwargs)
  File "/usr/local/lib/python3.7/site-packages/requests/sessions.py", line 646, in send
    r = adapter.send(request, **kwargs)
  File "/usr/local/lib/python3.7/site-packages/requests/adapters.py", line 498, in send
    raise ConnectionError(err, request=request)
requests.exceptions.ConnectionError: ('Connection aborted.', ConnectionResetError(54, 'Connection reset by peer'))

2021-12-08 08:55:02 /w/api.php, iiprop=timestamp%7Cuser%7Ccomment%7Curl%7Csize%7Csha1%7Cmime%7Cmetadata%7Carchivename&titles=File%3AC.A.+Lorentzen+-+De+Usynlige%2C+III+akt%2C+3.+scene+-+KMS481+-+Statens+Museum+for+Kunst.jpg&prop=imageinfo&action=query&indexpageids=&continue=&iilimit=500&meta=userinfo&uiprop=blockinfo%7Chasmsg&maxlag=5&format=json
2021-12-08 08:55:02 Waiting 5 seconds before retrying.
2021-12-08 08:59:57 Found 1 wikidata:wikidata processes running, including this one.
2021-12-08 09:00:02 Found 1 commons:commons processes running, including this one.
2021-12-08 09:04:57 Found 1 wikidata:wikidata processes running, including this one.
2021-12-08 09:05:03 Found 1 commons:commons processes running, including this one.
2021-12-08 09:09:57 Found 1 wikidata:wikidata processes running, including this one.
2021-12-08 09:09:59 Dropped throttle(s).
2021-12-08 09:09:59 Closing network session.
2021-12-08 09:09:59 Network session closed.
2021-12-20 06:31:40 
2021-12-20 06:31:40 === Pywikibot framework v6.6.3 -- Logging header ===
2021-12-20 06:31:40 COMMAND: ['/Users/kimbach/Documents/wikilabskultur/batchupload/wikidata.py']
2021-12-20 06:31:40 DATE: 2021-12-20 05:31:40.714446 UTC
2021-12-20 06:31:40 VERSION: pywikibot/__init__.py (, -1 (unknown), 2021/12/15, 13:01:25, n/a)
2021-12-20 06:31:40 SYSTEM: posix.uname_result(sysname='Darwin', nodename='Isis.local', release='19.6.0', version='Darwin Kernel Version 19.6.0: Tue Jun 22 19:49:55 PDT 2021; root:xnu-6153.141.35~1/RELEASE_X86_64', machine='x86_64')
2021-12-20 06:31:40 CONFIG FILE DIR: /Users/kimbach/Documents/wikilabskultur/batchupload
2021-12-20 06:31:40 PACKAGES:
2021-12-20 06:31:40 MODULES:
2021-12-20 06:31:40   2018-12-24 04:41:55 /usr/local/lib/python3.7/site-packages/pkg_resources/__init__.py
2021-12-20 06:31:40   2018-12-24 04:41:55 /usr/local/lib/python3.7/site-packages/pkg_resources/extern/__init__.py
2021-12-20 06:31:40   2018-12-24 04:41:55 /usr/local/lib/python3.7/site-packages/pkg_resources/_vendor/__init__.py
2021-12-20 06:31:40   2018-12-24 04:41:55 /usr/local/lib/python3.7/site-packages/pkg_resources/_vendor/six.py
2021-12-20 06:31:40   2018-12-24 04:41:55 /usr/local/lib/python3.7/site-packages/pkg_resources/_vendor/six.py
2021-12-20 06:31:40   2018-12-24 04:41:55 /usr/local/lib/python3.7/site-packages/pkg_resources/py31compat.py
2021-12-20 06:31:40   2019-02-09 19:09:29 /usr/local/lib/python3.7/site-packages/pkg_resources/_vendor/appdirs.py
2021-12-20 06:31:40   2018-12-24 04:41:55 /usr/local/lib/python3.7/site-packages/pkg_resources/_vendor/packaging/__about__.py
2021-12-20 06:31:40   2018-12-24 04:41:55 /usr/local/lib/python3.7/site-packages/pkg_resources/_vendor/packaging/__init__.py
2021-12-20 06:31:40   2018-12-24 04:41:55 /usr/local/lib/python3.7/site-packages/pkg_resources/_vendor/packaging/version.py
2021-12-20 06:31:40   2018-12-24 04:41:55 /usr/local/lib/python3.7/site-packages/pkg_resources/_vendor/packaging/_structures.py
2021-12-20 06:31:40   2018-12-24 04:41:55 /usr/local/lib/python3.7/site-packages/pkg_resources/_vendor/packaging/specifiers.py
2021-12-20 06:31:40   2018-12-24 04:41:55 /usr/local/lib/python3.7/site-packages/pkg_resources/_vendor/packaging/_compat.py
2021-12-20 06:31:40   2018-12-24 04:41:55 /usr/local/lib/python3.7/site-packages/pkg_resources/_vendor/packaging/requirements.py
2021-12-20 06:31:40   2018-12-24 04:41:55 /usr/local/lib/python3.7/site-packages/pkg_resources/_vendor/pyparsing.py
2021-12-20 06:31:40   2018-12-24 04:41:55 /usr/local/lib/python3.7/site-packages/pkg_resources/_vendor/packaging/markers.py
2021-12-20 06:31:40   2019-09-14 05:06:46 /usr/local/lib/python3.7/site-packages/dateutil/__init__.py
2021-12-20 06:31:40   2019-09-14 05:06:46 /usr/local/lib/python3.7/site-packages/dateutil/_version.py
2021-12-20 06:31:40   2019-09-14 05:06:46 /usr/local/lib/python3.7/site-packages/dateutil/parser/__init__.py
2021-12-20 06:31:40   2019-09-14 05:06:46 /usr/local/lib/python3.7/site-packages/dateutil/parser/_parser.py
2021-12-20 06:31:40   2019-09-14 05:06:46 /usr/local/lib/python3.7/site-packages/dateutil/relativedelta.py
2021-12-20 06:31:40   2019-09-14 05:06:46 /usr/local/lib/python3.7/site-packages/dateutil/_common.py
2021-12-20 06:31:40   2019-09-14 05:06:46 /usr/local/lib/python3.7/site-packages/dateutil/tz/__init__.py
2021-12-20 06:31:40   2019-09-14 05:06:46 /usr/local/lib/python3.7/site-packages/dateutil/tz/tz.py
2021-12-20 06:31:40   2019-09-14 05:06:46 /usr/local/lib/python3.7/site-packages/dateutil/tz/_common.py
2021-12-20 06:31:40   2019-09-14 05:06:46 /usr/local/lib/python3.7/site-packages/dateutil/tz/_factories.py
2021-12-20 06:31:40   2019-09-14 05:06:46 /usr/local/lib/python3.7/site-packages/dateutil/parser/isoparser.py
2021-12-20 06:31:40   2021-12-15 13:01:25 /usr/local/lib/python3.7/site-packages/pywikibot/__init__.py
2021-12-20 06:31:40   2021-12-15 13:01:25 /usr/local/lib/python3.7/site-packages/pywikibot/config.py
2021-12-20 06:31:40   2021-12-15 13:01:25 /usr/local/lib/python3.7/site-packages/pywikibot/__metadata__.py
2021-12-20 06:31:40   2021-12-15 13:01:25 /usr/local/lib/python3.7/site-packages/pywikibot/backports.py
2021-12-20 06:31:40   2021-12-15 13:01:25 /usr/local/lib/python3.7/site-packages/pywikibot/logging.py
2021-12-20 06:31:40   2021-12-15 13:01:25 /usr/local/lib/python3.7/site-packages/pywikibot/tools/__init__.py
2021-12-20 06:31:40   2021-12-15 13:01:25 /usr/local/lib/python3.7/site-packages/pywikibot/tools/_deprecate.py
2021-12-20 06:31:40   2021-12-15 13:01:25 /usr/local/lib/python3.7/site-packages/pywikibot/tools/_unidata.py
2021-12-20 06:31:40   2021-12-15 13:01:25 /usr/local/lib/python3.7/site-packages/pywikibot/exceptions.py
2021-12-20 06:31:40   2021-12-15 13:01:25 /usr/local/lib/python3.7/site-packages/pywikibot/_wbtypes.py
2021-12-20 06:31:40   2021-12-15 13:01:25 /usr/local/lib/python3.7/site-packages/pywikibot/bot.py
2021-12-20 06:31:40   2021-12-15 13:01:25 /usr/local/lib/python3.7/site-packages/pywikibot/daemonize.py
2021-12-20 06:31:40   2021-12-15 13:01:25 /usr/local/lib/python3.7/site-packages/pywikibot/i18n.py
2021-12-20 06:31:40   2021-12-15 13:01:25 /usr/local/lib/python3.7/site-packages/pywikibot/plural.py
2021-12-20 06:31:40   2021-12-15 13:01:25 /usr/local/lib/python3.7/site-packages/pywikibot/version.py
2021-12-20 06:31:40   2021-12-15 13:01:25 /usr/local/lib/python3.7/site-packages/pywikibot/comms/__init__.py
2021-12-20 06:31:40   2021-12-15 13:01:25 /usr/local/lib/python3.7/site-packages/pywikibot/comms/http.py
2021-12-20 06:31:40   2019-02-14 18:34:46 /usr/local/lib/python3.7/site-packages/requests/__init__.py
2021-12-20 06:31:40   2019-02-14 18:34:46 /usr/local/lib/python3.7/site-packages/urllib3/__init__.py
2021-12-20 06:31:40   2019-02-14 18:34:46 /usr/local/lib/python3.7/site-packages/urllib3/connectionpool.py
2021-12-20 06:31:40   2019-02-14 18:34:46 /usr/local/lib/python3.7/site-packages/urllib3/exceptions.py
2021-12-20 06:31:40   2019-02-14 18:34:46 /usr/local/lib/python3.7/site-packages/urllib3/packages/__init__.py
2021-12-20 06:31:40   2019-02-14 18:34:46 /usr/local/lib/python3.7/site-packages/urllib3/packages/ssl_match_hostname/__init__.py
2021-12-20 06:31:40   2019-02-14 18:34:46 /usr/local/lib/python3.7/site-packages/urllib3/packages/six.py
2021-12-20 06:31:40   2019-02-14 18:34:46 /usr/local/lib/python3.7/site-packages/urllib3/connection.py
2021-12-20 06:31:40   2019-02-14 18:34:46 /usr/local/lib/python3.7/site-packages/urllib3/util/__init__.py
2021-12-20 06:31:40   2019-02-14 18:34:46 /usr/local/lib/python3.7/site-packages/urllib3/util/connection.py
2021-12-20 06:31:40   2019-02-14 18:34:46 /usr/local/lib/python3.7/site-packages/urllib3/util/wait.py
2021-12-20 06:31:40   2019-02-14 18:34:46 /usr/local/lib/python3.7/site-packages/urllib3/contrib/__init__.py
2021-12-20 06:31:40   2019-02-14 18:34:46 /usr/local/lib/python3.7/site-packages/urllib3/contrib/_appengine_environ.py
2021-12-20 06:31:40   2019-02-14 18:34:46 /usr/local/lib/python3.7/site-packages/urllib3/util/request.py
2021-12-20 06:31:40   2019-02-14 18:34:46 /usr/local/lib/python3.7/site-packages/urllib3/util/response.py
2021-12-20 06:31:40   2019-02-14 18:34:46 /usr/local/lib/python3.7/site-packages/urllib3/util/ssl_.py
2021-12-20 06:31:40   2019-02-14 18:34:46 /usr/local/lib/python3.7/site-packages/urllib3/util/timeout.py
2021-12-20 06:31:40   2019-02-14 18:34:46 /usr/local/lib/python3.7/site-packages/urllib3/util/retry.py
2021-12-20 06:31:40   2019-02-14 18:34:46 /usr/local/lib/python3.7/site-packages/urllib3/util/url.py
2021-12-20 06:31:40   2019-02-14 18:34:46 /usr/local/lib/python3.7/site-packages/urllib3/_collections.py
2021-12-20 06:31:40   2019-02-14 18:34:46 /usr/local/lib/python3.7/site-packages/urllib3/request.py
2021-12-20 06:31:40   2019-02-14 18:34:46 /usr/local/lib/python3.7/site-packages/urllib3/filepost.py
2021-12-20 06:31:40   2019-02-14 18:34:46 /usr/local/lib/python3.7/site-packages/urllib3/fields.py
2021-12-20 06:31:40   2019-02-14 18:34:46 /usr/local/lib/python3.7/site-packages/urllib3/response.py
2021-12-20 06:31:40   2019-02-14 18:34:46 /usr/local/lib/python3.7/site-packages/urllib3/util/queue.py
2021-12-20 06:31:40   2019-02-14 18:34:46 /usr/local/lib/python3.7/site-packages/urllib3/poolmanager.py
2021-12-20 06:31:40   2019-02-14 18:34:47 /usr/local/lib/python3.7/site-packages/chardet/__init__.py
2021-12-20 06:31:40   2019-02-14 18:34:47 /usr/local/lib/python3.7/site-packages/chardet/compat.py
2021-12-20 06:31:40   2019-02-14 18:34:47 /usr/local/lib/python3.7/site-packages/chardet/universaldetector.py
2021-12-20 06:31:40   2019-02-14 18:34:47 /usr/local/lib/python3.7/site-packages/chardet/charsetgroupprober.py
2021-12-20 06:31:40   2019-02-14 18:34:47 /usr/local/lib/python3.7/site-packages/chardet/enums.py
2021-12-20 06:31:40   2019-02-14 18:34:47 /usr/local/lib/python3.7/site-packages/chardet/charsetprober.py
2021-12-20 06:31:40   2019-02-14 18:34:47 /usr/local/lib/python3.7/site-packages/chardet/escprober.py
2021-12-20 06:31:40   2019-02-14 18:34:47 /usr/local/lib/python3.7/site-packages/chardet/codingstatemachine.py
2021-12-20 06:31:40   2019-02-14 18:34:47 /usr/local/lib/python3.7/site-packages/chardet/escsm.py
2021-12-20 06:31:40   2019-02-14 18:34:47 /usr/local/lib/python3.7/site-packages/chardet/latin1prober.py
2021-12-20 06:31:40   2019-02-14 18:34:47 /usr/local/lib/python3.7/site-packages/chardet/mbcsgroupprober.py
2021-12-20 06:31:40   2019-02-14 18:34:47 /usr/local/lib/python3.7/site-packages/chardet/utf8prober.py
2021-12-20 06:31:40   2019-02-14 18:34:47 /usr/local/lib/python3.7/site-packages/chardet/mbcssm.py
2021-12-20 06:31:40   2019-02-14 18:34:47 /usr/local/lib/python3.7/site-packages/chardet/sjisprober.py
2021-12-20 06:31:40   2019-02-14 18:34:47 /usr/local/lib/python3.7/site-packages/chardet/mbcharsetprober.py
2021-12-20 06:31:40   2019-02-14 18:34:47 /usr/local/lib/python3.7/site-packages/chardet/chardistribution.py
2021-12-20 06:31:40   2019-02-14 18:34:47 /usr/local/lib/python3.7/site-packages/chardet/euctwfreq.py
2021-12-20 06:31:40   2019-02-14 18:34:47 /usr/local/lib/python3.7/site-packages/chardet/euckrfreq.py
2021-12-20 06:31:40   2019-02-14 18:34:47 /usr/local/lib/python3.7/site-packages/chardet/gb2312freq.py
2021-12-20 06:31:40   2019-02-14 18:34:47 /usr/local/lib/python3.7/site-packages/chardet/big5freq.py
2021-12-20 06:31:40   2019-02-14 18:34:47 /usr/local/lib/python3.7/site-packages/chardet/jisfreq.py
2021-12-20 06:31:40   2019-02-14 18:34:47 /usr/local/lib/python3.7/site-packages/chardet/jpcntx.py
2021-12-20 06:31:40   2019-02-14 18:34:47 /usr/local/lib/python3.7/site-packages/chardet/eucjpprober.py
2021-12-20 06:31:40   2019-02-14 18:34:47 /usr/local/lib/python3.7/site-packages/chardet/gb2312prober.py
2021-12-20 06:31:40   2019-02-14 18:34:47 /usr/local/lib/python3.7/site-packages/chardet/euckrprober.py
2021-12-20 06:31:40   2019-02-14 18:34:47 /usr/local/lib/python3.7/site-packages/chardet/cp949prober.py
2021-12-20 06:31:40   2019-02-14 18:34:47 /usr/local/lib/python3.7/site-packages/chardet/big5prober.py
2021-12-20 06:31:40   2019-02-14 18:34:47 /usr/local/lib/python3.7/site-packages/chardet/euctwprober.py
2021-12-20 06:31:40   2019-02-14 18:34:47 /usr/local/lib/python3.7/site-packages/chardet/sbcsgroupprober.py
2021-12-20 06:31:40   2019-02-14 18:34:47 /usr/local/lib/python3.7/site-packages/chardet/sbcharsetprober.py
2021-12-20 06:31:40   2019-02-14 18:34:47 /usr/local/lib/python3.7/site-packages/chardet/langcyrillicmodel.py
2021-12-20 06:31:40   2019-02-14 18:34:47 /usr/local/lib/python3.7/site-packages/chardet/langgreekmodel.py
2021-12-20 06:31:40   2019-02-14 18:34:47 /usr/local/lib/python3.7/site-packages/chardet/langbulgarianmodel.py
2021-12-20 06:31:40   2019-02-14 18:34:47 /usr/local/lib/python3.7/site-packages/chardet/langthaimodel.py
2021-12-20 06:31:40   2019-02-14 18:34:47 /usr/local/lib/python3.7/site-packages/chardet/langhebrewmodel.py
2021-12-20 06:31:40   2019-02-14 18:34:47 /usr/local/lib/python3.7/site-packages/chardet/hebrewprober.py
2021-12-20 06:31:40   2019-02-14 18:34:47 /usr/local/lib/python3.7/site-packages/chardet/langturkishmodel.py
2021-12-20 06:31:40   2019-02-14 18:34:47 /usr/local/lib/python3.7/site-packages/chardet/version.py
2021-12-20 06:31:40   2019-02-14 18:34:46 /usr/local/lib/python3.7/site-packages/requests/exceptions.py
2021-12-20 06:31:40   2019-02-14 18:34:46 /usr/local/lib/python3.7/site-packages/requests/__version__.py
2021-12-20 06:31:40   2019-02-14 18:34:46 /usr/local/lib/python3.7/site-packages/requests/utils.py
2021-12-20 06:31:40   2019-02-14 18:34:46 /usr/local/lib/python3.7/site-packages/requests/certs.py
2021-12-20 06:31:40   2019-02-14 18:34:46 /usr/local/lib/python3.7/site-packages/certifi/__init__.py
2021-12-20 06:31:40   2019-02-14 18:34:46 /usr/local/lib/python3.7/site-packages/certifi/core.py
2021-12-20 06:31:40   2019-02-14 18:34:46 /usr/local/lib/python3.7/site-packages/requests/_internal_utils.py
2021-12-20 06:31:40   2019-02-14 18:34:46 /usr/local/lib/python3.7/site-packages/requests/compat.py
2021-12-20 06:31:40   2019-02-14 18:34:46 /usr/local/lib/python3.7/site-packages/requests/cookies.py
2021-12-20 06:31:40   2019-02-14 18:34:46 /usr/local/lib/python3.7/site-packages/requests/structures.py
2021-12-20 06:31:40   2019-02-14 18:34:46 /usr/local/lib/python3.7/site-packages/requests/packages.py
2021-12-20 06:31:40   2019-02-14 18:34:46 /usr/local/lib/python3.7/site-packages/urllib3/__init__.py
2021-12-20 06:31:40   2019-02-14 18:34:46 /usr/local/lib/python3.7/site-packages/urllib3/connectionpool.py
2021-12-20 06:31:40   2019-02-14 18:34:46 /usr/local/lib/python3.7/site-packages/urllib3/exceptions.py
2021-12-20 06:31:40   2019-02-14 18:34:46 /usr/local/lib/python3.7/site-packages/urllib3/packages/__init__.py
2021-12-20 06:31:40   2019-02-14 18:34:46 /usr/local/lib/python3.7/site-packages/urllib3/packages/ssl_match_hostname/__init__.py
2021-12-20 06:31:40   2019-02-14 18:34:46 /usr/local/lib/python3.7/site-packages/urllib3/packages/six.py
2021-12-20 06:31:40   2019-02-14 18:34:46 /usr/local/lib/python3.7/site-packages/urllib3/connection.py
2021-12-20 06:31:40   2019-02-14 18:34:46 /usr/local/lib/python3.7/site-packages/urllib3/util/__init__.py
2021-12-20 06:31:40   2019-02-14 18:34:46 /usr/local/lib/python3.7/site-packages/urllib3/util/connection.py
2021-12-20 06:31:40   2019-02-14 18:34:46 /usr/local/lib/python3.7/site-packages/urllib3/util/wait.py
2021-12-20 06:31:40   2019-02-14 18:34:46 /usr/local/lib/python3.7/site-packages/urllib3/contrib/__init__.py
2021-12-20 06:31:40   2019-02-14 18:34:46 /usr/local/lib/python3.7/site-packages/urllib3/contrib/_appengine_environ.py
2021-12-20 06:31:40   2019-02-14 18:34:46 /usr/local/lib/python3.7/site-packages/urllib3/util/request.py
2021-12-20 06:31:40   2019-02-14 18:34:46 /usr/local/lib/python3.7/site-packages/urllib3/util/response.py
2021-12-20 06:31:40   2019-02-14 18:34:46 /usr/local/lib/python3.7/site-packages/urllib3/util/ssl_.py
2021-12-20 06:31:40   2019-02-14 18:34:46 /usr/local/lib/python3.7/site-packages/urllib3/util/timeout.py
2021-12-20 06:31:40   2019-02-14 18:34:46 /usr/local/lib/python3.7/site-packages/urllib3/util/retry.py
2021-12-20 06:31:40   2019-02-14 18:34:46 /usr/local/lib/python3.7/site-packages/urllib3/util/url.py
2021-12-20 06:31:40   2019-02-14 18:34:46 /usr/local/lib/python3.7/site-packages/urllib3/_collections.py
2021-12-20 06:31:40   2019-02-14 18:34:46 /usr/local/lib/python3.7/site-packages/urllib3/request.py
2021-12-20 06:31:40   2019-02-14 18:34:46 /usr/local/lib/python3.7/site-packages/urllib3/filepost.py
2021-12-20 06:31:40   2019-02-14 18:34:46 /usr/local/lib/python3.7/site-packages/urllib3/fields.py
2021-12-20 06:31:40   2019-02-14 18:34:46 /usr/local/lib/python3.7/site-packages/urllib3/response.py
2021-12-20 06:31:40   2019-02-14 18:34:46 /usr/local/lib/python3.7/site-packages/urllib3/util/queue.py
2021-12-20 06:31:40   2019-02-14 18:34:46 /usr/local/lib/python3.7/site-packages/urllib3/poolmanager.py
2021-12-20 06:31:40   2019-02-14 18:34:46 /usr/local/lib/python3.7/site-packages/idna/__init__.py
2021-12-20 06:31:40   2019-02-14 18:34:46 /usr/local/lib/python3.7/site-packages/idna/package_data.py
2021-12-20 06:31:40   2019-02-14 18:34:46 /usr/local/lib/python3.7/site-packages/idna/core.py
2021-12-20 06:31:40   2019-02-14 18:34:46 /usr/local/lib/python3.7/site-packages/idna/idnadata.py
2021-12-20 06:31:40   2019-02-14 18:34:46 /usr/local/lib/python3.7/site-packages/idna/intranges.py
2021-12-20 06:31:40   2019-02-14 18:34:46 /usr/local/lib/python3.7/site-packages/idna/__init__.py
2021-12-20 06:31:40   2019-02-14 18:34:46 /usr/local/lib/python3.7/site-packages/idna/package_data.py
2021-12-20 06:31:40   2019-02-14 18:34:46 /usr/local/lib/python3.7/site-packages/idna/core.py
2021-12-20 06:31:40   2019-02-14 18:34:46 /usr/local/lib/python3.7/site-packages/idna/idnadata.py
2021-12-20 06:31:40   2019-02-14 18:34:46 /usr/local/lib/python3.7/site-packages/idna/intranges.py
2021-12-20 06:31:40   2019-02-14 18:34:47 /usr/local/lib/python3.7/site-packages/chardet/__init__.py
2021-12-20 06:31:40   2019-02-14 18:34:47 /usr/local/lib/python3.7/site-packages/chardet/compat.py
2021-12-20 06:31:40   2019-02-14 18:34:47 /usr/local/lib/python3.7/site-packages/chardet/universaldetector.py
2021-12-20 06:31:40   2019-02-14 18:34:47 /usr/local/lib/python3.7/site-packages/chardet/charsetgroupprober.py
2021-12-20 06:31:40   2019-02-14 18:34:47 /usr/local/lib/python3.7/site-packages/chardet/enums.py
2021-12-20 06:31:40   2019-02-14 18:34:47 /usr/local/lib/python3.7/site-packages/chardet/charsetprober.py
2021-12-20 06:31:40   2019-02-14 18:34:47 /usr/local/lib/python3.7/site-packages/chardet/escprober.py
2021-12-20 06:31:40   2019-02-14 18:34:47 /usr/local/lib/python3.7/site-packages/chardet/codingstatemachine.py
2021-12-20 06:31:40   2019-02-14 18:34:47 /usr/local/lib/python3.7/site-packages/chardet/escsm.py
2021-12-20 06:31:40   2019-02-14 18:34:47 /usr/local/lib/python3.7/site-packages/chardet/latin1prober.py
2021-12-20 06:31:40   2019-02-14 18:34:47 /usr/local/lib/python3.7/site-packages/chardet/mbcsgroupprober.py
2021-12-20 06:31:40   2019-02-14 18:34:47 /usr/local/lib/python3.7/site-packages/chardet/utf8prober.py
2021-12-20 06:31:40   2019-02-14 18:34:47 /usr/local/lib/python3.7/site-packages/chardet/mbcssm.py
2021-12-20 06:31:40   2019-02-14 18:34:47 /usr/local/lib/python3.7/site-packages/chardet/sjisprober.py
2021-12-20 06:31:40   2019-02-14 18:34:47 /usr/local/lib/python3.7/site-packages/chardet/mbcharsetprober.py
2021-12-20 06:31:40   2019-02-14 18:34:47 /usr/local/lib/python3.7/site-packages/chardet/chardistribution.py
2021-12-20 06:31:40   2019-02-14 18:34:47 /usr/local/lib/python3.7/site-packages/chardet/euctwfreq.py
2021-12-20 06:31:40   2019-02-14 18:34:47 /usr/local/lib/python3.7/site-packages/chardet/euckrfreq.py
2021-12-20 06:31:40   2019-02-14 18:34:47 /usr/local/lib/python3.7/site-packages/chardet/gb2312freq.py
2021-12-20 06:31:40   2019-02-14 18:34:47 /usr/local/lib/python3.7/site-packages/chardet/big5freq.py
2021-12-20 06:31:40   2019-02-14 18:34:47 /usr/local/lib/python3.7/site-packages/chardet/jisfreq.py
2021-12-20 06:31:40   2019-02-14 18:34:47 /usr/local/lib/python3.7/site-packages/chardet/jpcntx.py
2021-12-20 06:31:40   2019-02-14 18:34:47 /usr/local/lib/python3.7/site-packages/chardet/eucjpprober.py
2021-12-20 06:31:40   2019-02-14 18:34:47 /usr/local/lib/python3.7/site-packages/chardet/gb2312prober.py
2021-12-20 06:31:40   2019-02-14 18:34:47 /usr/local/lib/python3.7/site-packages/chardet/euckrprober.py
2021-12-20 06:31:40   2019-02-14 18:34:47 /usr/local/lib/python3.7/site-packages/chardet/cp949prober.py
2021-12-20 06:31:40   2019-02-14 18:34:47 /usr/local/lib/python3.7/site-packages/chardet/big5prober.py
2021-12-20 06:31:40   2019-02-14 18:34:47 /usr/local/lib/python3.7/site-packages/chardet/euctwprober.py
2021-12-20 06:31:40   2019-02-14 18:34:47 /usr/local/lib/python3.7/site-packages/chardet/sbcsgroupprober.py
2021-12-20 06:31:40   2019-02-14 18:34:47 /usr/local/lib/python3.7/site-packages/chardet/sbcharsetprober.py
2021-12-20 06:31:40   2019-02-14 18:34:47 /usr/local/lib/python3.7/site-packages/chardet/langcyrillicmodel.py
2021-12-20 06:31:40   2019-02-14 18:34:47 /usr/local/lib/python3.7/site-packages/chardet/langgreekmodel.py
2021-12-20 06:31:40   2019-02-14 18:34:47 /usr/local/lib/python3.7/site-packages/chardet/langbulgarianmodel.py
2021-12-20 06:31:40   2019-02-14 18:34:47 /usr/local/lib/python3.7/site-packages/chardet/langthaimodel.py
2021-12-20 06:31:40   2019-02-14 18:34:47 /usr/local/lib/python3.7/site-packages/chardet/langhebrewmodel.py
2021-12-20 06:31:40   2019-02-14 18:34:47 /usr/local/lib/python3.7/site-packages/chardet/hebrewprober.py
2021-12-20 06:31:40   2019-02-14 18:34:47 /usr/local/lib/python3.7/site-packages/chardet/langturkishmodel.py
2021-12-20 06:31:40   2019-02-14 18:34:47 /usr/local/lib/python3.7/site-packages/chardet/version.py
2021-12-20 06:31:40   2019-02-14 18:34:46 /usr/local/lib/python3.7/site-packages/requests/models.py
2021-12-20 06:31:40   2019-02-14 18:34:46 /usr/local/lib/python3.7/site-packages/requests/hooks.py
2021-12-20 06:31:40   2019-02-14 18:34:46 /usr/local/lib/python3.7/site-packages/requests/auth.py
2021-12-20 06:31:40   2019-02-14 18:34:46 /usr/local/lib/python3.7/site-packages/requests/status_codes.py
2021-12-20 06:31:40   2019-02-14 18:34:46 /usr/local/lib/python3.7/site-packages/requests/api.py
2021-12-20 06:31:40   2019-02-14 18:34:46 /usr/local/lib/python3.7/site-packages/requests/sessions.py
2021-12-20 06:31:40   2019-02-14 18:34:46 /usr/local/lib/python3.7/site-packages/requests/adapters.py
2021-12-20 06:31:40   2021-12-15 13:01:25 /usr/local/lib/python3.7/site-packages/pywikibot/bot_choice.py
2021-12-20 06:31:40   2021-12-15 13:01:25 /usr/local/lib/python3.7/site-packages/pywikibot/tools/_logging.py
2021-12-20 06:31:40   2021-12-15 13:01:25 /usr/local/lib/python3.7/site-packages/pywikibot/tools/formatter.py
2021-12-20 06:31:40   2021-12-15 13:01:25 /usr/local/lib/python3.7/site-packages/pywikibot/userinterfaces/__init__.py
2021-12-20 06:31:40   2021-12-15 13:01:25 /usr/local/lib/python3.7/site-packages/pywikibot/userinterfaces/terminal_interface_base.py
2021-12-20 06:31:40   2021-12-15 13:01:25 /usr/local/lib/python3.7/site-packages/pywikibot/userinterfaces/transliteration.py
2021-12-20 06:31:40   2021-12-15 13:01:25 /usr/local/lib/python3.7/site-packages/pywikibot/userinterfaces/_interface_base.py
2021-12-20 06:31:40   2021-12-15 13:01:25 /usr/local/lib/python3.7/site-packages/pywikibot/userinterfaces/terminal_interface.py
2021-12-20 06:31:40   2021-12-15 13:01:25 /usr/local/lib/python3.7/site-packages/pywikibot/userinterfaces/terminal_interface_unix.py
2021-12-20 06:31:40   2021-12-15 13:01:25 /usr/local/lib/python3.7/site-packages/pywikibot/diff.py
2021-12-20 06:31:40   2021-12-15 13:01:25 /usr/local/lib/python3.7/site-packages/pywikibot/tools/chars.py
2021-12-20 06:31:40   2021-12-15 13:01:25 /usr/local/lib/python3.7/site-packages/pywikibot/family.py
2021-12-20 06:31:40   2021-12-15 13:01:25 /usr/local/lib/python3.7/site-packages/pywikibot/site/__init__.py
2021-12-20 06:31:40   2021-12-15 13:01:25 /usr/local/lib/python3.7/site-packages/pywikibot/site/_apisite.py
2021-12-20 06:31:40   2021-12-15 13:01:25 /usr/local/lib/python3.7/site-packages/pywikibot/data/__init__.py
2021-12-20 06:31:40   2021-12-15 13:01:25 /usr/local/lib/python3.7/site-packages/pywikibot/data/api.py
2021-12-20 06:31:40   2021-12-15 13:01:25 /usr/local/lib/python3.7/site-packages/pywikibot/login.py
2021-12-20 06:31:40   2021-12-15 13:01:25 /usr/local/lib/python3.7/site-packages/pywikibot/textlib.py
2021-12-20 06:31:40   2019-02-26 22:00:09 /usr/local/lib/python3.7/site-packages/mwparserfromhell/__init__.py
2021-12-20 06:31:40   2019-02-26 22:00:09 /usr/local/lib/python3.7/site-packages/mwparserfromhell/compat.py
2021-12-20 06:31:40   2019-02-26 22:00:09 /usr/local/lib/python3.7/site-packages/mwparserfromhell/definitions.py
2021-12-20 06:31:40   2019-02-26 22:00:09 /usr/local/lib/python3.7/site-packages/mwparserfromhell/nodes/__init__.py
2021-12-20 06:31:40   2019-02-26 22:00:09 /usr/local/lib/python3.7/site-packages/mwparserfromhell/string_mixin.py
2021-12-20 06:31:40   2019-02-26 22:00:09 /usr/local/lib/python3.7/site-packages/mwparserfromhell/nodes/extras/__init__.py
2021-12-20 06:31:40   2019-02-26 22:00:09 /usr/local/lib/python3.7/site-packages/mwparserfromhell/nodes/extras/attribute.py
2021-12-20 06:31:40   2019-02-26 22:00:09 /usr/local/lib/python3.7/site-packages/mwparserfromhell/utils.py
2021-12-20 06:31:40   2019-02-26 22:00:09 /usr/local/lib/python3.7/site-packages/mwparserfromhell/smart_list.py
2021-12-20 06:31:40   2019-02-26 22:00:09 /usr/local/lib/python3.7/site-packages/mwparserfromhell/nodes/extras/parameter.py
2021-12-20 06:31:40   2019-02-26 22:00:09 /usr/local/lib/python3.7/site-packages/mwparserfromhell/nodes/text.py
2021-12-20 06:31:40   2019-02-26 22:00:09 /usr/local/lib/python3.7/site-packages/mwparserfromhell/nodes/argument.py
2021-12-20 06:31:40   2019-02-26 22:00:09 /usr/local/lib/python3.7/site-packages/mwparserfromhell/nodes/comment.py
2021-12-20 06:31:40   2019-02-26 22:00:09 /usr/local/lib/python3.7/site-packages/mwparserfromhell/nodes/external_link.py
2021-12-20 06:31:40   2019-02-26 22:00:09 /usr/local/lib/python3.7/site-packages/mwparserfromhell/nodes/heading.py
2021-12-20 06:31:40   2019-02-26 22:00:09 /usr/local/lib/python3.7/site-packages/mwparserfromhell/nodes/html_entity.py
2021-12-20 06:31:40   2019-02-26 22:00:09 /usr/local/lib/python3.7/site-packages/mwparserfromhell/nodes/tag.py
2021-12-20 06:31:40   2019-02-26 22:00:09 /usr/local/lib/python3.7/site-packages/mwparserfromhell/nodes/template.py
2021-12-20 06:31:40   2019-02-26 22:00:09 /usr/local/lib/python3.7/site-packages/mwparserfromhell/nodes/wikilink.py
2021-12-20 06:31:40   2019-02-26 22:00:09 /usr/local/lib/python3.7/site-packages/mwparserfromhell/parser/__init__.py
2021-12-20 06:31:40   2019-02-26 22:00:09 /usr/local/lib/python3.7/site-packages/mwparserfromhell/parser/builder.py
2021-12-20 06:31:40   2019-02-26 22:00:09 /usr/local/lib/python3.7/site-packages/mwparserfromhell/parser/tokens.py
2021-12-20 06:31:40   2019-02-26 22:00:09 /usr/local/lib/python3.7/site-packages/mwparserfromhell/wikicode.py
2021-12-20 06:31:40   2019-02-26 22:00:09 /usr/local/lib/python3.7/site-packages/mwparserfromhell/parser/_tokenizer.cpython-37m-darwin.so
2021-12-20 06:31:40   2021-12-15 13:01:25 /usr/local/lib/python3.7/site-packages/pywikibot/site/_basesite.py
2021-12-20 06:31:40   2021-12-15 13:01:25 /usr/local/lib/python3.7/site-packages/pywikibot/site/_namespace.py
2021-12-20 06:31:40   2021-12-15 13:01:25 /usr/local/lib/python3.7/site-packages/pywikibot/throttle.py
2021-12-20 06:31:40   2021-12-15 13:01:25 /usr/local/lib/python3.7/site-packages/pywikibot/site/_decorators.py
2021-12-20 06:31:40   2021-12-15 13:01:25 /usr/local/lib/python3.7/site-packages/pywikibot/site/_extensions.py
2021-12-20 06:31:40   2021-12-15 13:01:25 /usr/local/lib/python3.7/site-packages/pywikibot/echo.py
2021-12-20 06:31:40   2021-12-15 13:01:25 /usr/local/lib/python3.7/site-packages/pywikibot/site/_generators.py
2021-12-20 06:31:40   2021-12-15 13:01:25 /usr/local/lib/python3.7/site-packages/pywikibot/site/_interwikimap.py
2021-12-20 06:31:40   2021-12-15 13:01:25 /usr/local/lib/python3.7/site-packages/pywikibot/site/_siteinfo.py
2021-12-20 06:31:40   2021-12-15 13:01:25 /usr/local/lib/python3.7/site-packages/pywikibot/site/_tokenwallet.py
2021-12-20 06:31:40   2021-12-15 13:01:25 /usr/local/lib/python3.7/site-packages/pywikibot/site/_datasite.py
2021-12-20 06:31:40   2021-12-15 13:01:25 /usr/local/lib/python3.7/site-packages/pywikibot/site/_obsoletesites.py
2021-12-20 06:31:40   2021-12-15 13:01:25 /usr/local/lib/python3.7/site-packages/pywikibot/page/__init__.py
2021-12-20 06:31:40   2021-12-15 13:01:25 /usr/local/lib/python3.7/site-packages/pywikibot/page/_collections.py
2021-12-20 06:31:40   2021-12-15 13:01:25 /usr/local/lib/python3.7/site-packages/pywikibot/page/_decorators.py
2021-12-20 06:31:40   2021-12-15 13:01:25 /usr/local/lib/python3.7/site-packages/pywikibot/page/_revision.py
2021-12-20 06:31:40   2021-12-15 13:01:25 /usr/local/lib/python3.7/site-packages/pywikibot/pagegenerators.py
2021-12-20 06:31:40   2021-12-15 13:01:25 /usr/local/lib/python3.7/site-packages/pywikibot/date.py
2021-12-20 06:31:40   2021-12-15 13:01:25 /usr/local/lib/python3.7/site-packages/pywikibot/xmlreader.py
2021-12-20 06:31:40   2021-12-15 13:01:25 /usr/local/lib/python3.7/site-packages/pywikibot/proofreadpage.py
2021-12-20 06:31:40   2021-12-15 13:01:25 /usr/local/lib/python3.7/site-packages/pywikibot/families/wikidata_family.py
2021-12-20 06:31:40 =========================================================
2021-12-20 06:31:40 Found 1 wikidata:wikidata processes running, including this one.
2021-12-20 06:31:41 Found candidate wikidata:wikidata
2021-12-20 06:31:49 Found 1 commons:commons processes running, including this one.
2021-12-20 06:36:41 Found 1 wikidata:wikidata processes running, including this one.
2021-12-20 06:36:49 Found 1 commons:commons processes running, including this one.
2021-12-20 06:41:41 Found 1 wikidata:wikidata processes running, including this one.
2021-12-20 06:41:50 Found 1 commons:commons processes running, including this one.
2021-12-20 06:46:41 Found 1 wikidata:wikidata processes running, including this one.
2021-12-20 06:46:50 Found 1 commons:commons processes running, including this one.
2021-12-20 06:51:41 Found 1 wikidata:wikidata processes running, including this one.
2021-12-20 06:51:50 Found 1 commons:commons processes running, including this one.
2021-12-20 06:56:42 Found 1 wikidata:wikidata processes running, including this one.
2021-12-20 06:56:50 Found 1 commons:commons processes running, including this one.
2021-12-20 07:01:42 Found 1 wikidata:wikidata processes running, including this one.
2021-12-20 07:01:50 Found 1 commons:commons processes running, including this one.
2021-12-20 07:06:42 Found 1 wikidata:wikidata processes running, including this one.
2021-12-20 07:06:51 Found 1 commons:commons processes running, including this one.
2021-12-20 07:11:43 Found 1 wikidata:wikidata processes running, including this one.
2021-12-20 07:11:51 Found 1 commons:commons processes running, including this one.
2021-12-20 07:14:48 An error occurred for uri https://www.wikidata.org/w/api.php?ids=Q20440563&action=wbgetentities&maxlag=5&format=json
2021-12-20 07:14:48 Traceback (most recent call last):
  File "/usr/local/lib/python3.7/site-packages/pywikibot/data/api.py", line 1488, in _http_request
    data=data, headers=headers)
  File "/usr/local/lib/python3.7/site-packages/pywikibot/tools/_deprecate.py", line 404, in wrapper
    return obj(*__args, **__kw)
  File "/usr/local/lib/python3.7/site-packages/pywikibot/comms/http.py", line 263, in request
    r = fetch(baseuri, headers=headers, **kwargs)
  File "/usr/local/lib/python3.7/site-packages/pywikibot/tools/_deprecate.py", line 404, in wrapper
    return obj(*__args, **__kw)
  File "/usr/local/lib/python3.7/site-packages/pywikibot/comms/http.py", line 425, in fetch
    callback(response)
  File "/usr/local/lib/python3.7/site-packages/pywikibot/comms/http.py", line 308, in error_handling_callback
    raise response from None
  File "/usr/local/lib/python3.7/site-packages/pywikibot/comms/http.py", line 418, in fetch
    **kwargs)
  File "/usr/local/lib/python3.7/site-packages/requests/sessions.py", line 533, in request
    resp = self.send(prep, **send_kwargs)
  File "/usr/local/lib/python3.7/site-packages/requests/sessions.py", line 646, in send
    r = adapter.send(request, **kwargs)
  File "/usr/local/lib/python3.7/site-packages/requests/adapters.py", line 529, in send
    raise ReadTimeout(e, request=request)
requests.exceptions.ReadTimeout: HTTPSConnectionPool(host='www.wikidata.org', port=443): Read timed out. (read timeout=45)

2021-12-20 07:14:48 /w/api.php?ids=Q20440563&action=wbgetentities&maxlag=5&format=json, ids=Q20440563&action=wbgetentities&maxlag=5&format=json
2021-12-20 07:14:48 Waiting 5.0 seconds before retrying.
2021-12-20 07:24:10 Found 1 wikidata:wikidata processes running, including this one.
2021-12-20 07:24:10 An error occurred for uri https://www.wikidata.org/w/api.php?ids=Q20441030&action=wbgetentities&maxlag=5&format=json
2021-12-20 07:24:10 Traceback (most recent call last):
  File "/usr/local/lib/python3.7/site-packages/pywikibot/data/api.py", line 1488, in _http_request
    data=data, headers=headers)
  File "/usr/local/lib/python3.7/site-packages/pywikibot/tools/_deprecate.py", line 404, in wrapper
    return obj(*__args, **__kw)
  File "/usr/local/lib/python3.7/site-packages/pywikibot/comms/http.py", line 263, in request
    r = fetch(baseuri, headers=headers, **kwargs)
  File "/usr/local/lib/python3.7/site-packages/pywikibot/tools/_deprecate.py", line 404, in wrapper
    return obj(*__args, **__kw)
  File "/usr/local/lib/python3.7/site-packages/pywikibot/comms/http.py", line 425, in fetch
    callback(response)
  File "/usr/local/lib/python3.7/site-packages/pywikibot/comms/http.py", line 308, in error_handling_callback
    raise response from None
  File "/usr/local/lib/python3.7/site-packages/pywikibot/comms/http.py", line 418, in fetch
    **kwargs)
  File "/usr/local/lib/python3.7/site-packages/requests/sessions.py", line 533, in request
    resp = self.send(prep, **send_kwargs)
  File "/usr/local/lib/python3.7/site-packages/requests/sessions.py", line 646, in send
    r = adapter.send(request, **kwargs)
  File "/usr/local/lib/python3.7/site-packages/requests/adapters.py", line 498, in send
    raise ConnectionError(err, request=request)
requests.exceptions.ConnectionError: ('Connection aborted.', ConnectionResetError(54, 'Connection reset by peer'))

2021-12-20 07:24:10 /w/api.php?ids=Q20441030&action=wbgetentities&maxlag=5&format=json, ids=Q20441030&action=wbgetentities&maxlag=5&format=json
2021-12-20 07:24:10 Waiting 5.0 seconds before retrying.
2021-12-20 07:24:16 Found 1 commons:commons processes running, including this one.
2021-12-20 08:58:12 An error occurred for uri https://www.wikidata.org/w/api.php?ids=Q20355838&action=wbgetentities&maxlag=5&format=json
2021-12-20 08:58:12 Traceback (most recent call last):
  File "/usr/local/lib/python3.7/site-packages/pywikibot/data/api.py", line 1488, in _http_request
    data=data, headers=headers)
  File "/usr/local/lib/python3.7/site-packages/pywikibot/tools/_deprecate.py", line 404, in wrapper
    return obj(*__args, **__kw)
  File "/usr/local/lib/python3.7/site-packages/pywikibot/comms/http.py", line 263, in request
    r = fetch(baseuri, headers=headers, **kwargs)
  File "/usr/local/lib/python3.7/site-packages/pywikibot/tools/_deprecate.py", line 404, in wrapper
    return obj(*__args, **__kw)
  File "/usr/local/lib/python3.7/site-packages/pywikibot/comms/http.py", line 425, in fetch
    callback(response)
  File "/usr/local/lib/python3.7/site-packages/pywikibot/comms/http.py", line 308, in error_handling_callback
    raise response from None
  File "/usr/local/lib/python3.7/site-packages/pywikibot/comms/http.py", line 418, in fetch
    **kwargs)
  File "/usr/local/lib/python3.7/site-packages/requests/sessions.py", line 533, in request
    resp = self.send(prep, **send_kwargs)
  File "/usr/local/lib/python3.7/site-packages/requests/sessions.py", line 646, in send
    r = adapter.send(request, **kwargs)
  File "/usr/local/lib/python3.7/site-packages/requests/adapters.py", line 529, in send
    raise ReadTimeout(e, request=request)
requests.exceptions.ReadTimeout: HTTPSConnectionPool(host='www.wikidata.org', port=443): Read timed out. (read timeout=45)

2021-12-20 08:58:12 /w/api.php?ids=Q20355838&action=wbgetentities&maxlag=5&format=json, ids=Q20355838&action=wbgetentities&maxlag=5&format=json
2021-12-20 08:58:12 Waiting 5.0 seconds before retrying.
2021-12-20 08:58:17 Found 1 wikidata:wikidata processes running, including this one.
2021-12-20 08:58:17 Found 1 commons:commons processes running, including this one.
2021-12-20 08:58:17 An error occurred for uri https://commons.wikimedia.org/w/api.php?iiprop=timestamp%7Cuser%7Ccomment%7Curl%7Csize%7Csha1%7Cmime%7Cmetadata%7Carchivename&titles=File%3ARembrandt+emaus.jpg&prop=imageinfo&action=query&indexpageids=&continue=&iilimit=500&meta=userinfo&uiprop=blockinfo%7Chasmsg&maxlag=5&format=json
2021-12-20 08:58:17 Traceback (most recent call last):
  File "/usr/local/lib/python3.7/site-packages/pywikibot/data/api.py", line 1488, in _http_request
    data=data, headers=headers)
  File "/usr/local/lib/python3.7/site-packages/pywikibot/tools/_deprecate.py", line 404, in wrapper
    return obj(*__args, **__kw)
  File "/usr/local/lib/python3.7/site-packages/pywikibot/comms/http.py", line 263, in request
    r = fetch(baseuri, headers=headers, **kwargs)
  File "/usr/local/lib/python3.7/site-packages/pywikibot/tools/_deprecate.py", line 404, in wrapper
    return obj(*__args, **__kw)
  File "/usr/local/lib/python3.7/site-packages/pywikibot/comms/http.py", line 425, in fetch
    callback(response)
  File "/usr/local/lib/python3.7/site-packages/pywikibot/comms/http.py", line 308, in error_handling_callback
    raise response from None
  File "/usr/local/lib/python3.7/site-packages/pywikibot/comms/http.py", line 418, in fetch
    **kwargs)
  File "/usr/local/lib/python3.7/site-packages/requests/sessions.py", line 533, in request
    resp = self.send(prep, **send_kwargs)
  File "/usr/local/lib/python3.7/site-packages/requests/sessions.py", line 646, in send
    r = adapter.send(request, **kwargs)
  File "/usr/local/lib/python3.7/site-packages/requests/adapters.py", line 498, in send
    raise ConnectionError(err, request=request)
requests.exceptions.ConnectionError: ('Connection aborted.', ConnectionResetError(54, 'Connection reset by peer'))

2021-12-20 08:58:17 /w/api.php?iiprop=timestamp%7Cuser%7Ccomment%7Curl%7Csize%7Csha1%7Cmime%7Cmetadata%7Carchivename&titles=File%3ARembrandt+emaus.jpg&prop=imageinfo&action=query&indexpageids=&continue=&iilimit=500&meta=userinfo&uiprop=blockinfo%7Chasmsg&maxlag=5&format=json, iiprop=timestamp%7Cuser%7Ccomment%7Curl%7Csize%7Csha1%7Cmime%7Cmetadata%7Carchivename&titles=File%3ARembrandt+emaus.jpg&prop=imageinfo&action=query&indexpageids=&continue=&iilimit=500&meta=userinfo&uiprop=blockinfo%7Chasmsg&maxlag=5&format=json
2021-12-20 08:58:17 Waiting 5.0 seconds before retrying.
2021-12-20 09:00:10 Dropped throttle(s).
2021-12-20 09:00:10 Closing network session.
2021-12-20 09:00:10 Network session closed.
